Workbook

Sheet Fertilizer
A2: 04-0001 | B2: 46-0-0 | C2: 50
A3: 04-0003 | B3: Borax | C3: 25
A4: 04-0008 | B4: 0-0-60 | C4: 50
A5: 04-0030 | B5: 0-3-0 | C5: 50
A6: 04-0169 | B6: Dolomite | C6: 25

Sheet Terrain
A1: พื้นที่ | B1: แปลง | C1: รหัสบล๊อก | D1: รหัสบล๊อกใหม่ | E1: จน.ไร่ | F1: จน.ต้น | G1: ปีปลูก | H1: ช่วงปี
A2: Lower | B2: Panrai | C2: R-22-C5 | D2: =IF(LEFT(C2,2)="R-",MID(C2,3,FIND("-",C2,3)-3)&"-"&LEFT(MID(C2,FIND("-",C2,3)+1,99),1)&TEXT(--MID(C2,FIND("-",C2,3)+2,99),"00")&"-R",LEFT(C2,FIND("-",C2))&LEFT(MID(C2,FIND("-",C2)+1,99),1)&TEXT(--MID(C2,FIND("-",C2)+2,99),"00")) -> 22-C05-R | E2: 8 | F2: 184 | G2: =2500+VALUE(MID(D2,1,2)) -> 2522 | H2: ปาล์มใหญ่
A3: Lower | B3: Yuansao | C3: 30-PU1 | D3: 30-PU1 | E3: 82 | F3: 1813 | G3: =2500+VALUE(MID(D3,1,2)) -> 2530 | H3: ปาล์มใหญ่
A4: Lower | B4: Yuansao | C4: 30-PU3 | D4: 30-PU3 | E4: 72 | F4: 1574 | G4: =2500+VALUE(MID(D4,1,2)) -> 2530 | H4: ปาล์มใหญ่
A5: Lower | B5: Yuansao | C5: 30-PU4 | D5: 30-PU4 | E5: 69 | F5: 1509 | G5: =2500+VALUE(MID(D5,1,2)) -> 2530 | H5: ปาล์มใหญ่
A6: Lower | B6: Kapao | C6: R-49-A10 | D6: =IF(LEFT(C6,2)="R-",MID(C6,3,FIND("-",C6,3)-3)&"-"&LEFT(MID(C6,FIND("-",C6,3)+1,99),1)&TEXT(--MID(C6,FIND("-",C6,3)+2,99),"00")&"-R",LEFT(C6,FIND("-",C6))&LEFT(MID(C6,FIND("-",C6)+1,99),1)&TEXT(--MID(C6,FIND("-",C6)+2,99),"00")) -> 49-A10-R | E6: 111 | F6: 2785 | G6: =2500+VALUE(MID(D6,1,2)) -> 2549 | H6: 2549 - 2552
A7: Lower | B7: Kapao | C7: R-49-A11 | D7: =IF(LEFT(C7,2)="R-",MID(C7,3,FIND("-",C7,3)-3)&"-"&LEFT(MID(C7,FIND("-",C7,3)+1,99),1)&TEXT(--MID(C7,FIND("-",C7,3)+2,99),"00")&"-R",LEFT(C7,FIND("-",C7))&LEFT(MID(C7,FIND("-",C7)+1,99),1)&TEXT(--MID(C7,FIND("-",C7)+2,99),"00")) -> 49-A11-R | E7: 97 | F7: 2421 | G7: =2500+VALUE(MID(D7,1,2)) -> 2549 | H7: 2549 - 2552
A8: Lower | B8: Kapao | C8: R-49-A12 | D8: =IF(LEFT(C8,2)="R-",MID(C8,3,FIND("-",C8,3)-3)&"-"&LEFT(MID(C8,FIND("-",C8,3)+1,99),1)&TEXT(--MID(C8,FIND("-",C8,3)+2,99),"00")&"-R",LEFT(C8,FIND("-",C8))&LEFT(MID(C8,FIND("-",C8)+1,99),1)&TEXT(--MID(C8,FIND("-",C8)+2,99),"00")) -> 49-A12-R | E8: 151 | F8: 3764 | G8: =2500+VALUE(MID(D8,1,2)) -> 2549 | H8: 2549 - 2552
A9: Lower | B9: Kapao | C9: R-49-A13 | D9: =IF(LEFT(C9,2)="R-",MID(C9,3,FIND("-",C9,3)-3)&"-"&LEFT(MID(C9,FIND("-",C9,3)+1,99),1)&TEXT(--MID(C9,FIND("-",C9,3)+2,99),"00")&"-R",LEFT(C9,FIND("-",C9))&LEFT(MID(C9,FIND("-",C9)+1,99),1)&TEXT(--MID(C9,FIND("-",C9)+2,99),"00")) -> 49-A13-R | E9: 116 | F9: 2893 | G9: =2500+VALUE(MID(D9,1,2)) -> 2549 | H9: 2549 - 2552
A10: Lower | B10: Kapao | C10: 50-A4 | D10: =IF(LEFT(C10,2)="R-",MID(C10,3,FIND("-",C10,3)-3)&"-"&LEFT(MID(C10,FIND("-",C10,3)+1,99),1)&TEXT(--MID(C10,FIND("-",C10,3)+2,99),"00")&"-R",LEFT(C10,FIND("-",C10))&LEFT(MID(C10,FIND("-",C10)+1,99),1)&TEXT(--MID(C10,FIND("-",C10)+2,99),"00")) -> 50-A04 | E10: 195 | F10: 4864 | G10: =2500+VALUE(MID(D10,1,2)) -> 2550 | H10: 2549 - 2552
A11: Lower | B11: Kapao | C11: 50-A5 | D11: =IF(LEFT(C11,2)="R-",MID(C11,3,FIND("-",C11,3)-3)&"-"&LEFT(MID(C11,FIND("-",C11,3)+1,99),1)&TEXT(--MID(C11,FIND("-",C11,3)+2,99),"00")&"-R",LEFT(C11,FIND("-",C11))&LEFT(MID(C11,FIND("-",C11)+1,99),1)&TEXT(--MID(C11,FIND("-",C11)+2,99),"00")) -> 50-A05 | E11: 171 | F11: 4608 | G11: =2500+VALUE(MID(D11,1,2)) -> 2550 | H11: 2549 - 2552
A12: Lower | B12: Panrai | C12: R-50-C5 | D12: =IF(LEFT(C12,2)="R-",MID(C12,3,FIND("-",C12,3)-3)&"-"&LEFT(MID(C12,FIND("-",C12,3)+1,99),1)&TEXT(--MID(C12,FIND("-",C12,3)+2,99),"00")&"-R",LEFT(C12,FIND("-",C12))&LEFT(MID(C12,FIND("-",C12)+1,99),1)&TEXT(--MID(C12,FIND("-",C12)+2,99),"00")) -> 50-C05-R | E12: 103 | F12: 2792 | G12: =2500+VALUE(MID(D12,1,2)) -> 2550 | H12: 2549 - 2552
A13: Lower | B13: Panrai | C13: R-50-C7 | D13: =IF(LEFT(C13,2)="R-",MID(C13,3,FIND("-",C13,3)-3)&"-"&LEFT(MID(C13,FIND("-",C13,3)+1,99),1)&TEXT(--MID(C13,FIND("-",C13,3)+2,99),"00")&"-R",LEFT(C13,FIND("-",C13))&LEFT(MID(C13,FIND("-",C13)+1,99),1)&TEXT(--MID(C13,FIND("-",C13)+2,99),"00")) -> 50-C07-R | E13: 156 | F13: 4202 | G13: =2500+VALUE(MID(D13,1,2)) -> 2550 | H13: 2549 - 2552
A14: Lower | B14: Plairang | C14: 51-P7 | D14: =IF(LEFT(C14,2)="R-",MID(C14,3,FIND("-",C14,3)-3)&"-"&LEFT(MID(C14,FIND("-",C14,3)+1,99),1)&TEXT(--MID(C14,FIND("-",C14,3)+2,99),"00")&"-R",LEFT(C14,FIND("-",C14))&LEFT(MID(C14,FIND("-",C14)+1,99),1)&TEXT(--MID(C14,FIND("-",C14)+2,99),"00")) -> 51-P07 | E14: 6 | F14: 152 | G14: =2500+VALUE(MID(D14,1,2)) -> 2551 | H14: 2549 - 2552
A15: Lower | B15: Plairang | C15: R-51-P7 | D15: =IF(LEFT(C15,2)="R-",MID(C15,3,FIND("-",C15,3)-3)&"-"&LEFT(MID(C15,FIND("-",C15,3)+1,99),1)&TEXT(--MID(C15,FIND("-",C15,3)+2,99),"00")&"-R",LEFT(C15,FIND("-",C15))&LEFT(MID(C15,FIND("-",C15)+1,99),1)&TEXT(--MID(C15,FIND("-",C15)+2,99),"00")) -> 51-P07-R | E15: 15 | F15: 401 | G15: =2500+VALUE(MID(D15,1,2)) -> 2551 | H15: 2549 - 2552
A16: Lower | B16: Plairang | C16: R-55-P7 | D16: =IF(LEFT(C16,2)="R-",MID(C16,3,FIND("-",C16,3)-3)&"-"&LEFT(MID(C16,FIND("-",C16,3)+1,99),1)&TEXT(--MID(C16,FIND("-",C16,3)+2,99),"00")&"-R",LEFT(C16,FIND("-",C16))&LEFT(MID(C16,FIND("-",C16)+1,99),1)&TEXT(--MID(C16,FIND("-",C16)+2,99),"00")) -> 55-P07-R | E16: 4 | F16: 93 | G16: =2500+VALUE(MID(D16,1,2)) -> 2555 | H16: 2555 - 2558
A17: Lower | B17: Kapao | C17: 56-A1 | D17: =IF(LEFT(C17,2)="R-",MID(C17,3,FIND("-",C17,3)-3)&"-"&LEFT(MID(C17,FIND("-",C17,3)+1,99),1)&TEXT(--MID(C17,FIND("-",C17,3)+2,99),"00")&"-R",LEFT(C17,FIND("-",C17))&LEFT(MID(C17,FIND("-",C17)+1,99),1)&TEXT(--MID(C17,FIND("-",C17)+2,99),"00")) -> 56-A01 | E17: 78 | F17: 1950 | G17: =2500+VALUE(MID(D17,1,2)) -> 2556 | H17: 2555 - 2558
... A48: Lower | B48: Monmai | C48: R-65-D5 | D48: =IF(LEFT(C48,2)="R-",MID(C48,3,FIND("-",C48,3)-3)&"-"&LEFT(MID(C48,FIND("-",C48,3)+1,99),1)&TEXT(--MID(C48,FIND("-",C48,3)+2,99),"00")&"-R",LEFT(C48,FIND("-",C48))&LEFT(MID(C48,FIND("-",C48)+1,99),1)&TEXT(--MID(C48,FIND("-",C48)+2,99),"00")) -> 65-D05-R | E48: 122 | F48: 2687 | G48: =2500+VALUE(MID(D48,1,2)) -> 2565 | H48: 2563 - 2565
A49: Lower | B49: Monmai | C49: R-66-D9 | D49: =IF(LEFT(C49,2)="R-",MID(C49,3,FIND("-",C49,3)-3)&"-"&LEFT(MID(C49,FIND("-",C49,3)+1,99),1)&TEXT(--MID(C49,FIND("-",C49,3)+2,99),"00")&"-R",LEFT(C49,FIND("-",C49))&LEFT(MID(C49,FIND("-",C49)+1,99),1)&TEXT(--MID(C49,FIND("-",C49)+2,99),"00")) -> 66-D09-R | E49: 136 | F49: 2999 | G49: =2500+VALUE(MID(D49,1,2)) -> 2566 | H49: 2566
A50: Lower | B50: Plairang | C50: R-66-P3 | D50: =IF(LEFT(C50,2)="R-",MID(C50,3,FIND("-",C50,3)-3)&"-"&LEFT(MID(C50,FIND("-",C50,3)+1,99),1)&TEXT(--MID(C50,FIND("-",C50,3)+2,99),"00")&"-R",LEFT(C50,FIND("-",C50))&LEFT(MID(C50,FIND("-",C50)+1,99),1)&TEXT(--MID(C50,FIND("-",C50)+2,99),"00")) -> 66-P03-R | E50: 116 | F50: 2550 | G50: =2500+VALUE(MID(D50,1,2)) -> 2566 | H50: 2566
A51: Lower | B51: Plairang | C51: R-66-P4 | D51: =IF(LEFT(C51,2)="R-",MID(C51,3,FIND("-",C51,3)-3)&"-"&LEFT(MID(C51,FIND("-",C51,3)+1,99),1)&TEXT(--MID(C51,FIND("-",C51,3)+2,99),"00")&"-R",LEFT(C51,FIND("-",C51))&LEFT(MID(C51,FIND("-",C51)+1,99),1)&TEXT(--MID(C51,FIND("-",C51)+2,99),"00")) -> 66-P04-R | E51: 130 | F51: 2854 | G51: =2500+VALUE(MID(D51,1,2)) -> 2566 | H51: 2566
A52: Lower | B52: Plairang | C52: R-66-P5 | D52: =IF(LEFT(C52,2)="R-",MID(C52,3,FIND("-",C52,3)-3)&"-"&LEFT(MID(C52,FIND("-",C52,3)+1,99),1)&TEXT(--MID(C52,FIND("-",C52,3)+2,99),"00")&"-R",LEFT(C52,FIND("-",C52))&LEFT(MID(C52,FIND("-",C52)+1,99),1)&TEXT(--MID(C52,FIND("-",C52)+2,99),"00")) -> 66-P05-R | E52: 141 | F52: 3111 | G52: =2500+VALUE(MID(D52,1,2)) -> 2566 | H52: 2566
A53: Lower | B53: Yuansao | C53: 66-PU2 | D53: 66-PU2 | E53: 90 | F53: 1970 | G53: =2500+VALUE(MID(D53,1,2)) -> 2566 | H53: 2566
A54: Lower | B54: Monmai | C54: R-67-D6 | D54: =IF(LEFT(C54,2)="R-",MID(C54,3,FIND("-",C54,3)-3)&"-"&LEFT(MID(C54,FIND("-",C54,3)+1,99),1)&TEXT(--MID(C54,FIND("-",C54,3)+2,99),"00")&"-R",LEFT(C54,FIND("-",C54))&LEFT(MID(C54,FIND("-",C54)+1,99),1)&TEXT(--MID(C54,FIND("-",C54)+2,99),"00")) -> 67-D06-R | E54: 130 | F54: 2865 | G54: =2500+VALUE(MID(D54,1,2)) -> 2567 | H54: 2567
A55: Lower | B55: Plairang | C55: R-67-P1 | D55: =IF(LEFT(C55,2)="R-",MID(C55,3,FIND("-",C55,3)-3)&"-"&LEFT(MID(C55,FIND("-",C55,3)+1,99),1)&TEXT(--MID(C55,FIND("-",C55,3)+2,99),"00")&"-R",LEFT(C55,FIND("-",C55))&LEFT(MID(C55,FIND("-",C55)+1,99),1)&TEXT(--MID(C55,FIND("-",C55)+2,99),"00")) -> 67-P01-R | E55: 99 | F55: 2167 | G55: =2500+VALUE(MID(D55,1,2)) -> 2567 | H55: 2567
A56: Lower | B56: Plairang | C56: R-67-P2 | D56: =IF(LEFT(C56,2)="R-",MID(C56,3,FIND("-",C56,3)-3)&"-"&LEFT(MID(C56,FIND("-",C56,3)+1,99),1)&TEXT(--MID(C56,FIND("-",C56,3)+2,99),"00")&"-R",LEFT(C56,FIND("-",C56))&LEFT(MID(C56,FIND("-",C56)+1,99),1)&TEXT(--MID(C56,FIND("-",C56)+2,99),"00")) -> 67-P02-R | E56: 105 | F56: 2320 | G56: =2500+VALUE(MID(D56,1,2)) -> 2567 | H56: 2567
A57: Lower | B57: Yuansao | C57: 68-PU1 | D57: 68-PU1 | E57: 86 | F57: 1892 | G57: =2500+VALUE(MID(D57,1,2)) -> 2568 | H57: 2568
A58: Lower | B58: Yuansao | C58: 68-PU3 | D58: 68-PU3 | E58: 77 | F58: 1686 | G58: =2500+VALUE(MID(D58,1,2)) -> 2568 | H58: 2568
A59: Lower | B59: Yuansao | C59: 68-PU4 | D59: 68-PU4 | E59: 63 | F59: 1380 | G59: =2500+VALUE(MID(D59,1,2)) -> 2568 | H59: 2568
A60: Lower | B60: Yuansao | C60: 68-PU5 | D60: 68-PU5 | E60: 34 | F60: 751 | G60: =2500+VALUE(MID(D60,1,2)) -> 2568 | H60: 2568
A61: Lower | B61: Yuansao | C61: R-68-PU5 | D61: 68-PU5-R | E61: 53 | F61: 1168 | G61: =2500+VALUE(MID(D61,1,2)) -> 2568 | H61: 2568
A62: Lower | B62: Yuansao | C62: 68-PU6 | D62: 68-PU6 | E62: 7 | F62: 145 | G62: =2500+VALUE(MID(D62,1,2)) -> 2568 | H62: 2568
A63: Lower | B63: Yuansao | C63: R-68-PU6 | D63: 68-PU6-R | E63: 70 | F63: 1547 | G63: =2500+VALUE(MID(D63,1,2)) -> 2568 | H63: 2568
A64: Upper | B64: Banggun | C64: 30-B14 | D64: =IF(LEFT(C64,2)="R-",MID(C64,3,FIND("-",C64,3)-3)&"-"&LEFT(MID(C64,FIND("-",C64,3)+1,99),1)&TEXT(--MID(C64,FIND("-",C64,3)+2,99),"00")&"-R",LEFT(C64,FIND("-",C64))&LEFT(MID(C64,FIND("-",C64)+1,99),1)&TEXT(--MID(C64,FIND("-",C64)+2,99),"00")) -> 30-B14 | E64: 6 | F64: 126 | G64: =2500+VALUE(MID(D64,1,2)) -> 2530 | H64: ปาล์มใหญ่
A65: Upper | B65: Takuk | C65: 37-T29 | D65: =IF(LEFT(C65,2)="R-",MID(C65,3,FIND("-",C65,3)-3)&"-"&LEFT(MID(C65,FIND("-",C65,3)+1,99),1)&TEXT(--MID(C65,FIND("-",C65,3)+2,99),"00")&"-R",LEFT(C65,FIND("-",C65))&LEFT(MID(C65,FIND("-",C65)+1,99),1)&TEXT(--MID(C65,FIND("-",C65)+2,99),"00")) -> 37-T29 | E65: 102 | F65: 2243 | G65: =2500+VALUE(MID(D65,1,2)) -> 2537 | H65: ปาล์มใหญ่
A66: Upper | B66: Takuk | C66: 37-T30 | D66: =IF(LEFT(C66,2)="R-",MID(C66,3,FIND("-",C66,3)-3)&"-"&LEFT(MID(C66,FIND("-",C66,3)+1,99),1)&TEXT(--MID(C66,FIND("-",C66,3)+2,99),"00")&"-R",LEFT(C66,FIND("-",C66))&LEFT(MID(C66,FIND("-",C66)+1,99),1)&TEXT(--MID(C66,FIND("-",C66)+2,99),"00")) -> 37-T30 | E66: 113 | F66: 2494 | G66: =2500+VALUE(MID(D66,1,2)) -> 2537 | H66: ปาล์มใหญ่
A67: Upper | B67: Banggun | C67: 49-B13 | D67: =IF(LEFT(C67,2)="R-",MID(C67,3,FIND("-",C67,3)-3)&"-"&LEFT(MID(C67,FIND("-",C67,3)+1,99),1)&TEXT(--MID(C67,FIND("-",C67,3)+2,99),"00")&"-R",LEFT(C67,FIND("-",C67))&LEFT(MID(C67,FIND("-",C67)+1,99),1)&TEXT(--MID(C67,FIND("-",C67)+2,99),"00")) -> 49-B13 | E67: 168 | F67: 4192 | G67: =2500+VALUE(MID(D67,1,2)) -> 2549 | H67: ปาล์มใหญ่
A68: Upper | B68: Banggun | C68: R-49-T20 | D68: =IF(LEFT(C68,2)="R-",MID(C68,3,FIND("-",C68,3)-3)&"-"&LEFT(MID(C68,FIND("-",C68,3)+1,99),1)&TEXT(--MID(C68,FIND("-",C68,3)+2,99),"00")&"-R",LEFT(C68,FIND("-",C68))&LEFT(MID(C68,FIND("-",C68)+1,99),1)&TEXT(--MID(C68,FIND("-",C68)+2,99),"00")) -> 49-T20-R | E68: 113 | F68: 2833 | G68: =2500+VALUE(MID(D68,1,2)) -> 2549 | H68: 2549 - 2552
A69: Upper | B69: Takuk | C69: R-49-T16 | D69: =IF(LEFT(C69,2)="R-",MID(C69,3,FIND("-",C69,3)-3)&"-"&LEFT(MID(C69,FIND("-",C69,3)+1,99),1)&TEXT(--MID(C69,FIND("-",C69,3)+2,99),"00")&"-R",LEFT(C69,FIND("-",C69))&LEFT(MID(C69,FIND("-",C69)+1,99),1)&TEXT(--MID(C69,FIND("-",C69)+2,99),"00")) -> 49-T16-R | E69: 4 | F69: 112 | G69: =2500+VALUE(MID(D69,1,2)) -> 2549 | H69: 2549 - 2552
A70: Upper | B70: Takuk | C70: R-49-T20 | D70: =IF(LEFT(C70,2)="R-",MID(C70,3,FIND("-",C70,3)-3)&"-"&LEFT(MID(C70,FIND("-",C70,3)+1,99),1)&TEXT(--MID(C70,FIND("-",C70,3)+2,99),"00")&"-R",LEFT(C70,FIND("-",C70))&LEFT(MID(C70,FIND("-",C70)+1,99),1)&TEXT(--MID(C70,FIND("-",C70)+2,99),"00")) -> 49-T20-R | E70: 113 | F70: 2833 | G70: =2500+VALUE(MID(D70,1,2)) -> 2549 | H70: 2549 - 2552
...

Sheet Work system
A1: รหัส | B1: ชื่อแปลง | C1: ปีพ.ศ.ปลูก | D1: บล็อก
A2: 11 | B2: ตะกุก | C2: ปาล์มใหญ่ | D2: 29,30
A3: 12 | B3: บางกัน | C3: ปาล์มใหญ่ | D3: 14
A4: 25 | B4: ยวนสาว | C4: ปาล์มใหญ่ | D4: 1,3,4
A5: 276 | B5: R-ปลายราง | C5: ปาล์มใหญ่ | D5: 1,2,
A6: 277 | B6: หมอนไม้ | C6: ปาล์มใหญ่ | D6: 6-9
A7: 278 | B7: R-พันไร่ | C7: ปาล์มใหญ่ | D7: 5
A8: 310 | B8: R-พันไร่ | C8: 49-52 | D8: 5,7
A9: 312 | B9: R-ปลายราง | C9: 49-52 | D9: 7
A10: 393 | B10: ปลายราง | C10: 49-52 | D10: 7
A11: 315 | B11: กะเปา | C11: 49-52 | D11: 4,5
A12: 317 | B12: R-กะเปา | C12: 49-52 | D12: 10,11,12,13
A13: 320 | B13: R-ตะกุก | C13: 49-52 | D13: 10,12,16,20,28
A14: 322 | B14: บางกัน | C14: 49-52 | D14: 7,10,13
A15: 346 | B15: R-กะเปา | C15: 55-58 | D15: 3,8,9
A16: 347 | B16: กะเปา | C16: 55-58 | D16: 1,2
A17: 348 | B17: R-พันไร่ | C17: 55-58 | D17: 6,10
A18: 392 | B18: พันไร่ | C18: 55-58 | D18: 6
A19: 349 | B19: R-หมอนไม้ | C19: 55-58 | D19: 7
A20: 350 | B20: R-ตะกุก | C20: 55-58 | D20: 8,9,11,13,17,18,19,21,28
A21: 351 | B21: ตะกุก | C21: 55-58 | D21: 8
A22: 352 | B22: บางกัน | C22: 55-58 | D22: 3,12,14
A23: 358 | B23: R-ปลายราง | C23: 55-58 | D23: ปี 55 บ.7
A24: 353 | B24: R-พันไร่ | C24: 59-60 | D24: 1,2,3,4,5,8,9,11
A25: 354 | B25: กะเปา | C25: 59-60 | D25: 6
A26: 355 | B26: บางกัน | C26: 59-60 | D26: 4,8,9
A27: 395 | B27: R-รีเพลนท์หมอนไม้ 63 - 65 | C27: 63-65 | D27: 1,2,3,4,5,8
A28: 381 | B28: R-กะเปา-63 - 65 | C28: 63-65 | D28: 1,3,7
A29: 382 | B29: กะเปา-63 - 65 | C29: 63-65 | D29: 1,7
A30: 383 | B30: R-ปลายราง-63 - 65 | C30: 63-65 | D30: 6,7,8,9
A31: 384 | B31: บางกัน-63 - 64 | C31: 63-64 | D31: 2,5,6
A32: 360 | B32: รีเพลนท์ ยวนสาว ปี 63-65 | C32: 63-65 | D32: 1,3
A33: 385 | B33: R-ตะกุก-63 - 65 | C33: 63-65 | D33: 5,22,23
A34: 396 | B34: รีเพลนท์บางกัน 63-65 | C34: 63-65 | D34: 1,2,5,6,11
A35: 362 | B35: R-รีเพลนท์ปลายราง ปี 66 | C35: 66 | D35: 3,4,5
A36: 363 | B36: R-รีเพลนท์หมอนไม้ ปี 66 | C36: 66 | D36: 9
A37: 364 | B37: รีเพลนท์ ตะกุก ปี 66 | C37: 66 | D37: 3,4,6,7
A38: 368 | B38: รีเพลนท์ ยวนสาว ปี 66 | C38: 66 | D38: 2(ปลูกแซม)
A39: 374 | B39: R-รีเพลนท์ปลายราง 67 | C39: 67 | D39: 1,2
A40: 375 | B40: R-รีเพลนท์หมอนไม้ 67 | C40: 67 | D40: 6
...

Sheet Caltivate
A1: No | B1: date | C1: terrain | D1: material | E1: base_unit | F1: dosage_rate | G1: Tree Count | H1: wo_number | I1: AP Code | J1: sku_unit | K1: base_qty | L1: Stock Required (Base Qty) | M1: Stock Required (Original SKU Qty) | N1: Stock Required (Round SKU Qty) | O1: Rate
A2: 0 | B2: 46023 | C2: 65-D05-R | D2: 04-0008 | E2: กิโลกรัม | F2: 1.25 | G2: 2687 | H2: 713|0 | I2: 395 | J2: BAG 50 Kg | K2: 3358.75 | L2: 3358.75 | M2: 67.175 | N2: 67 | O2: =F2*1000 -> 1250
A3: 1 | B3: 46054 | C3: 56-A01 | D3: 04-0169 | E3: กิโลกรัม | F3: 2 | G3: 1950 | H3: 172|0 | I3: 347 | J3: BAG 25 Kg | K3: 3900 | L3: 3900 | M3: 156 | N3: 156 | O3: =F3*1000 -> 2000
A4: 2 | B4: 46054 | C4: 63-A01-R | D4: 04-0169 | E4: กิโลกรัม | F4: 2 | G4: 534 | H4: 684|0 | I4: 381 | J4: BAG 25 Kg | K4: 1068 | L4: 1068 | M4: 42.72 | N4: 43 | O4: =F4*1000 -> 2000
A5: 3 | B5: 46054 | C5: 56-A02 | D5: 04-0169 | E5: กิโลกรัม | F5: 2 | G5: 3835 | H5: 162|0 | I5: 347 | J5: BAG 25 Kg | K5: 7670 | L5: 7670 | M5: 306.8 | N5: 307 | O5: =F5*1000 -> 2000
A6: 4 | B6: 46054 | C6: 56-A03-R | D6: 04-0169 | E6: กิโลกรัม | F6: 2 | G6: 2119 | H6: 156|0 | I6: 346 | J6: BAG 25 Kg | K6: 4238 | L6: 4238 | M6: 169.52 | N6: 170 | O6: =F6*1000 -> 2000
A7: 5 | B7: 46054 | C7: 63-A03-R | D7: 04-0169 | E7: กิโลกรัม | F7: 2 | G7: 980 | H7: 685|0 | I7: 381 | J7: BAG 25 Kg | K7: 1960 | L7: 1960 | M7: 78.4 | N7: 78 | O7: =F7*1000 -> 2000
A8: 6 | B8: 46054 | C8: 50-A04 | D8: 04-0169 | E8: กิโลกรัม | F8: 1.5 | G8: 4864 | H8: 71|0 | I8: 315 | J8: BAG 25 Kg | K8: 7296 | L8: 7296 | M8: 291.84 | N8: 292 | O8: =F8*1000 -> 1500
A9: 7 | B9: 46054 | C9: 50-A05 | D9: 04-0169 | E9: กิโลกรัม | F9: 1.5 | G9: 4608 | H9: 67|0 | I9: 315 | J9: BAG 25 Kg | K9: 6912 | L9: 6912 | M9: 276.48 | N9: 276 | O9: =F9*1000 -> 1500
A10: 8 | B10: 46054 | C10: 60-A06 | D10: 04-0169 | E10: กิโลกรัม | F10: 2 | G10: 3259 | H10: 158|0 | I10: 354 | J10: BAG 25 Kg | K10: 6518 | L10: 6518 | M10: 260.72 | N10: 261 | O10: =F10*1000 -> 2000
A11: 9 | B11: 46054 | C11: 63-A07 | D11: 04-0169 | E11: กิโลกรัม | F11: 2 | G11: 2388 | H11: 252|0 | I11: 382 | J11: BAG 25 Kg | K11: 4776 | L11: 4776 | M11: 191.04 | N11: 191 | O11: =F11*1000 -> 2000
A12: 10 | B12: 46054 | C12: 63-A07-R | D12: 04-0169 | E12: กิโลกรัม | F12: 2 | G12: 309 | H12: 247|0 | I12: 381 | J12: BAG 25 Kg | K12: 618 | L12: 618 | M12: 24.72 | N12: 25 | O12: =F12*1000 -> 2000
A13: 11 | B13: 46054 | C13: 57-A08-R | D13: 04-0169 | E13: กิโลกรัม | F13: 2 | G13: 4308 | H13: 157|0 | I13: 346 | J13: BAG 25 Kg | K13: 8616 | L13: 8616 | M13: 344.64 | N13: 345 | O13: =F13*1000 -> 2000
... A760: 758 | B760: 46327 | C760: 67-T30 | D760: 04-0001 | E760: กิโลกรัม | F760: 0.75 | G760: 3270 | H760: 652|0 | I760: 376 | J760: BAG 50 Kg | K760: 2452.5 | L760: 2452.5 | M760: 49.05 | N760: 49 | O760: =F760*1000 -> 750

Sheet Raw Data
A1: Month | B1: material | C1: n_material | D1: wo_number | E1: area | F1: terrain | G1: # of Trees | H1: Date Planted | I1: Stock (KG) | J1: Stock (BAG) | K1: BAG(25/50) | L1: Rate | M1: AP Code | N1: Planted year | O1: terrain format
A2: 46054 | B2: 04-0169 | C2: Dolomite | D2: 172|0 | E2: =_xlfn.XLOOKUP(F2,Terrain!D:D,Terrain!A:A,"") -> Lower | F2: 56-A01 | G2: 1950 | H2: =2500+VALUE(MID(F2,1,2)) -> 2556 | I2: 3900 | J2: 156 | K2: 156 | L2: =I2*1000/G2 -> 2000 | M2: 347 | N2: =_xlfn.XLOOKUP(F2,Terrain!D:D,Terrain!H:H,"") -> 2555 - 2558 | O2: =F2 & " | " & G2 & " | " & D2 -> 56-A01 | 1950 | 172|0
A3: 46054 | B3: 04-0169 | C3: Dolomite | D3: 684|0 | E3: =_xlfn.XLOOKUP(F3,Terrain!D:D,Terrain!A:A,"") -> Lower | F3: 63-A01-R | G3: 534 | H3: =2500+VALUE(MID(F3,1,2)) -> 2563 | I3: 1068 | J3: 42.72 | K3: 43 | L3: =I3*1000/G3 -> 2000 | M3: 381 | N3: =_xlfn.XLOOKUP(F3,Terrain!D:D,Terrain!H:H,"") -> 2563 - 2565 | O3: =F3 & " | " & G3 & " | " & D3 -> 63-A01-R | 534 | 684|0
A4: 46054 | B4: 04-0169 | C4: Dolomite | D4: 162|0 | E4: =_xlfn.XLOOKUP(F4,Terrain!D:D,Terrain!A:A,"") -> Lower | F4: 56-A02 | G4: 3835 | H4: =2500+VALUE(MID(F4,1,2)) -> 2556 | I4: 7670 | J4: 306.8 | K4: 307 | L4: =I4*1000/G4 -> 2000 | M4: 347 | N4: =_xlfn.XLOOKUP(F4,Terrain!D:D,Terrain!H:H,"") -> 2555 - 2558 | O4: =F4 & " | " & G4 & " | " & D4 -> 56-A02 | 3835 | 162|0
A5: 46054 | B5: 04-0169 | C5: Dolomite | D5: 156|0 | E5: =_xlfn.XLOOKUP(F5,Terrain!D:D,Terrain!A:A,"") -> Lower | F5: 56-A03-R | G5: 2119 | H5: =2500+VALUE(MID(F5,1,2)) -> 2556 | I5: 4238 | J5: 169.52 | K5: 170 | L5: =I5*1000/G5 -> 2000 | M5: 346 | N5: =_xlfn.XLOOKUP(F5,Terrain!D:D,Terrain!H:H,"") -> 2555 - 2558 | O5: =F5 & " | " & G5 & " | " & D5 -> 56-A03-R | 2119 | 156|0
A6: 46054 | B6: 04-0169 | C6: Dolomite | D6: 685|0 | E6: =_xlfn.XLOOKUP(F6,Terrain!D:D,Terrain!A:A,"") -> Lower | F6: 63-A03-R | G6: 980 | H6: =2500+VALUE(MID(F6,1,2)) -> 2563 | I6: 1960 | J6: 78.4 | K6: 78 | L6: =I6*1000/G6 -> 2000 | M6: 381 | N6: =_xlfn.XLOOKUP(F6,Terrain!D:D,Terrain!H:H,"") -> 2563 - 2565 | O6: =F6 & " | " & G6 & " | " & D6 -> 63-A03-R | 980 | 685|0
A7: 46054 | B7: 04-0169 | C7: Dolomite | D7: 71|0 | E7: =_xlfn.XLOOKUP(F7,Terrain!D:D,Terrain!A:A,"") -> Lower | F7: 50-A04 | G7: 4864 | H7: =2500+VALUE(MID(F7,1,2)) -> 2550 | I7: 7296 | J7: 291.84 | K7: 292 | L7: =I7*1000/G7 -> 1500 | M7: 315 | N7: =_xlfn.XLOOKUP(F7,Terrain!D:D,Terrain!H:H,"") -> 2549 - 2552 | O7: =F7 & " | " & G7 & " | " & D7 -> 50-A04 | 4864 | 71|0
A8: 46054 | B8: 04-0169 | C8: Dolomite | D8: 67|0 | E8: =_xlfn.XLOOKUP(F8,Terrain!D:D,Terrain!A:A,"") -> Lower | F8: 50-A05 | G8: 4608 | H8: =2500+VALUE(MID(F8,1,2)) -> 2550 | I8: 6912 | J8: 276.48 | K8: 276 | L8: =I8*1000/G8 -> 1500 | M8: 315 | N8: =_xlfn.XLOOKUP(F8,Terrain!D:D,Terrain!H:H,"") -> 2549 - 2552 | O8: =F8 & " | " & G8 & " | " & D8 -> 50-A05 | 4608 | 67|0
A9: 46054 | B9: 04-0169 | C9: Dolomite | D9: 158|0 | E9: =_xlfn.XLOOKUP(F9,Terrain!D:D,Terrain!A:A,"") -> Lower | F9: 60-A06 | G9: 3259 | H9: =2500+VALUE(MID(F9,1,2)) -> 2560 | I9: 6518 | J9: 260.72 | K9: 261 | L9: =I9*1000/G9 -> 2000 | M9: 354 | N9: =_xlfn.XLOOKUP(F9,Terrain!D:D,Terrain!H:H,"") -> 2559 - 2560 | O9: =F9 & " | " & G9 & " | " & D9 -> 60-A06 | 3259 | 158|0
A10: 46054 | B10: 04-0169 | C10: Dolomite | D10: 252|0 | E10: =_xlfn.XLOOKUP(F10,Terrain!D:D,Terrain!A:A,"") -> Lower | F10: 63-A07 | G10: 2388 | H10: =2500+VALUE(MID(F10,1,2)) -> 2563 | I10: 4776 | J10: 191.04 | K10: 191 | L10: =I10*1000/G10 -> 2000 | M10: 382 | N10: =_xlfn.XLOOKUP(F10,Terrain!D:D,Terrain!H:H,"") -> 2563 - 2565 | O10: =F10 & " | " & G10 & " | " & D10 -> 63-A07 | 2388 | 252|0
A11: 46054 | B11: 04-0169 | C11: Dolomite | D11: 247|0 | E11: =_xlfn.XLOOKUP(F11,Terrain!D:D,Terrain!A:A,"") -> Lower | F11: 63-A07-R | G11: 309 | H11: =2500+VALUE(MID(F11,1,2)) -> 2563 | I11: 618 | J11: 24.72 | K11: 25 | L11: =I11*1000/G11 -> 2000 | M11: 381 | N11: =_xlfn.XLOOKUP(F11,Terrain!D:D,Terrain!H:H,"") -> 2563 - 2565 | O11: =F11 & " | " & G11 & " | " & D11 -> 63-A07-R | 309 | 247|0
A12: 46054 | B12: 04-0169 | C12: Dolomite | D12: 157|0 | E12: =_xlfn.XLOOKUP(F12,Terrain!D:D,Terrain!A:A,"") -> Lower | F12: 57-A08-R | G12: 4308 | H12: =2500+VALUE(MID(F12,1,2)) -> 2557 | I12: 8616 | J12: 344.64 | K12: 345 | L12: =I12*1000/G12 -> 2000 | M12: 346 | N12: =_xlfn.XLOOKUP(F12,Terrain!D:D,Terrain!H:H,"") -> 2555 - 2558 | O12: =F12 & " | " & G12 & " | " & D12 -> 57-A08-R | 4308 | 157|0
A13: 46054 | B13: 04-0169 | C13: Dolomite | D13: 169|0 | E13: =_xlfn.XLOOKUP(F13,Terrain!D:D,Terrain!A:A,"") -> Lower | F13: 57-A09-R | G13: 3861 | H13: =2500+VALUE(MID(F13,1,2)) -> 2557 | I13: 7722 | J13: 308.88 | K13: 309 | L13: =I13*1000/G13 -> 2000 | M13: 346 | N13: =_xlfn.XLOOKUP(F13,Terrain!D:D,Terrain!H:H,"") -> 2555 - 2558 | O13: =F13 & " | " & G13 & " | " & D13 -> 57-A09-R | 3861 | 169|0
... A759: 46327 | B759: 04-0001 | C759: 46-0-0 (3) | D759: 652|0 | E759: =_xlfn.XLOOKUP(F759,Terrain!D:D,Terrain!A:A,"") -> Upper | F759: 67-T30 | G759: 3270 | H759: =2500+VALUE(MID(F759,1,2)) -> 2567 | I759: 2452.5 | J759: 49.05 | K759: 49 | L759: =I759*1000/G759 -> 750 | M759: 376 | N759: =_xlfn.XLOOKUP(F759,Terrain!D:D,Terrain!H:H,"") -> 2567 | O759: =F759 & " | " & G759 & " | " & D759 -> 67-T30 | 3270 | 652|0
C760: =_xlfn.XLOOKUP(B760,Fertilizer!A:A,Fertilizer!B:B,"") -> 0 | E760: =_xlfn.XLOOKUP(F760,Terrain!D:D,Terrain!A:A,"") | F760: =IF(RIGHT(Table2[[#This Row],[terrain]],2)="-R",MID(Table2[[#This Row],[terrain]],FIND("-",Table2[[#This Row],[terrain]])+1,LEN(Table2[[#This Row],[terrain]])-FIND("-",Table2[[#This Row],[terrain]])-2)&"-"&LEFT(Table2[[#This Row],[terrain]],FIND("-",Table2[[#This Row],[terrain]])-1)&"-R",MID(Table2[[#This Row],[terrain]],FIND("-",Table2[[#This Row],[terrain]])+1,99)&"-"&LEFT(Table2[[#This Row],[terrain]],FIND("-",Table2[[#This Row],[terrain]])-1)) -> 0 | H760: =2500+VALUE(MID(F760,1,2)) -> 2556 | L760: =I760*1000/G760 -> #DIV/0! | N760: =_xlfn.XLOOKUP(F760,Terrain!D:D,Terrain!H:H,"") | O760: =F760 & " | " & G760 & " | " & D760 -> | |
C761: =_xlfn.XLOOKUP(B761,Fertilizer!A:A,Fertilizer!B:B,"") -> 0 | E761: =_xlfn.XLOOKUP(F761,Terrain!D:D,Terrain!A:A,"") | F761: =IF(RIGHT(Table2[[#This Row],[terrain]],2)="-R",MID(Table2[[#This Row],[terrain]],FIND("-",Table2[[#This Row],[terrain]])+1,LEN(Table2[[#This Row],[terrain]])-FIND("-",Table2[[#This Row],[terrain]])-2)&"-"&LEFT(Table2[[#This Row],[terrain]],FIND("-",Table2[[#This Row],[terrain]])-1)&"-R",MID(Table2[[#This Row],[terrain]],FIND("-",Table2[[#This Row],[terrain]])+1,99)&"-"&LEFT(Table2[[#This Row],[terrain]],FIND("-",Table2[[#This Row],[terrain]])-1)) -> 0 | H761: =2500+VALUE(MID(F761,1,2)) -> 2556 | L761: =I761*1000/G761 -> #DIV/0! | N761: =_xlfn.XLOOKUP(F761,Terrain!D:D,Terrain!H:H,"") | O761: =F761 & " | " & G761 & " | " & D761 -> | |
C762: =_xlfn.XLOOKUP(B762,Fertilizer!A:A,Fertilizer!B:B,"") -> 0 | E762: =_xlfn.XLOOKUP(F762,Terrain!D:D,Terrain!A:A,"") -> 0 | F762: =IF(RIGHT(Table2[[#This Row],[terrain]],2)="-R",MID(Table2[[#This Row],[terrain]],FIND("-",Table2[[#This Row],[terrain]])+1,LEN(Table2[[#This Row],[terrain]])-FIND("-",Table2[[#This Row],[terrain]])-2)&"-"&LEFT(Table2[[#This Row],[terrain]],FIND("-",Table2[[#This Row],[terrain]])-1)&"-R",MID(Table2[[#This Row],[terrain]],FIND("-",Table2[[#This Row],[terrain]])+1,99)&"-"&LEFT(Table2[[#This Row],[terrain]],FIND("-",Table2[[#This Row],[terrain]])-1)) -> 0 | H762: =2500+VALUE(MID(F762,1,2)) -> 2556 | L762: =I762*1000/G762 -> #DIV/0! | N762: =_xlfn.XLOOKUP(F762,Terrain!D:D,Terrain!H:H,"") | O762: =F762 & " | " & G762 & " | " & D762 -> | |
C763: =_xlfn.XLOOKUP(B763,Fertilizer!A:A,Fertilizer!B:B,"") -> 0 | E763: =_xlfn.XLOOKUP(F763,Terrain!D:D,Terrain!A:A,"") | F763: =IF(RIGHT(Table2[[#This Row],[terrain]],2)="-R",MID(Table2[[#This Row],[terrain]],FIND("-",Table2[[#This Row],[terrain]])+1,LEN(Table2[[#This Row],[terrain]])-FIND("-",Table2[[#This Row],[terrain]])-2)&"-"&LEFT(Table2[[#This Row],[terrain]],FIND("-",Table2[[#This Row],[terrain]])-1)&"-R",MID(Table2[[#This Row],[terrain]],FIND("-",Table2[[#This Row],[terrain]])+1,99)&"-"&LEFT(Table2[[#This Row],[terrain]],FIND("-",Table2[[#This Row],[terrain]])-1)) -> 0 | H763: =2500+VALUE(MID(F763,1,2)) -> 2556 | L763: =I763*1000/G763 -> #DIV/0! | N763: =_xlfn.XLOOKUP(F763,Terrain!D:D,Terrain!H:H,"") | O763: =F763 & " | " & G763 & " | " & D763 -> | |

Sheet Pivot
A3: Sum of BAG(25/50) | B3: Column Labels
B4: ก.พ. | F4: มี.ค. | I4: เม.ย. | N4: พ.ค. | S4: ก.ค. | V4: ส.ค. | AA4: ก.ย. | AF4: ต.ค. | AH4: พ.ย. | AJ4: Grand Total
B5: Dolomite | F5: 0-3-0 (1) | I5: 0-0-60 (1) | N5: 46-0-0 (1) | S5: Borax | V5: 0-0-60 (2) | AA5: 46-0-0 (2) | AF5: 0-0-60 (3) | AH5: 46-0-0 (3)
A6: Row Labels | B6: 500 | C6: 1000 | D6: 1500 | E6: 2000 | F6: 500 | G6: 1500 | H6: 2000 | I6: 250 | J6: 750 | K6: 1250 | L6: 1500 | M6: 1750 | N6: 350 | O6: 500 | P6: 750 | Q6: 1000 | R6: 1250 | S6: 50 | T6: 100 | U6: 100 | V6: 250 | W6: 1000 | X6: 1250 | Y6: 1500 | Z6: 1750 | AA6: 350 | AB6: 500 | AC6: 750 | AD6: 1000 | AE6: 1250 | AF6: 500 | AG6: 1250 | AH6: 500 | AI6: 750
A7: Lower | B7: 172 | C7: 834 | D7: 1744 | E7: 6320 | F7: 222 | G7: 874 | H7: 3157 | I7: 43 | J7: 111 | K7: 337 | L7: 874 | M7: 2767 | N7: 60 | O7: 74 | P7: 203 | Q7: 581 | R7: 1974 | S7: 17 | T7: 10 | U7: 504 | V7: 43 | W7: 146 | X7: 337 | Y7: 874 | Z7: 2767 | AA7: 60 | AB7: 74 | AC7: 203 | AD7: 581 | AE7: 1974 | AF7: 86 | AG7: 521 | AH7: 86 | AI7: 314 | AJ7: 28944
A8: 2566 | C8: 539 | F8: 136 | K8: 337 | P8: 203 | U8: 53 | X8: 337 | AC8: 203 | AG8: 337 | AI8: 203 | AJ8: 2348
A9: 66-D09-R | C9: 120 | F9: 30 | K9: 75 | P9: 45 | U9: 12 | X9: 75 | AC9: 45 | AG9: 75 | AI9: 45 | AJ9: 522
A10: 66-P03-R | C10: 102 | F10: 26 | K10: 64 | P10: 38 | U10: 10 | X10: 64 | AC10: 38 | AG10: 64 | AI10: 38 | AJ10: 444
A11: 66-P04-R | C11: 114 | F11: 29 | K11: 71 | P11: 43 | U11: 11 | X11: 71 | AC11: 43 | AG11: 71 | AI11: 43 | AJ11: 496
A12: 66-P05-R | C12: 124 | F12: 31 | K12: 78 | P12: 47 | U12: 12 | X12: 78 | AC12: 47 | AG12: 78 | AI12: 47 | AJ12: 542
A13: 66-PU2 | C13: 79 | F13: 20 | K13: 49 | P13: 30 | U13: 8 | X13: 49 | AC13: 30 | AG13: 49 | AI13: 30 | AJ13: 344
A14: 2567 | C14: 295 | J14: 111 | O14: 74 | U14: 29 | W14: 146 | AB14: 74 | AG14: 184 | AI14: 111 | AJ14: 1024
A15: 67-D06-R | C15: 115 | J15: 43 | O15: 29 | U15: 11 | W15: 57 | AB15: 29 | AG15: 72 | AI15: 43 | AJ15: 399
A16: 67-P01-R | C16: 87 | J16: 33 | O16: 22 | U16: 9 | W16: 43 | AB16: 22 | AG16: 54 | AI16: 33 | AJ16: 303
A17: 67-P02-R | C17: 93 | J17: 35 | O17: 23 | U17: 9 | W17: 46 | AB17: 23 | AG17: 58 | AI17: 35 | AJ17: 322
A18: 2568 | B18: 172 | F18: 86 | I18: 43 | N18: 60 | S18: 17 | V18: 43 | AA18: 60 | AF18: 86 | AH18: 86 | AJ18: 653
A19: 68-PU1 | B19: 38 | F19: 19 | I19: 9 | N19: 13 | S19: 4 | V19: 9 | AA19: 13 | AF19: 19 | AH19: 19 | AJ19: 143
A20: 68-PU3 | B20: 34 | F20: 17 | I20: 8 | N20: 12 | S20: 3 | V20: 8 | AA20: 12 | AF20: 17 | AH20: 17 | AJ20: 128
A21: 68-PU4 | B21: 28 | F21: 14 | I21: 7 | N21: 10 | S21: 3 | V21: 7 | AA21: 10 | AF21: 14 | AH21: 14 | AJ21: 107
A22: 68-PU5 | B22: 15 | F22: 8 | I22: 4 | N22: 5 | S22: 2 | V22: 4 | AA22: 5 | AF22: 8 | AH22: 8 | AJ22: 59
A23: 68-PU5-R | B23: 23 | F23: 12 | I23: 6 | N23: 8 | S23: 2 | V23: 6 | AA23: 8 | AF23: 12 | AH23: 12 | AJ23: 89
A24: 68-PU6 | B24: 3 | F24: 1 | I24: 1 | N24: 1 | S24: 0 | V24: 1 | AA24: 1 | AF24: 1 | AH24: 1 | AJ24: 10
A25: 68-PU6-R | B25: 31 | F25: 15 | I25: 8 | N25: 11 | S25: 3 | V25: 8 | AA25: 11 | AF25: 15 | AH25: 15 | AJ25: 117
A26: 2549 - 2552 | D26: 1733 | G26: 868 | L26: 868 | Q26: 577 | U26: 116 | Y26: 868 | AD26: 577 | AJ26: 5607
A27: 49-A10-R | D27: 167 | G27: 84 | L27: 84 | Q27: 56 | U27: 11 | Y27: 84 | AD27: 56 | AJ27: 542
A28: 49-A11-R | D28: 145 | G28: 73 | L28: 73 | Q28: 48 | U28: 10 | Y28: 73 | AD28: 48 | AJ28: 470
A29: 49-A12-R | D29: 226 | G29: 113 | L29: 113 | Q29: 75 | U29: 15 | Y29: 113 | AD29: 75 | AJ29: 730
A30: 49-A13-R | D30: 174 | G30: 87 | L30: 87 | Q30: 58 | U30: 12 | Y30: 87 | AD30: 58 | AJ30: 563
A31: 50-A04 | D31: 292 | G31: 146 | L31: 146 | Q31: 97 | U31: 19 | Y31: 146 | AD31: 97 | AJ31: 943
A32: 50-A05 | D32: 276 | G32: 138 | L32: 138 | Q32: 92 | U32: 18 | Y32: 138 | AD32: 92 | AJ32: 892
A33: 50-C05-R | D33: 168 | G33: 84 | L33: 84 | Q33: 56 | U33: 11 | Y33: 84 | AD33: 56 | AJ33: 543
A34: 50-C07-R | D34: 252 | G34: 126 | L34: 126 | Q34: 84 | U34: 17 | Y34: 126 | AD34: 84 | AJ34: 815
A35: 51-P07 | D35: 9 | G35: 5 | L35: 5 | Q35: 3 | U35: 1 | Y35: 5 | AD35: 3 | AJ35: 31
A36: 51-P07-R | D36: 24 | G36: 12 | L36: 12 | Q36: 8 | U36: 2 | Y36: 12 | AD36: 8 | AJ36: 78
A37: 2555 - 2558 | E37: 2073 | H37: 1035 | M37: 907 | R37: 649 | U37: 102 | Z37: 907 | AE37: 649 | AJ37: 6322
A38: 56-A01 | E38: 156 | H38: 78 | M38: 68 | R38: 49 | U38: 8 | Z38: 68 | AE38: 49 | AJ38: 476
A39: 56-A02 | E39: 307 | H39: 153 | M39: 134 | R39: 96 | U39: 15 | Z39: 134 | AE39: 96 | AJ39: 935
A40: 56-A03-R | E40: 170 | H40: 85 | M40: 74 | R40: 53 | U40: 8 | Z40: 74 | AE40: 53 | AJ40: 517
A41: 56-C10-R | E41: 248 | H41: 124 | M41: 109 | R41: 78 | U41: 12 | Z41: 109 | AE41: 78 | AJ41: 758
A42: 56-D07-R | E42: 314 | H42: 157 | M42: 138 | R42: 98 | U42: 16 | Z42: 138 | AE42: 98 | AJ42: 959
...

Sheet Pt-Planted Year
A2: Sum of BAG(25/50)
A4: Mouth | B4: ก.พ. | F4: มี.ค. | I4: เม.ย. | N4: พ.ค. | S4: ก.ค. | U4: ส.ค. | Z4: ก.ย. | AE4: ต.ค. | AG4: พ.ย. | AI4: Grand Total
A5: Fertilizer | B5: Dolomite | F5: 0-3-0 (1) | I5: 0-0-60 (1) | N5: 46-0-0 (1) | S5: Borax | U5: 0-0-60 (2) | Z5: 46-0-0 (2) | AE5: 0-0-60 (3) | AG5: 46-0-0 (3)
A6: Rate | B6: 500 | C6: 1000 | D6: 1500 | E6: 2000 | F6: 500 | G6: 1500 | H6: 2000 | I6: 250 | J6: 750 | K6: 1250 | L6: 1500 | M6: 1750 | N6: 350 | O6: 500 | P6: 750 | Q6: 1000 | R6: 1250 | S6: 50 | T6: 100 | U6: 250 | V6: 1000 | W6: 1250 | X6: 1500 | Y6: 1750 | Z6: 350 | AA6: 500 | AB6: 750 | AC6: 1000 | AD6: 1250 | AE6: 500 | AF6: 1250 | AG6: 500 | AH6: 750
A8: Upper | B8: 122 | C8: 663 | D8: 1293 | E8: 5413 | F8: 159 | G8: 646 | H8: 2711 | I8: 31 | J8: 103 | K8: 242 | L8: 646 | M8: 2370 | N8: 43 | O8: 69 | P8: 145 | Q8: 431 | R8: 1694 | S8: 12 | T8: 422 | U8: 31 | V8: 135 | W8: 242 | X8: 646 | Y8: 2370 | Z8: 43 | AA8: 69 | AB8: 145 | AC8: 431 | AD8: 1694 | AE8: 62 | AF8: 413 | AG8: 62 | AH8: 248 | AI8: =AI9+AI12+AI20+AI34+AI38+AI42+AI48+AI53+AI59 -> 23806
A9: ปาล์มใหญ่ | D9: 260 | G9: 130 | L9: 130 | Q9: 87 | T9: 18 | X9: 130 | AC9: 87 | AI9: 842
A10: B13-49 | D10: 252 | G10: 126 | L10: 126 | Q10: 84 | T10: 17 | X10: 126 | AC10: 84 | AI10: 815 | AK10: =IF(RIGHT(A10,2)="-R",MID(A10,FIND("-",A10)+1,LEN(A10)-FIND("-",A10)-2)&"-"&LEFT(A10,FIND("-",A10)-1)&"-R",MID(A10,FIND("-",A10)+1,99)&"-"&LEFT(A10,FIND("-",A10)-1)) -> 49-B13
A11: B14-30 | D11: 8 | G11: 4 | L11: 4 | Q11: 3 | T11: 1 | X11: 4 | AC11: 3 | AI11: 27 | AK11: =IF(RIGHT(A11,2)="-R",MID(A11,FIND("-",A11)+1,LEN(A11)-FIND("-",A11)-2)&"-"&LEFT(A11,FIND("-",A11)-1)&"-R",MID(A11,FIND("-",A11)+1,99)&"-"&LEFT(A11,FIND("-",A11)-1)) -> 30-B14
A12: 2549 - 2552 | D12: 1033 | G12: 516 | L12: 516 | Q12: 344 | T12: 67 | X12: 516 | AC12: 344 | AI12: =SUM(AI13:AI19) -> 3336
A13: T16-49-R | D13: 7 | G13: 3 | L13: 3 | Q13: 2 | T13: 0 | X13: 3 | AC13: 2 | AI13: 20 | AK13: =IF(RIGHT(A13,2)="-R",MID(A13,FIND("-",A13)+1,LEN(A13)-FIND("-",A13)-2)&"-"&LEFT(A13,FIND("-",A13)-1)&"-R",MID(A13,FIND("-",A13)+1,99)&"-"&LEFT(A13,FIND("-",A13)-1)) -> 49-T16-R
A14: T20-49-R | D14: 170 | G14: 85 | L14: 85 | Q14: 57 | T14: 11 | X14: 85 | AC14: 57 | AI14: 550 | AK14: =IF(RIGHT(A14,2)="-R",MID(A14,FIND("-",A14)+1,LEN(A14)-FIND("-",A14)-2)&"-"&LEFT(A14,FIND("-",A14)-1)&"-R",MID(A14,FIND("-",A14)+1,99)&"-"&LEFT(A14,FIND("-",A14)-1)) -> 49-T20-R
A15: B07-50 | D15: 241 | G15: 121 | L15: 121 | Q15: 80 | T15: 16 | X15: 121 | AC15: 80 | AI15: 780 | AK15: =IF(RIGHT(A15,2)="-R",MID(A15,FIND("-",A15)+1,LEN(A15)-FIND("-",A15)-2)&"-"&LEFT(A15,FIND("-",A15)-1)&"-R",MID(A15,FIND("-",A15)+1,99)&"-"&LEFT(A15,FIND("-",A15)-1)) -> 50-B07
A16: B10-50 | D16: 255 | G16: 127 | L16: 127 | Q16: 85 | T16: 17 | X16: 127 | AC16: 85 | AI16: 823 | AK16: =IF(RIGHT(A16,2)="-R",MID(A16,FIND("-",A16)+1,LEN(A16)-FIND("-",A16)-2)&"-"&LEFT(A16,FIND("-",A16)-1)&"-R",MID(A16,FIND("-",A16)+1,99)&"-"&LEFT(A16,FIND("-",A16)-1)) -> 50-B10
A17: T10-50-R | D17: 172 | G17: 86 | L17: 86 | Q17: 57 | T17: 11 | X17: 86 | AC17: 57 | AI17: 555 | AK17: =IF(RIGHT(A17,2)="-R",MID(A17,FIND("-",A17)+1,LEN(A17)-FIND("-",A17)-2)&"-"&LEFT(A17,FIND("-",A17)-1)&"-R",MID(A17,FIND("-",A17)+1,99)&"-"&LEFT(A17,FIND("-",A17)-1)) -> 50-T10-R
A18: T12-50-R | D18: 182 | G18: 91 | L18: 91 | Q18: 61 | T18: 12 | X18: 91 | AC18: 61 | AI18: 589 | AK18: =IF(RIGHT(A18,2)="-R",MID(A18,FIND("-",A18)+1,LEN(A18)-FIND("-",A18)-2)&"-"&LEFT(A18,FIND("-",A18)-1)&"-R",MID(A18,FIND("-",A18)+1,99)&"-"&LEFT(A18,FIND("-",A18)-1)) -> 50-T12-R
A19: T28-52-R | D19: 6 | G19: 3 | L19: 3 | Q19: 2 | T19: 0 | X19: 3 | AC19: 2 | AI19: 19 | AK19: =IF(RIGHT(A19,2)="-R",MID(A19,FIND("-",A19)+1,LEN(A19)-FIND("-",A19)-2)&"-"&LEFT(A19,FIND("-",A19)-1)&"-R",MID(A19,FIND("-",A19)+1,99)&"-"&LEFT(A19,FIND("-",A19)-1)) -> 52-T28-R
A20: 2555 - 2558 | E20: =SUM(E27:E33) -> 1828 | H20: =SUM(H27:H33) -> 915 | M20: =SUM(M27:M33) -> 801 | R20: =SUM(R27:R33) -> 573 | T20: =SUM(T27:T33) -> 91 | Y20: =SUM(Y27:Y33) -> 801 | AD20: =SUM(AD27:AD33) -> 573 | AI20: =SUM(AI21:AI33) -> 8586
A21: T08-56 | E21: 17 | H21: 9 | M21: 7 | R21: 5 | T21: 1 | Y21: 7 | AD21: 5 | AI21: 51 | AK21: =IF(RIGHT(A21,2)="-R",MID(A21,FIND("-",A21)+1,LEN(A21)-FIND("-",A21)-2)&"-"&LEFT(A21,FIND("-",A21)-1)&"-R",MID(A21,FIND("-",A21)+1,99)&"-"&LEFT(A21,FIND("-",A21)-1)) -> 56-T08
A22: T08-56-R | E22: 225 | H22: 113 | M22: 99 | R22: 70 | T22: 11 | Y22: 99 | AD22: 70 | AI22: 687 | AK22: =IF(RIGHT(A22,2)="-R",MID(A22,FIND("-",A22)+1,LEN(A22)-FIND("-",A22)-2)&"-"&LEFT(A22,FIND("-",A22)-1)&"-R",MID(A22,FIND("-",A22)+1,99)&"-"&LEFT(A22,FIND("-",A22)-1)) -> 56-T08-R
A23: T19-56-R | E23: 256 | H23: 128 | M23: 112 | R23: 80 | T23: 13 | Y23: 112 | AD23: 80 | AI23: 781 | AK23: =IF(RIGHT(A23,2)="-R",MID(A23,FIND("-",A23)+1,LEN(A23)-FIND("-",A23)-2)&"-"&LEFT(A23,FIND("-",A23)-1)&"-R",MID(A23,FIND("-",A23)+1,99)&"-"&LEFT(A23,FIND("-",A23)-1)) -> 56-T19-R
A24: T21-56-R | E24: 241 | H24: 121 | M24: 106 | R24: 75 | T24: 12 | Y24: 106 | AD24: 75 | AI24: 736 | AK24: =IF(RIGHT(A24,2)="-R",MID(A24,FIND("-",A24)+1,LEN(A24)-FIND("-",A24)-2)&"-"&LEFT(A24,FIND("-",A24)-1)&"-R",MID(A24,FIND("-",A24)+1,99)&"-"&LEFT(A24,FIND("-",A24)-1)) -> 56-T21-R
A25: T28-56-R | E25: 112 | H25: 56 | M25: 49 | R25: 35 | T25: 6 | Y25: 49 | AD25: 35 | AI25: 342 | AK25: =IF(RIGHT(A25,2)="-R",MID(A25,FIND("-",A25)+1,LEN(A25)-FIND("-",A25)-2)&"-"&LEFT(A25,FIND("-",A25)-1)&"-R",MID(A25,FIND("-",A25)+1,99)&"-"&LEFT(A25,FIND("-",A25)-1)) -> 56-T28-R
A26: B14-57 | E26: 133 | H26: 67 | M26: 58 | R26: 42 | T26: 7 | Y26: 58 | AD26: 42 | AI26: 407 | AK26: =IF(RIGHT(A26,2)="-R",MID(A26,FIND("-",A26)+1,LEN(A26)-FIND("-",A26)-2)&"-"&LEFT(A26,FIND("-",A26)-1)&"-R",MID(A26,FIND("-",A26)+1,99)&"-"&LEFT(A26,FIND("-",A26)-1)) -> 57-B14
A27: B03-57 | E27: 338 | H27: 169 | M27: 148 | R27: 106 | T27: 17 | Y27: 148 | AD27: 106 | AI27: 1032 | AK27: =IF(RIGHT(A27,2)="-R",MID(A27,FIND("-",A27)+1,LEN(A27)-FIND("-",A27)-2)&"-"&LEFT(A27,FIND("-",A27)-1)&"-R",MID(A27,FIND("-",A27)+1,99)&"-"&LEFT(A27,FIND("-",A27)-1)) -> 57-B03
A28: B12-57 | E28: 341 | H28: 171 | M28: 149 | R28: 107 | T28: 17 | Y28: 149 | AD28: 107 | AI28: 1041 | AK28: =IF(RIGHT(A28,2)="-R",MID(A28,FIND("-",A28)+1,LEN(A28)-FIND("-",A28)-2)&"-"&LEFT(A28,FIND("-",A28)-1)&"-R",MID(A28,FIND("-",A28)+1,99)&"-"&LEFT(A28,FIND("-",A28)-1)) -> 57-B12
A29: T09-58-R | E29: 235 | H29: 117 | M29: 103 | R29: 73 | T29: 12 | Y29: 103 | AD29: 73 | AI29: 716 | AK29: =IF(RIGHT(A29,2)="-R",MID(A29,FIND("-",A29)+1,LEN(A29)-FIND("-",A29)-2)&"-"&LEFT(A29,FIND("-",A29)-1)&"-R",MID(A29,FIND("-",A29)+1,99)&"-"&LEFT(A29,FIND("-",A29)-1)) -> 58-T09-R
A30: T11-58-R | E30: 232 | H30: 116 | M30: 102 | R30: 73 | T30: 12 | Y30: 102 | AD30: 73 | AI30: 710 | AK30: =IF(RIGHT(A30,2)="-R",MID(A30,FIND("-",A30)+1,LEN(A30)-FIND("-",A30)-2)&"-"&LEFT(A30,FIND("-",A30)-1)&"-R",MID(A30,FIND("-",A30)+1,99)&"-"&LEFT(A30,FIND("-",A30)-1)) -> 58-T11-R
A31: T13-58-R | E31: 229 | H31: 115 | M31: 100 | R31: 72 | T31: 11 | Y31: 100 | AD31: 72 | AI31: 699 | AK31: =IF(RIGHT(A31,2)="-R",MID(A31,FIND("-",A31)+1,LEN(A31)-FIND("-",A31)-2)&"-"&LEFT(A31,FIND("-",A31)-1)&"-R",MID(A31,FIND("-",A31)+1,99)&"-"&LEFT(A31,FIND("-",A31)-1)) -> 58-T13-R
A32: T17-58-R | E32: 226 | H32: 113 | M32: 99 | R32: 71 | T32: 11 | Y32: 99 | AD32: 71 | AI32: 690 | AK32: =IF(RIGHT(A32,2)="-R",MID(A32,FIND("-",A32)+1,LEN(A32)-FIND("-",A32)-2)&"-"&LEFT(A32,FIND("-",A32)-1)&"-R",MID(A32,FIND("-",A32)+1,99)&"-"&LEFT(A32,FIND("-",A32)-1)) -> 58-T17-R
A33: T18-58-R | E33: 227 | H33: 114 | M33: 100 | R33: 71 | T33: 11 | Y33: 100 | AD33: 71 | AI33: 694 | AK33: =IF(RIGHT(A33,2)="-R",MID(A33,FIND("-",A33)+1,LEN(A33)-FIND("-",A33)-2)&"-"&LEFT(A33,FIND("-",A33)-1)&"-R",MID(A33,FIND("-",A33)+1,99)&"-"&LEFT(A33,FIND("-",A33)-1)) -> 58-T18-R
A34: 2559 - 2560 | E34: 916 | H34: 458 | M34: 401 | R34: 286 | T34: 46 | Y34: 401 | AD34: 286 | AI34: 2794
A35: B04-60 | E35: 308 | H35: 154 | M35: 135 | R35: 96 | T35: 15 | Y35: 135 | AD35: 96 | AI35: 939 | AK35: =IF(RIGHT(A35,2)="-R",MID(A35,FIND("-",A35)+1,LEN(A35)-FIND("-",A35)-2)&"-"&LEFT(A35,FIND("-",A35)-1)&"-R",MID(A35,FIND("-",A35)+1,99)&"-"&LEFT(A35,FIND("-",A35)-1)) -> 60-B04
A36: B08-60 | E36: 278 | H36: 139 | M36: 122 | R36: 87 | T36: 14 | Y36: 122 | AD36: 87 | AI36: 849 | AK36: =IF(RIGHT(A36,2)="-R",MID(A36,FIND("-",A36)+1,LEN(A36)-FIND("-",A36)-2)&"-"&LEFT(A36,FIND("-",A36)-1)&"-R",MID(A36,FIND("-",A36)+1,99)&"-"&LEFT(A36,FIND("-",A36)-1)) -> 60-B08
A37: B09-60 | E37: 330 | H37: 165 | M37: 144 | R37: 103 | T37: 17 | Y37: 144 | AD37: 103 | AI37: 1006 | AK37: =IF(RIGHT(A37,2)="-R",MID(A37,FIND("-",A37)+1,LEN(A37)-FIND("-",A37)-2)&"-"&LEFT(A37,FIND("-",A37)-1)&"-R",MID(A37,FIND("-",A37)+1,99)&"-"&LEFT(A37,FIND("-",A37)-1)) -> 60-B09
A38: 2563 - 2564 | E38: 823 | H38: 412 | M38: 360 | R38: 258 | T38: 42 | Y38: 360 | AD38: 258 | AI38: 2513
A39: B02-64 | E39: 278 | H39: 139 | M39: 122 | R39: 87 | T39: 14 | Y39: 122 | AD39: 87 | AI39: 849 | AK39: =IF(RIGHT(A39,2)="-R",MID(A39,FIND("-",A39)+1,LEN(A39)-FIND("-",A39)-2)&"-"&LEFT(A39,FIND("-",A39)-1)&"-R",MID(A39,FIND("-",A39)+1,99)&"-"&LEFT(A39,FIND("-",A39)-1)) -> 64-B02
A40: B05-64 | E40: 251 | H40: 126 | M40: 110 | R40: 79 | T40: 13 | Y40: 110 | AD40: 79 | AI40: 768 | AK40: =IF(RIGHT(A40,2)="-R",MID(A40,FIND("-",A40)+1,LEN(A40)-FIND("-",A40)-2)&"-"&LEFT(A40,FIND("-",A40)-1)&"-R",MID(A40,FIND("-",A40)+1,99)&"-"&LEFT(A40,FIND("-",A40)-1)) -> 64-B05
A41: B06-64 | E41: 294 | H41: 147 | M41: 128 | R41: 92 | T41: 15 | Y41: 128 | AD41: 92 | AI41: 896 | AK41: =IF(RIGHT(A41,2)="-R",MID(A41,FIND("-",A41)+1,LEN(A41)-FIND("-",A41)-2)&"-"&LEFT(A41,FIND("-",A41)-1)&"-R",MID(A41,FIND("-",A41)+1,99)&"-"&LEFT(A41,FIND("-",A41)-1)) -> 64-B06
A42: 2563 - 2565 | E42: 862 | H42: 432 | M42: 377 | R42: 270 | T42: 42 | Y42: 377 | AD42: 270 | AI42: 2630
A43: T05-63-R | E43: 243 | H43: 121 | M43: 106 | R43: 76 | T43: 12 | Y43: 106 | AD43: 76 | AI43: 740 | AK43: =IF(RIGHT(A43,2)="-R",MID(A43,FIND("-",A43)+1,LEN(A43)-FIND("-",A43)-2)&"-"&LEFT(A43,FIND("-",A43)-1)&"-R",MID(A43,FIND("-",A43)+1,99)&"-"&LEFT(A43,FIND("-",A43)-1)) -> 63-T05-R
...

Sheet Pt-Area
A2: Sum of BAG(25/50)
A4: Mouth | B4: ก.พ. | F4: มี.ค. | I4: เม.ย. | N4: พ.ค. | S4: ก.ค. | U4: ส.ค. | Z4: ก.ย. | AE4: ต.ค. | AG4: พ.ย. | AI4: Grand Total
A5: Fertilizer | B5: Dolomite | F5: 0-3-0 (1) | I5: 0-0-60 (1) | N5: 46-0-0 (1) | S5: Borax | U5: 0-0-60 (2) | Z5: 46-0-0 (2) | AE5: 0-0-60 (3) | AG5: 46-0-0 (3)
A6: Rate | B6: 500 | C6: 1000 | D6: 1500 | E6: 2000 | F6: 500 | G6: 1500 | H6: 2000 | I6: 250 | J6: 750 | K6: 1250 | L6: 1500 | M6: 1750 | N6: 350 | O6: 500 | P6: 750 | Q6: 1000 | R6: 1250 | S6: 50 | T6: 100 | U6: 250 | V6: 1000 | W6: 1250 | X6: 1500 | Y6: 1750 | Z6: 350 | AA6: 500 | AB6: 750 | AC6: 1000 | AD6: 1250 | AE6: 500 | AF6: 1250 | AG6: 500 | AH6: 750
A8: Lower | B8: 172 | C8: 834 | D8: 1744 | E8: 6320 | F8: 222 | G8: 874 | H8: 3157 | I8: 43 | J8: 111 | K8: 337 | L8: 874 | M8: 2767 | N8: 60 | O8: 74 | P8: 203 | Q8: 581 | R8: 1974 | S8: 17 | T8: 514 | U8: 43 | V8: 146 | W8: 337 | X8: 874 | Y8: 2767 | Z8: 60 | AA8: 74 | AB8: 203 | AC8: 581 | AD8: 1974 | AE8: 86 | AF8: 521 | AG8: 86 | AH8: 314 | AI8: 28944
A9: A01-56 | E9: 156 | H9: 78 | M9: 68 | R9: 49 | T9: 8 | Y9: 68 | AD9: 49 | AI9: 476 | AL9: =IF(RIGHT(A9,2)="-R",MID(A9,FIND("-",A9)+1,LEN(A9)-FIND("-",A9)-2)&"-"&LEFT(A9,FIND("-",A9)-1)&"-R",MID(A9,FIND("-",A9)+1,99)&"-"&LEFT(A9,FIND("-",A9)-1)) -> 56-A01
A10: A01-63-R | E10: 43 | H10: 21 | M10: 19 | R10: 13 | T10: 2 | Y10: 19 | AD10: 13 | AI10: 130 | AL10: =IF(RIGHT(A10,2)="-R",MID(A10,FIND("-",A10)+1,LEN(A10)-FIND("-",A10)-2)&"-"&LEFT(A10,FIND("-",A10)-1)&"-R",MID(A10,FIND("-",A10)+1,99)&"-"&LEFT(A10,FIND("-",A10)-1)) -> 63-A01-R
A11: A02-56 | E11: 307 | H11: 153 | M11: 134 | R11: 96 | T11: 15 | Y11: 134 | AD11: 96 | AI11: 935 | AL11: =IF(RIGHT(A11,2)="-R",MID(A11,FIND("-",A11)+1,LEN(A11)-FIND("-",A11)-2)&"-"&LEFT(A11,FIND("-",A11)-1)&"-R",MID(A11,FIND("-",A11)+1,99)&"-"&LEFT(A11,FIND("-",A11)-1)) -> 56-A02
A12: A03-56-R | E12: 170 | H12: 85 | M12: 74 | R12: 53 | T12: 8 | Y12: 74 | AD12: 53 | AI12: 517 | AL12: =IF(RIGHT(A12,2)="-R",MID(A12,FIND("-",A12)+1,LEN(A12)-FIND("-",A12)-2)&"-"&LEFT(A12,FIND("-",A12)-1)&"-R",MID(A12,FIND("-",A12)+1,99)&"-"&LEFT(A12,FIND("-",A12)-1)) -> 56-A03-R
A13: A03-63-R | E13: 78 | H13: 39 | M13: 34 | R13: 25 | T13: 4 | Y13: 34 | AD13: 25 | AI13: 239 | AL13: =IF(RIGHT(A13,2)="-R",MID(A13,FIND("-",A13)+1,LEN(A13)-FIND("-",A13)-2)&"-"&LEFT(A13,FIND("-",A13)-1)&"-R",MID(A13,FIND("-",A13)+1,99)&"-"&LEFT(A13,FIND("-",A13)-1)) -> 63-A03-R
A14: A04-50 | D14: 292 | G14: 146 | L14: 146 | Q14: 97 | T14: 19 | X14: 146 | AC14: 97 | AI14: 943 | AL14: =IF(RIGHT(A14,2)="-R",MID(A14,FIND("-",A14)+1,LEN(A14)-FIND("-",A14)-2)&"-"&LEFT(A14,FIND("-",A14)-1)&"-R",MID(A14,FIND("-",A14)+1,99)&"-"&LEFT(A14,FIND("-",A14)-1)) -> 50-A04
A15: A05-50 | D15: 276 | G15: 138 | L15: 138 | Q15: 92 | T15: 18 | X15: 138 | AC15: 92 | AI15: 892 | AL15: =IF(RIGHT(A15,2)="-R",MID(A15,FIND("-",A15)+1,LEN(A15)-FIND("-",A15)-2)&"-"&LEFT(A15,FIND("-",A15)-1)&"-R",MID(A15,FIND("-",A15)+1,99)&"-"&LEFT(A15,FIND("-",A15)-1)) -> 50-A05
A16: A06-60 | E16: 261 | H16: 130 | M16: 114 | R16: 81 | T16: 13 | Y16: 114 | AD16: 81 | AI16: 794 | AL16: =IF(RIGHT(A16,2)="-R",MID(A16,FIND("-",A16)+1,LEN(A16)-FIND("-",A16)-2)&"-"&LEFT(A16,FIND("-",A16)-1)&"-R",MID(A16,FIND("-",A16)+1,99)&"-"&LEFT(A16,FIND("-",A16)-1)) -> 60-A06
A17: A07-63 | E17: 191 | H17: 96 | M17: 84 | R17: 60 | T17: 10 | Y17: 84 | AD17: 60 | AI17: 585 | AL17: =IF(RIGHT(A17,2)="-R",MID(A17,FIND("-",A17)+1,LEN(A17)-FIND("-",A17)-2)&"-"&LEFT(A17,FIND("-",A17)-1)&"-R",MID(A17,FIND("-",A17)+1,99)&"-"&LEFT(A17,FIND("-",A17)-1)) -> 63-A07
A18: A07-63-R | E18: 25 | H18: 12 | M18: 11 | R18: 8 | T18: 1 | Y18: 11 | AD18: 8 | AI18: 76 | AL18: =IF(RIGHT(A18,2)="-R",MID(A18,FIND("-",A18)+1,LEN(A18)-FIND("-",A18)-2)&"-"&LEFT(A18,FIND("-",A18)-1)&"-R",MID(A18,FIND("-",A18)+1,99)&"-"&LEFT(A18,FIND("-",A18)-1)) -> 63-A07-R
A19: A08-57-R | E19: 345 | H19: 172 | M19: 151 | R19: 108 | T19: 17 | Y19: 151 | AD19: 108 | AI19: 1052 | AL19: =IF(RIGHT(A19,2)="-R",MID(A19,FIND("-",A19)+1,LEN(A19)-FIND("-",A19)-2)&"-"&LEFT(A19,FIND("-",A19)-1)&"-R",MID(A19,FIND("-",A19)+1,99)&"-"&LEFT(A19,FIND("-",A19)-1)) -> 57-A08-R
A20: A09-57-R | E20: 309 | H20: 154 | M20: 135 | R20: 97 | T20: 15 | Y20: 135 | AD20: 97 | AI20: 942 | AL20: =IF(RIGHT(A20,2)="-R",MID(A20,FIND("-",A20)+1,LEN(A20)-FIND("-",A20)-2)&"-"&LEFT(A20,FIND("-",A20)-1)&"-R",MID(A20,FIND("-",A20)+1,99)&"-"&LEFT(A20,FIND("-",A20)-1)) -> 57-A09-R
A21: A10-49-R | D21: 167 | G21: 84 | L21: 84 | Q21: 56 | T21: 11 | X21: 84 | AC21: 56 | AI21: 542 | AL21: =IF(RIGHT(A21,2)="-R",MID(A21,FIND("-",A21)+1,LEN(A21)-FIND("-",A21)-2)&"-"&LEFT(A21,FIND("-",A21)-1)&"-R",MID(A21,FIND("-",A21)+1,99)&"-"&LEFT(A21,FIND("-",A21)-1)) -> 49-A10-R
A22: A11-49-R | D22: 145 | G22: 73 | L22: 73 | Q22: 48 | T22: 10 | X22: 73 | AC22: 48 | AI22: 470 | AL22: =IF(RIGHT(A22,2)="-R",MID(A22,FIND("-",A22)+1,LEN(A22)-FIND("-",A22)-2)&"-"&LEFT(A22,FIND("-",A22)-1)&"-R",MID(A22,FIND("-",A22)+1,99)&"-"&LEFT(A22,FIND("-",A22)-1)) -> 49-A11-R
A23: A12-49-R | D23: 226 | G23: 113 | L23: 113 | Q23: 75 | T23: 15 | X23: 113 | AC23: 75 | AI23: 730 | AL23: =IF(RIGHT(A23,2)="-R",MID(A23,FIND("-",A23)+1,LEN(A23)-FIND("-",A23)-2)&"-"&LEFT(A23,FIND("-",A23)-1)&"-R",MID(A23,FIND("-",A23)+1,99)&"-"&LEFT(A23,FIND("-",A23)-1)) -> 49-A12-R
A24: A13-49-R | D24: 174 | G24: 87 | L24: 87 | Q24: 58 | T24: 12 | X24: 87 | AC24: 58 | AI24: 563 | AL24: =IF(RIGHT(A24,2)="-R",MID(A24,FIND("-",A24)+1,LEN(A24)-FIND("-",A24)-2)&"-"&LEFT(A24,FIND("-",A24)-1)&"-R",MID(A24,FIND("-",A24)+1,99)&"-"&LEFT(A24,FIND("-",A24)-1)) -> 49-A13-R
A25: C01-60-R | E25: 217 | H25: 108 | M25: 95 | R25: 68 | T25: 11 | Y25: 95 | AD25: 68 | AI25: 662 | AL25: =IF(RIGHT(A25,2)="-R",MID(A25,FIND("-",A25)+1,LEN(A25)-FIND("-",A25)-2)&"-"&LEFT(A25,FIND("-",A25)-1)&"-R",MID(A25,FIND("-",A25)+1,99)&"-"&LEFT(A25,FIND("-",A25)-1)) -> 60-C01-R
A26: C02-60-R | E26: 171 | H26: 85 | M26: 75 | R26: 53 | T26: 9 | Y26: 75 | AD26: 53 | AI26: 521 | AL26: =IF(RIGHT(A26,2)="-R",MID(A26,FIND("-",A26)+1,LEN(A26)-FIND("-",A26)-2)&"-"&LEFT(A26,FIND("-",A26)-1)&"-R",MID(A26,FIND("-",A26)+1,99)&"-"&LEFT(A26,FIND("-",A26)-1)) -> 60-C02-R
A27: C03-59-R | E27: 267 | H27: 133 | M27: 117 | R27: 83 | T27: 13 | Y27: 117 | AD27: 83 | AI27: 813 | AL27: =IF(RIGHT(A27,2)="-R",MID(A27,FIND("-",A27)+1,LEN(A27)-FIND("-",A27)-2)&"-"&LEFT(A27,FIND("-",A27)-1)&"-R",MID(A27,FIND("-",A27)+1,99)&"-"&LEFT(A27,FIND("-",A27)-1)) -> 59-C03-R
A28: C04-59-R | E28: 202 | H28: 101 | M28: 88 | R28: 63 | T28: 10 | Y28: 88 | AD28: 63 | AI28: 615 | AL28: =IF(RIGHT(A28,2)="-R",MID(A28,FIND("-",A28)+1,LEN(A28)-FIND("-",A28)-2)&"-"&LEFT(A28,FIND("-",A28)-1)&"-R",MID(A28,FIND("-",A28)+1,99)&"-"&LEFT(A28,FIND("-",A28)-1)) -> 59-C04-R
A29: C05-22-R | D29: 11 | G29: 6 | L29: 6 | Q29: 4 | T29: 1 | X29: 6 | AC29: 4 | AI29: 38 | AL29: =IF(RIGHT(A29,2)="-R",MID(A29,FIND("-",A29)+1,LEN(A29)-FIND("-",A29)-2)&"-"&LEFT(A29,FIND("-",A29)-1)&"-R",MID(A29,FIND("-",A29)+1,99)&"-"&LEFT(A29,FIND("-",A29)-1)) -> 22-C05-R
A30: C05-50-R | D30: 168 | G30: 84 | L30: 84 | Q30: 56 | T30: 11 | X30: 84 | AC30: 56 | AI30: 543 | AL30: =IF(RIGHT(A30,2)="-R",MID(A30,FIND("-",A30)+1,LEN(A30)-FIND("-",A30)-2)&"-"&LEFT(A30,FIND("-",A30)-1)&"-R",MID(A30,FIND("-",A30)+1,99)&"-"&LEFT(A30,FIND("-",A30)-1)) -> 50-C05-R
A31: C05-60-R | E31: 58 | H31: 29 | M31: 25 | R31: 18 | T31: 3 | Y31: 25 | AD31: 18 | AI31: 176 | AL31: =IF(RIGHT(A31,2)="-R",MID(A31,FIND("-",A31)+1,LEN(A31)-FIND("-",A31)-2)&"-"&LEFT(A31,FIND("-",A31)-1)&"-R",MID(A31,FIND("-",A31)+1,99)&"-"&LEFT(A31,FIND("-",A31)-1)) -> 60-C05-R
A32: C06-57 | E32: 24 | H32: 12 | M32: 11 | R32: 8 | T32: 1 | Y32: 11 | AD32: 8 | AI32: 75 | AL32: =IF(RIGHT(A32,2)="-R",MID(A32,FIND("-",A32)+1,LEN(A32)-FIND("-",A32)-2)&"-"&LEFT(A32,FIND("-",A32)-1)&"-R",MID(A32,FIND("-",A32)+1,99)&"-"&LEFT(A32,FIND("-",A32)-1)) -> 57-C06
A33: C06-57-R | E33: 200 | H33: 100 | M33: 87 | R33: 62 | T33: 10 | Y33: 87 | AD33: 62 | AI33: 608 | AL33: =IF(RIGHT(A33,2)="-R",MID(A33,FIND("-",A33)+1,LEN(A33)-FIND("-",A33)-2)&"-"&LEFT(A33,FIND("-",A33)-1)&"-R",MID(A33,FIND("-",A33)+1,99)&"-"&LEFT(A33,FIND("-",A33)-1)) -> 57-C06-R
A34: C07-50-R | D34: 252 | G34: 126 | L34: 126 | Q34: 84 | T34: 17 | X34: 126 | AC34: 84 | AI34: 815 | AL34: =IF(RIGHT(A34,2)="-R",MID(A34,FIND("-",A34)+1,LEN(A34)-FIND("-",A34)-2)&"-"&LEFT(A34,FIND("-",A34)-1)&"-R",MID(A34,FIND("-",A34)+1,99)&"-"&LEFT(A34,FIND("-",A34)-1)) -> 50-C07-R
A35: C08-59-R | E35: 231 | H35: 116 | M35: 101 | R35: 72 | T35: 12 | Y35: 101 | AD35: 72 | AI35: 705 | AL35: =IF(RIGHT(A35,2)="-R",MID(A35,FIND("-",A35)+1,LEN(A35)-FIND("-",A35)-2)&"-"&LEFT(A35,FIND("-",A35)-1)&"-R",MID(A35,FIND("-",A35)+1,99)&"-"&LEFT(A35,FIND("-",A35)-1)) -> 59-C08-R
A36: C09-59-R | E36: 152 | H36: 76 | M36: 67 | R36: 48 | T36: 8 | Y36: 67 | AD36: 48 | AI36: 466 | AL36: =IF(RIGHT(A36,2)="-R",MID(A36,FIND("-",A36)+1,LEN(A36)-FIND("-",A36)-2)&"-"&LEFT(A36,FIND("-",A36)-1)&"-R",MID(A36,FIND("-",A36)+1,99)&"-"&LEFT(A36,FIND("-",A36)-1)) -> 59-C09-R
A37: C10-56-R | E37: 248 | H37: 124 | M37: 109 | R37: 78 | T37: 12 | Y37: 109 | AD37: 78 | AI37: 758 | AL37: =IF(RIGHT(A37,2)="-R",MID(A37,FIND("-",A37)+1,LEN(A37)-FIND("-",A37)-2)&"-"&LEFT(A37,FIND("-",A37)-1)&"-R",MID(A37,FIND("-",A37)+1,99)&"-"&LEFT(A37,FIND("-",A37)-1)) -> 56-C10-R
A38: C11-59-R | E38: 183 | H38: 92 | M38: 80 | R38: 57 | T38: 9 | Y38: 80 | AD38: 57 | AI38: 558 | AL38: =IF(RIGHT(A38,2)="-R",MID(A38,FIND("-",A38)+1,LEN(A38)-FIND("-",A38)-2)&"-"&LEFT(A38,FIND("-",A38)-1)&"-R",MID(A38,FIND("-",A38)+1,99)&"-"&LEFT(A38,FIND("-",A38)-1)) -> 59-C11-R
A39: D01-65-R | E39: 202 | H39: 101 | M39: 89 | R39: 63 | T39: 10 | Y39: 89 | AD39: 63 | AI39: 617 | AL39: =IF(RIGHT(A39,2)="-R",MID(A39,FIND("-",A39)+1,LEN(A39)-FIND("-",A39)-2)&"-"&LEFT(A39,FIND("-",A39)-1)&"-R",MID(A39,FIND("-",A39)+1,99)&"-"&LEFT(A39,FIND("-",A39)-1)) -> 65-D01-R
A40: D02-64-R | E40: 228 | H40: 114 | M40: 100 | R40: 71 | T40: 11 | Y40: 100 | AD40: 71 | AI40: 695 | AL40: =IF(RIGHT(A40,2)="-R",MID(A40,FIND("-",A40)+1,LEN(A40)-FIND("-",A40)-2)&"-"&LEFT(A40,FIND("-",A40)-1)&"-R",MID(A40,FIND("-",A40)+1,99)&"-"&LEFT(A40,FIND("-",A40)-1)) -> 64-D02-R
A41: D03-65-R | E41: 224 | H41: 112 | M41: 98 | R41: 70 | T41: 11 | Y41: 98 | AD41: 70 | AI41: 683 | AL41: =IF(RIGHT(A41,2)="-R",MID(A41,FIND("-",A41)+1,LEN(A41)-FIND("-",A41)-2)&"-"&LEFT(A41,FIND("-",A41)-1)&"-R",MID(A41,FIND("-",A41)+1,99)&"-"&LEFT(A41,FIND("-",A41)-1)) -> 65-D03-R
A42: D04-65-R | E42: 226 | H42: 113 | M42: 99 | R42: 70 | T42: 11 | Y42: 99 | AD42: 70 | AI42: 688 | AL42: =IF(RIGHT(A42,2)="-R",MID(A42,FIND("-",A42)+1,LEN(A42)-FIND("-",A42)-2)&"-"&LEFT(A42,FIND("-",A42)-1)&"-R",MID(A42,FIND("-",A42)+1,99)&"-"&LEFT(A42,FIND("-",A42)-1)) -> 65-D04-R
A43: D05-65-R | E43: 215 | H43: 107 | M43: 94 | R43: 67 | T43: 11 | Y43: 94 | AD43: 67 | AI43: 655 | AL43: =IF(RIGHT(A43,2)="-R",MID(A43,FIND("-",A43)+1,LEN(A43)-FIND("-",A43)-2)&"-"&LEFT(A43,FIND("-",A43)-1)&"-R",MID(A43,FIND("-",A43)+1,99)&"-"&LEFT(A43,FIND("-",A43)-1)) -> 65-D05-R
...
