Workbook

Sheet จน.ปาล์ม 69 
A1: จำนวนต้นปาล์ม 2569
A2: รุ่นปาล์ม | B2: แปลงปฏิบัติการ | C2: แปลง | D2: บล็อก | E2: จำนวน(ไร่) | F2: จำนวน(ต้น) | G2: จน.ต้น/ไร่ | H2: Hactare (1H=6.25ไร่) | I2: 6.25
A3: 22-37 (แก่) | B3: ตอนบน
C4: ตะกุก | D4: 37-T29 | E4: 136 | F4: 2243 | G4: 22 | H4: =E4/$I2 -> 21.76
D5: 37-T30 | E5: 151 | F5: 2494 | G5: 22 | H5: =E5/$I$2 -> 24.16
B6: รวมพื้นที่ปาล์มแก่ แปลงตะกุก (ไร่/ต้น) | E6: =SUM(E4:E5) -> 287 | F6: =SUM(F4:F5) -> 4737 | H6: =SUM(H4:H5) -> 45.92
C7: บางกัน | D7: 30-B14 | E7: 6 | F7: 126 | G7: 22 | H7: =E7/$I$2 -> 0.96
B8: รวมพื้นที่ปาล์มแก่ แปลงบางกัน (ไร่/ต้น) | E8: =SUM(E7) -> 6 | F8: =SUM(F7) -> 126 | H8: =SUM(H7) -> 0.96
B9: รวมพื้นที่ปาล์มแก่ตอนบน | E9: =+E6+E8 -> 293 | F9: =+F6+F8 -> 4863 | H9: =H6+H8 -> 46.88
B10: ตอนล่าง
C11: พันไร่ | D11: R-22-C5 | E11: 8 | F11: 184 | G11: 22 | H11: =E11/$I$2 -> 1.28
B12: รวมพื้นที่ปาล์มแก่ แปลงพันไร่ (ไร่/ต้น) | E12: =SUM(E11) -> 8 | F12: =SUM(F11) -> 184 | H12: =H11 -> 1.28
C13: ยวนสาว | D13: 30-PU1 | E13: 82 | F13: 1813 | G13: 22 | H13: =E13/$I$2 -> 13.12
D14: 30-PU3 | E14: 72 | F14: 1574 | G14: 22 | H14: =E14/$I$2 -> 11.52
D15: 30-PU4 | E15: 69 | F15: 1509 | G15: 22 | H15: =E15/$I$2 -> 11.04
B16: รวมพื้นที่ปาล์มแก่ แปลงยวนสาว (ไร่/ต้น) | E16: =SUM(E13:E15) -> 223 | F16: =SUM(F13:F15) -> 4896 | H16: =SUM(H13:H15) -> 35.68
B17: รวมพื้นที่ปาล์มแก่ตอนล่าง | E17: =E12+E16 -> 231 | F17: =F12+F16 -> 5080 | H17: =H12+H16 -> 36.96
A18: รวมพื้นที่ปาล์มแก่ทั้งหมด | E18: =+E9+E17 -> 524 | F18: =+F9+F17 -> 9943 | H18: =H17+H9 -> 83.84
A19: 49-52 | B19: ตอนบน
C20: ตะกุก | D20: 49-T16-R | E20: 4 | F20: 112 | G20: 25 | H20: =E20/$I$2 -> 0.64
D21: 49-T20-R | E21: 113 | F21: 2833 | G21: 25 | H21: =E21/$I$2 -> 18.08
D22: 50-T10-R | E22: 115 | F22: 2872 | G22: 25 | H22: =E22/$I$2 -> 18.4
D23: 50-T12-R | E23: 121 | F23: 3030 | G23: 25 | H23: =E23/$I$2 -> 19.36
D24: 52-T28-R | E24: 4 | F24: 92 | G24: 25 | H24: =E24/$I$2 -> 0.64
B25: รวมพื้นที่ปาล์ม 49-52 แปลงตะกุก (ไร่/ต้น) | E25: =SUM(E20:E24) -> 357 | F25: =SUM(F20:F24) -> 8939 | H25: =SUM(H20:H24) -> 57.12
C26: บางกัน | D26: 49-B13 | E26: 168 | F26: 4192 | G26: 25 | H26: =E26/$I$2 -> 26.88
D27: 50-B07 | E27: 157 | F27: 4022 | G27: 27, 25 | H27: =E27/$I$2 -> 25.12
D28: 50-B10 | E28: 170 | F28: 4245 | G28: 25 | H28: =E28/$I$2 -> 27.2
B29: รวมพื้นที่ปาล์ม 49-52 แปลงบางกัน (ไร่/ต้น) | E29: =SUM(E26:E28) -> 495 | F29: =SUM(F26:F28) -> 12459 | H29: =SUM(H26:H28) -> 79.2
B30: รวมพื้นที่ปาล์ม 49-52 ตอนบน | E30: =+E25+E29 -> 852 | F30: =+F25+F29 -> 21398 | H30: =H25+H29 -> 136.32
B31: ตอนล่าง
C32: กะเปา | D32: 49-A10-R | E32: 112 | F32: 2785 | G32: 25 | H32: =E32/$I$2 -> 17.92
D33: 49-A11-R | E33: 98 | F33: 2421 | G33: 25 | H33: =E33/$I$2 -> 15.68
D34: 49-A12-R | E34: 153 | F34: 3764 | G34: 25 | H34: =E34/$I$2 -> 24.48
D35: 49-A13-R | E35: 116 | F35: 2893 | G35: 25 | H35: =E35/$I$2 -> 18.56
D36: 50-A04 | E36: 195 | F36: 4864 | G36: 25 | H36: =E36/$I$2 -> 31.2
D37: 50-A05 | E37: 171 | F37: 4608 | G37: 27 | H37: =E37/$I$2 -> 27.36
B38: รวมพื้นที่ปาล์ม 49-52 กะเปา (ไร่/ต้น) | E38: =SUM(E32:E37) -> 845 | F38: =SUM(F32:F37) -> 21335 | H38: =SUM(H32:H37) -> 135.2
C39: ปรายราง | D39: 51-P07-R | E39: 15 | F39: 401 | G39: 27 | H39: =E39/$I$2 -> 2.4
D40: 51-P07 | E40: 5 | F40: 152 | G40: 27 | H40: =E40/$I$2 -> 0.8
...

Sheet ผลผลิต
B1: ผลผลิตและค่าจ้างตัดปาล์ม
B2: แปลงปฏิบัติการ | C2: แปลง | D2: บล็อก | E2: จำนวน(ไร่) | F2: จำนวน(ต้น) | G2: จน.ต้น/ไร่ | H2: (ตัน/ไร่) | I2: ผลผลิต | J2: อัตราค่าจ้างตัด (บาท/ตัน) | K2: ค่าตัดปาล์ม | L2: ผู้รับเหมา
N3: สูตรการคำนวณ : ผลผลิต * อัตราค่าจ้าง = ค่าจ้างตัดปาล์ม
B4: ตอนล่าง
C5: กะเปา | D5: 50-A04 | E5: 195 | F5: 4864 | G5: 22 | H5: =I5/E5 -> 3.8461538 | I5: 750 | J5: 450 | K5: =J5*I5 -> 337500
D6: 50-A05 | E6: 171 | F6: 4608 | G6: 22 | H6: =I6/E6 -> 4.0935673 | I6: 700 | J6: 450 | K6: =J6*I6 -> 315000
D7: 49-A10-R | E7: 112 | F7: 2785 | H7: =I7/E7 -> 3.5714286 | I7: 400 | J7: 730 | K7: =J7*I7 -> 292000
D8: 49-A11-R | E8: 98 | F8: 2421 | H8: =I8/E8 -> 3.5714286 | I8: 350 | J8: ประกวดราคา | K8: =0 -> 0
D9: 49-A12-R | E9: 153 | F9: 3764 | H9: =I9/E9 -> 3.4640523 | I9: 530 | J9: 730 | K9: =J9*I9 -> 386900
D10: 49-A13-R | E10: 116 | F10: 2893 | H10: =I10/E10 -> 3.4482759 | I10: 400 | J10: 730 | K10: =J10*I10 -> 292000
D11: 56-A01 | E11: 78 | F11: 1950 | H11: =I11/E11 -> 3.0769231 | I11: 240 | J11: 700 | K11: =J11*I11 -> 168000
D12: 56-A02 | E12: 154 | F12: 3835 | H12: =I12/E12 -> 3.2467532 | I12: 500 | J12: 700 | K12: =J12*I12 -> 350000
D13: 56-A03-R | E13: 85 | F13: 2119 | H13: =I13/E13 -> 3.1764706 | I13: 270 | J13: 700 | K13: =J13*I13 -> 189000
D14: 57-A08-R | E14: 172 | F14: 4308 | H14: =I14/E14 -> 3.1976744 | I14: 550 | J14: 700 | K14: =J14*I14 -> 385000
D15: 57-A09-R | E15: 154 | F15: 3861 | H15: =I15/E15 -> 3.0519481 | I15: 470 | J15: 700 | K15: =J15*I15 -> 329000
D16: 60-A06 | E16: 142 | F16: 3259 | H16: =I16/E16 -> 2.4647887 | I16: 350 | J16: 760 | K16: =J16*I16 -> 266000
D17: 63-A01-R | E17: 24 | F17: 534 | H17: =I17/E17 -> 2.5 | I17: 60 | J17: 900 | K17: =J17*I17 -> 54000
D18: 63-A03-R | E18: 39 | F18: 980 | H18: =I18/E18 -> 1.2820513 | I18: 50 | J18: 900 | K18: =J18*I18 -> 45000
D19: 63-A07-R | E19: 14 | F19: 309 | H19: =I19/E19 -> 2.5 | I19: 35 | J19: 900 | K19: =J19*I19 -> 31500
D20: 63-A07 | E20: 109 | F20: 2388 | H20: =I20/E20 -> 2.3853211 | I20: 260 | J20: 900 | K20: =J20*I20 -> 234000
B21: รวมกะเปา | E21: =SUM(E5:E20) -> 1816 | F21: =SUM(F5:F20) -> 44878 | G21: =SUM(G5:G20) -> 44 | H21: =I21/E21 -> 3.2571586 | I21: =SUM(I5:I20) -> 5915 | J21: =AVERAGE(J5:J7,J9:J20) -> 730 | K21: =SUM(K5:K20) -> 3674900
C22: หมอนไม้ | D22: R-56-D7 | E22: 157 | F22: 3932 | G22: 22 | H22: =I22/E22 -> 3.1847134 | I22: 500 | J22: 430 | K22: =J22*I22 -> 215000
D23: 63-D08-R | E23: 108 | F23: 2365 | G23: 22 | H23: =I23/E23 -> 3.5185185 | I23: 380 | J23: 700 | K23: =J23*I23 -> 266000
D24: 64-D02-R | E24: 130 | F24: 2853 | H24: =I24/E24 -> 1.5384615 | I24: 200 | J24: 1050 | K24: =J24*I24 -> 210000
D25: 65-D01-R | E25: 115 | F25: 2531 | H25: =I25/E25 -> 0.8 | I25: 92 | J25: ประกวดราคา | K25: =0 -> 0
D26: 65-D03-R | E26: 127 | F26: 2803 | H26: =I26/E26 -> 0.64566929 | I26: 82 | J26: ประกวดราคา | K26: =0 -> 0
D27: 65-D04-R | E27: 128 | F27: 2819 | H27: =I27/E27 -> 1.171875 | I27: 150 | J27: ประกวดราคา | K27: =0 -> 0
D28: 65-D05-R | E28: 122 | F28: 2687 | H28: =I28/E28 -> 0.40983607 | I28: 50 | J28: ประกวดราคา | K28: =0 -> 0
B29: รวมหมอนไม้ | E29: =SUM(E22:E28) -> 887 | F29: =SUM(F22:F28) -> 19990 | G29: =SUM(G22:G28) -> 44 | H29: =I29/E29 -> 1.6392334 | I29: =SUM(I22:I28) -> 1454 | J29: =AVERAGE(J22:J24,J26:J28) -> 726.66667 | K29: =SUM(K22:K28) -> 691000
C30: พันไร่ | D30: R-22-C5 | E30: 8 | F30: 184 | G30: 22 | H30: =I30/E30 -> 4.25 | I30: 34 | J30: 550 | K30: =J30*I30 -> 18700
D31: 50-C05-R | E31: 103 | F31: 2792 | G31: 22 | H31: =I31/E31 -> 4.368932 | I31: 450 | J31: 450 | K31: =J31*I31 -> 202500
D32: 50-C07-R | E32: 156 | F32: 4202 | H32: =I32/E32 -> 4.3589744 | I32: 680 | J32: 450 | K32: =J32*I32 -> 306000
D33: 56-C10-R | E33: 124 | F33: 3106 | H33: =I33/E33 -> 2.9032258 | I33: 360 | J33: 430 | K33: =J33*I33 -> 154800
D34: 57-C06-R | E34: 100 | F34: 2495 | H34: =I34/E34 -> 3.4 | I34: 340 | J34: 700 | K34: =J34*I34 -> 238000
D35: 57-C06 | E35: 12 | F35: 300 | H35: =I35/E35 -> 3.3333333 | I35: 40 | J35: 700 | K35: =J35*I35 -> 28000
D36: 59-C03-R | E36: 134 | F36: 3333 | H36: =I36/E36 -> 2.6119403 | I36: 350 | J36: 680 | K36: =J36*I36 -> 238000
D37: 59-C04-R | E37: 101 | F37: 2525 | H37: =I37/E37 -> 2.5742574 | I37: 260 | J37: 680 | K37: =J37*I37 -> 176800
D38: 59-C08-R | E38: 116 | F38: 2888 | H38: =I38/E38 -> 2.9310345 | I38: 340 | J38: 680 | K38: =J38*I38 -> 231200
D39: 59-C09-R | E39: 76 | F39: 1905 | H39: =I39/E39 -> 2.6315789 | I39: 200 | J39: 680 | K39: =J39*I39 -> 136000
D40: 59-C11-R | E40: 92 | F40: 2291 | H40: =I40/E40 -> 2.7173913 | I40: 250 | J40: 680 | K40: =J40*I40 -> 170000
...

Sheet ค่าสารเคมี,อัตราจ้าง 69 
A1: ค่าสารเคมีและอัตราจ้าง
A2: รหัสบล็อก | B2: ไร่ | C2: ต้น | D2: จำนวน(ครั้ง/ปี) | G2: อัตราฉีดยา cc/ต้น | J2: อัตราจ้าง(บาท/ต้น) | M2: ปริมาณสารเคมี (ลิตร) | U2: อัตราค่าจ้างฉีดยา (บาท/ต้น) | AC2: อัตราค่าใช้จ่ายสารเคมี (ไกลโฟเสท 95 , กลูโฟซิเนต 100 บาท) | AK2: รวมค่าใช้จ่าย (บาท)
D3: ตอนบน / ตอนล่าง | G3: รอบโคน | H3: ล้างแปลง | I3: แถบ | J3: รอบโคน | K3: ล้างแปลง | L3: แถบ | M3: รอบโคน | O3: ล้างแปลง | R3: แถบ | U3: รอบโคน | W3: ล้างแปลง | Z3: แถบ | AC3: รอบโคน | AE3: ล้างแปลง | AH3: แถบ | AK3: รอบโคน | AM3: ล้างแปลง | AP3: แถบ | AT3: สูตรการคำนวณ : ปริมาณสารเคมี / ลิตร = (อัตราฉีดยา / CC * จำนวนต้น) / 1,000
M4: ครั้งที่1 | N4: ครั้งที่2 | O4: ครั้งที่3 | P4: ครั้งที่4 | Q4: ครั้งที่5 | R4: ครั้งที่6 | S4: ครั้งที่7 | T4: ครั้งที่8 | U4: ครั้งที่1 | V4: ครั้งที่2 | W4: ครั้งที่3 | X4: ครั้งที่4 | Y4: ครั้งที่5 | Z4: ครั้งที่6 | AA4: ครั้งที่7 | AB4: ครั้งที่8 | AC4: ครั้งที่1 | AD4: ครั้งที่2 | AE4: ครั้งที่3 | AF4: ครั้งที่4 | AG4: ครั้งที่5 | AH4: ครั้งที่6 | AI4: ครั้งที่7 | AJ4: ครั้งที่8 | AK4: ครั้งที่1 | AL4: ครั้งที่2 | AM4: ครั้งที่3 | AN4: ครั้งที่4 | AO4: ครั้งที่5 | AP4: ครั้งที่6 | AQ4: ครั้งที่7 | AR4: ครั้งที่8 | AV4: อัตราจ้างฉีด = ค่าจ้างฉีด * จำนวนต้น
D5: รอบโคน | E5: ล้างแปลง | F5: แถบ | AV5: อัตราค่าใช้จ่ายสารเคมี = ปริมาณสารเคมี * ราคาสารเคมี
A6: ปาล์มใหญ่
A7: ตอนบน
A8: 37-T29 | B8: 102 | C8: 2243 | D8: 1 | E8: 0 | F8: 0 | G8: 5 | H8: =0 -> 0 | I8: =0 -> 0 | J8: 1.1 | K8: 2 | L8: 1.7 | M8: =ROUND(C8*G8/1000,0) -> 11 | U8: =ROUND(C8*J8,0) -> 2467 | AC8: =ROUND(M8*95,0) -> 1045 | AK8: =U8+AC8 -> 3512 | AL8: =V8+AD8 -> 0
A9: 37-T30 | B9: 113 | C9: 2494 | D9: 1 | E9: 0 | F9: 0 | G9: 5 | H9: =0 -> 0 | I9: =0 -> 0 | J9: 1.1 | K9: 2 | L9: 1.7 | M9: =ROUND(C9*G9/1000,0) -> 12 | U9: =ROUND(C9*J9,0) -> 2743 | AC9: =ROUND(M9*95,0) -> 1140 | AK9: =U9+AC9 -> 3883 | AL9: =V9+AD9 -> 0
A10: 56-T08 | B10: 9 | C10: 213 | D10: 1 | E10: =0 -> 0 | F10: =0 -> 0 | G10: 5 | H10: =0 -> 0 | I10: =0 -> 0 | J10: 1.1 | K10: 2 | L10: 1.7 | M10: =ROUND(C10*G10/1000,0) -> 1 | U10: =ROUND(C10*J10,0) -> 234 | AC10: =ROUND(M10*95,0) -> 95 | AK10: =U10+AC10 -> 329
A11: 66-T03 | B11: 111 | C11: 2449 | D11: 1 | E11: =0 -> 0 | F11: =0 -> 0 | G11: 5 | H11: =0 -> 0 | I11: =0 -> 0 | J11: 1.1 | K11: 2 | L11: 1.7 | M11: =ROUND(C11*G11/1000,0) -> 12 | U11: =ROUND(C11*J11,0) -> 2694 | AC11: =ROUND(M11*95,0) -> 1140 | AK11: =U11+AC11 -> 3834
A12: 66-T04 | B12: 92 | C12: 2014 | D12: 1 | E12: =0 -> 0 | F12: =0 -> 0 | G12: 5 | H12: =0 -> 0 | I12: =0 -> 0 | J12: 1.1 | K12: 2 | L12: 1.7 | M12: =ROUND(C12*G12/1000,0) -> 10 | U12: =ROUND(C12*J12,0) -> 2215 | AC12: =ROUND(M12*95,0) -> 950 | AK12: =U12+AC12 -> 3165
A13: 66-T06 | B13: 132 | C13: 2898 | D13: 1 | E13: =0 -> 0 | F13: =0 -> 0 | G13: 5 | H13: =0 -> 0 | I13: =0 -> 0 | J13: 1.1 | K13: 2 | L13: 1.7 | M13: =ROUND(C13*G13/1000,0) -> 14 | U13: =ROUND(C13*J13,0) -> 3188 | AC13: =ROUND(M13*95,0) -> 1330 | AK13: =U13+AC13 -> 4518
A14: 66-T07 | B14: 107 | C14: 2364 | D14: 1 | E14: =0 -> 0 | F14: =0 -> 0 | G14: 5 | H14: =0 -> 0 | I14: =0 -> 0 | J14: 1.1 | K14: 2 | L14: 1.7 | M14: =ROUND(C14*G14/1000,0) -> 12 | U14: =ROUND(C14*J14,0) -> 2600 | AC14: =ROUND(M14*95,0) -> 1140 | AK14: =U14+AC14 -> 3740
A15: 67-T10 | B15: 3 | C15: 61 | D15: 1 | E15: =0 -> 0 | F15: =0 -> 0 | G15: 5 | H15: =0 -> 0 | I15: =0 -> 0 | J15: 1.1 | K15: 2 | L15: 1.7 | M15: =C15*G15/1000 -> 0.305 | U15: =ROUND(C15*J15,0) -> 67 | AC15: =ROUND(M15*95,0) -> 29 | AK15: =U15+AC15 -> 96
A16: 67-T18 | B16: 8 | C16: 171 | D16: 1 | E16: =0 -> 0 | F16: =0 -> 0 | G16: 5 | H16: =0 -> 0 | I16: =0 -> 0 | J16: 1.1 | K16: 2 | L16: 1.7 | M16: =ROUND(C16*G16/1000,0) -> 1 | U16: =ROUND(C16*J16,0) -> 188 | AC16: =ROUND(M16*95,0) -> 95 | AK16: =U16+AC16 -> 283
A17: 67-T21 | B17: 11 | C17: 241 | D17: 1 | E17: =0 -> 0 | F17: =0 -> 0 | G17: 5 | H17: =0 -> 0 | I17: =0 -> 0 | J17: 1.1 | K17: 2 | L17: 1.7 | M17: =ROUND(C17*G17/1000,0) -> 1 | U17: =ROUND(C17*J17,0) -> 265 | AC17: =ROUND(M17*95,0) -> 95 | AK17: =U17+AC17 -> 360
A18: 67-T29 | B18: 140 | C18: 3070 | D18: 1 | E18: =0 -> 0 | F18: =0 -> 0 | G18: 5 | H18: =0 -> 0 | I18: =0 -> 0 | J18: 1.1 | K18: 2 | L18: 1.7 | M18: =ROUND(C18*G18/1000,0) -> 15 | U18: =ROUND(C18*J18,0) -> 3377 | AC18: =ROUND(M18*95,0) -> 1425 | AK18: =U18+AC18 -> 4802
A19: 67-T30 | B19: 149 | C19: 3270 | D19: 1 | E19: =0 -> 0 | F19: =0 -> 0 | G19: 5 | H19: =0 -> 0 | I19: =0 -> 0 | J19: 1.1 | K19: 2 | L19: 1.7 | M19: =ROUND(C19*G19/1000,0) -> 16 | U19: =ROUND(C19*J19,0) -> 3597 | AC19: =ROUND(M19*95,0) -> 1520 | AK19: =U19+AC19 -> 5117
A20: 68-T01 | B20: 144 | C20: 3171 | D20: 1 | E20: =0 -> 0 | F20: =0 -> 0 | G20: 5 | H20: =0 -> 0 | I20: =0 -> 0 | J20: 1.1 | K20: 2 | L20: 1.7 | M20: =ROUND(C20*G20/1000,0) -> 16 | U20: =ROUND(C20*J20,0) -> 3488 | AC20: =ROUND(M20*95,0) -> 1520 | AK20: =U20+AC20 -> 5008
A21: 68-T02 | B21: 134 | C21: 2950 | D21: 1 | E21: =0 -> 0 | F21: =0 -> 0 | G21: 5 | H21: =0 -> 0 | I21: =0 -> 0 | J21: 1.1 | K21: 2 | L21: 1.7 | M21: =ROUND(C21*G21/1000,0) -> 15 | U21: =ROUND(C21*J21,0) -> 3245 | AC21: =ROUND(M21*95,0) -> 1425 | AK21: =U21+AC21 -> 4670
A22: รวมตะกุก | B22: =SUM(B8:B21) -> 1255 | C22: =SUM(C8:C21) -> 27609 | M22: =SUM(M8:M21) -> 136.305 | N22: =SUM(N8:N9) -> 0 | U22: =SUM(U8:U21) -> 30368 | AC22: =SUM(AC8:AC10) -> 2280 | AK22: =SUM(AK8:AK10) -> 7724 | AL22: =AL8+AL9 -> 0
M23: =M22+N22 -> 136.305 | U23: =U22+V22 -> 30368 | AC23: =AC22+AD22 -> 2280 | AK23: =AK22+AL22 -> 7724
A24: 30-B14 | B24: 6 | C24: 126 | D24: 1 | E24: 0 | F24: 0 | G24: 5 | H24: =0 -> 0 | I24: =0 -> 0 | J24: 1.1 | K24: 2 | L24: 1.7 | M24: =ROUND(C24*G24/1000,0) -> 1 | U24: =ROUND(C24*J24,0) -> 139 | AC24: =ROUND(M24*95,0) -> 95 | AD24: =N24*960 -> 0 | AK24: =U24+AC24 -> 234 | AL24: =V24+AD24 -> 0
A25: 57-B03 | B25: 169 | C25: 4231 | D25: 1 | E25: 0 | F25: 0 | G25: 5 | H25: =0 -> 0 | I25: =0 -> 0 | J25: 1.1 | K25: 2 | L25: 1.7 | M25: =ROUND(C25*G25/1000,0) -> 21 | U25: =ROUND(C25*J25,0) -> 4654 | AC25: =ROUND(M25*95,0) -> 1995 | AK25: =U25+AC25 -> 6649
A26: 57-B12 | B26: 171 | C26: 4265 | D26: 1 | E26: =0 -> 0 | F26: =0 -> 0 | G26: 5 | H26: =0 -> 0 | I26: =0 -> 0 | J26: 1.1 | K26: 2 | L26: 1.7 | M26: =ROUND(C26*G26/1000,0) -> 21 | U26: =ROUND(C26*J26,0) -> 4692 | AC26: =ROUND(M26*95,0) -> 1995 | AK26: =U26+AC26 -> 6687
A27: 57-B14 | B27: 67 | C27: 1663 | D27: 1 | E27: 0 | F27: 0 | G27: 5 | H27: =0 -> 0 | I27: =0 -> 0 | J27: 1.1 | K27: 2 | L27: 1.7 | M27: =ROUND(C27*G27/1000,0) -> 8 | U27: =ROUND(C27*J27,0) -> 1829 | AC27: =ROUND(M27*95,0) -> 760 | AK27: =U27+AC27 -> 2589
A28: 60-B04 | B28: 154 | C28: 3851 | D28: 1 | E28: 0 | F28: 0 | G28: 5 | H28: =0 -> 0 | I28: =0 -> 0 | J28: 1.1 | K28: 2 | L28: 1.7 | M28: =ROUND(C28*G28/1000,0) -> 19 | U28: =ROUND(C28*J28,0) -> 4236 | AC28: =ROUND(M28*95,0) -> 1805 | AK28: =U28+AC28 -> 6041
A29: 60-B08 | B29: 139 | C29: 3476 | D29: 1 | E29: =0 -> 0 | F29: =0 -> 0 | G29: 5 | H29: =0 -> 0 | I29: =0 -> 0 | J29: 1.1 | K29: 2 | L29: 1.7 | M29: =ROUND(C29*G29/1000,0) -> 17 | U29: =ROUND(C29*J29,0) -> 3824 | AC29: =ROUND(M29*95,0) -> 1615 | AK29: =U29+AC29 -> 5439
A30: 60-B09 | B30: 165 | C30: 4127 | D30: 1 | E30: 0 | F30: 0 | G30: 5 | H30: =0 -> 0 | I30: =0 -> 0 | J30: 1.1 | K30: 2 | L30: 1.7 | M30: =ROUND(C30*G30/1000,0) -> 21 | U30: =ROUND(C30*J30,0) -> 4540 | AC30: =ROUND(M30*95,0) -> 1995 | AK30: =U30+AC30 -> 6535
A31: 64-B02 | B31: 158 | C31: 3480 | D31: 1 | E31: 0 | F31: 0 | G31: 5 | H31: =0 -> 0 | I31: =0 -> 0 | J31: 1.1 | K31: 2 | L31: 1.7 | M31: =ROUND(C31*G31/1000,0) -> 17 | U31: =ROUND(C31*J31,0) -> 3828 | AC31: =ROUND(M31*95,0) -> 1615 | AK31: =U31+AC31 -> 5443
A32: 64-B05 | B32: 143 | C32: 3140 | D32: 1 | E32: =0 -> 0 | F32: =0 -> 0 | G32: 5 | H32: =0 -> 0 | I32: =0 -> 0 | J32: 1.1 | K32: 2 | L32: 1.7 | M32: =ROUND(C32*G32/1000,0) -> 16 | U32: =ROUND(C32*J32,0) -> 3454 | AC32: =ROUND(M32*95,0) -> 1520 | AK32: =U32+AC32 -> 4974
A33: 64-B06 | B33: 167 | C33: 3671 | D33: 1 | E33: 0 | F33: 0 | G33: 5 | H33: =0 -> 0 | I33: =0 -> 0 | J33: 1.1 | K33: 2 | L33: 1.7 | M33: =ROUND(C33*G33/1000,0) -> 18 | U33: =ROUND(C33*J33,0) -> 4038 | AC33: =ROUND(M33*95,0) -> 1710 | AK33: =U33+AC33 -> 5748
A34: 65-B01 | B34: 130 | C34: 2868 | D34: 1 | E34: 0 | F34: 0 | G34: 5 | H34: =0 -> 0 | I34: =0 -> 0 | J34: 1.1 | K34: 2 | L34: 1.7 | M34: =ROUND(C34*G34/1000,0) -> 14 | U34: =ROUND(C34*J34,0) -> 3155 | AC34: =ROUND(M34*95,0) -> 1330 | AK34: =U34+AC34 -> 4485
A35: 65-B11 | B35: 145 | C35: 3193 | D35: 1 | E35: =0 -> 0 | F35: =0 -> 0 | G35: 5 | H35: =0 -> 0 | I35: =0 -> 0 | J35: 1.1 | K35: 2 | L35: 1.7 | M35: =ROUND(C35*G35/1000,0) -> 16 | U35: =ROUND(C35*J35,0) -> 3512 | AC35: =ROUND(M35*960,0) -> 15360 | AK35: =U35+AC35 -> 18872
A36: รวมบางกัน | B36: =SUM(B24:B35) -> 1614 | C36: =SUM(C24:C35) -> 38091 | M36: =SUM(M24:M35) -> 189 | N36: =SUM(N24:N35) -> 0 | O36: =SUM(O24:O35) -> 0 | P36: =SUM(P24:P35) -> 0 | Q36: =SUM(Q24:Q35) -> 0 | R36: =SUM(R24:R35) -> 0 | S36: =SUM(S24:S35) -> 0 | T36: =SUM(T24:T35) -> 0 | ... V36: =SUM(V24:V35) -> 0 | AC36: =SUM(AC24:AC35) -> 31795 | AD36: =SUM(AD24:AD35) -> 0 | AK36: =SUM(AK24:AK35) -> 73696 | AL36: =SUM(AL24:AL35) -> 0
M37: =M36+N36 -> 189 | O37: =O36+P36+Q36 -> 0 | R37: =R36+S36+T36 -> 0 | U37: =U36+V36 -> 41901 | W37: =W36+X36+Y36 -> 0 | Z37: =Z36+AA36+AB36 -> 0 | AC37: =AC36+AD36 -> 31795 | AE37: =AE36+AF36+AG36 -> 0 | AH37: =AH36+AI36+AJ36 -> 0 | AK37: =AK36+AL36 -> 73696 | AM37: =AM36+AN36+AO36 -> 0 | AP37: =AP36+AQ36+AR36 -> 0
A38: ตอนล่าง
A39: 30-PU1 | B39: 82 | C39: 1813 | D39: 1 | E39: 0 | F39: 0 | G39: 5 | H39: =0 -> 0 | I39: =0 -> 0 | J39: 1.1 | K39: 2 | L39: 1.7 | M39: =ROUND(C39*G39/1000,0) -> 9 | N39: =0 -> 0 | O39: =0 -> 0 | P39: =0 -> 0 | Q39: =0 -> 0 | U39: =ROUND(C39*J39,0) -> 1994 | AC39: =ROUND(M39*95,0) -> 855 | AD39: =ROUND(N39*960,0) -> 0 | AK39: =U39+AC39 -> 2849 | AL39: =V39+AD39 -> 0
A40: 30-PU3 | B40: 72 | C40: 1574 | D40: 1 | E40: 0 | F40: 0 | G40: 5 | H40: =0 -> 0 | I40: =0 -> 0 | J40: 1.1 | K40: 2 | L40: 1.7 | M40: =ROUND(C40*G40/1000,0) -> 8 | N40: =0 -> 0 | O40: =0 -> 0 | P40: =0 -> 0 | Q40: =0 -> 0 | U40: =ROUND(C40*J40,0) -> 1731 | AC40: =ROUND(M40*95,0) -> 760 | AD40: =ROUND(N40*960,0) -> 0 | AK40: =U40+AC40 -> 2491 | AL40: =V40+AD40 -> 0
...

Sheet ถางป่าพร้อมทายา 69
A1: ค่าแรงถางป่าพร้อมทายากาลอน
A2: บล็อก | C2: ไร่ | D2: ต้น | E2: จำนวนไร่ของพื้นที่ทั้งหมด | F2: จำนวนต้นของพื้นที่ทั้งหมด | G2: ค่าแรง (บาท/ต้น) | H2: รวมค่าแรงถางป่าพร้อมทายากาลอน | J2: สูตรการคำนวณ : ค่าแรงถางป่า = (จำนวนต้นในพื้นที่ต้องการถางป่า * ค่าแรง)
G3: 5
A4: ปาล์ม (49-52)
A5: ตอนบน
A6: 50-T10-R | B6: 1 | C6: ='จน.ปาล์ม 69 '!E22 -> 115 | D6: ='จน.ปาล์ม 69 '!F22 -> 2872 | E6: =ROUND(C6*B6,0) -> 115 | F6: =ROUND(D6*B6,0) -> 2872 | G6: =$G$3 -> 5 | H6: =ROUND(G6*F6,0) -> 14360
A7: 50-T12-R | B7: 1 | C7: ='จน.ปาล์ม 69 '!E23 -> 121 | D7: ='จน.ปาล์ม 69 '!F23 -> 3030 | E7: =ROUND(C7*B7,0) -> 121 | F7: =ROUND(D7*B7,0) -> 3030 | G7: =$G$3 -> 5 | H7: =ROUND(G7*F7,0) -> 15150
A8: รวมค่าแรงแปลงตะกุก | H8: =SUM(H6:H7) -> 29510
A9: ='จน.ปาล์ม 69 '!D26 -> 49-B13 | B9: 1 | C9: ='จน.ปาล์ม 69 '!E26 -> 168 | D9: ='จน.ปาล์ม 69 '!F26 -> 4192 | E9: =ROUND(C9*B9,0) -> 168 | F9: =ROUND(D9*B9,0) -> 4192 | G9: =$G$3 -> 5 | H9: =ROUND(G9*F9,0) -> 20960
A10: ='จน.ปาล์ม 69 '!D27 -> 50-B07 | B10: 1 | C10: ='จน.ปาล์ม 69 '!E27 -> 157 | D10: ='จน.ปาล์ม 69 '!F27 -> 4022 | E10: =ROUND(C10*B10,0) -> 157 | F10: =ROUND(D10*B10,0) -> 4022 | G10: =$G$3 -> 5 | H10: =ROUND(G10*F10,0) -> 20110
A11: ='จน.ปาล์ม 69 '!D28 -> 50-B10 | B11: 1 | C11: ='จน.ปาล์ม 69 '!E28 -> 170 | D11: ='จน.ปาล์ม 69 '!F28 -> 4245 | E11: =ROUND(C11*B11,0) -> 170 | F11: =ROUND(D11*B11,0) -> 4245 | G11: =$G$3 -> 5 | H11: =ROUND(G11*F11,0) -> 21225
A12: รวมค่าแรงแปลงบางกัน | H12: =SUM(H9:H11) -> 62295
A13: รวมค่าแรงถางป่าพร้อมทายากาลอนปาล์มตอนบน 49-52 | H13: =H8+H12 -> 91805
A14: ตอนล่าง
A15: ='จน.ปาล์ม 69 '!D42 -> 50-C05-R | B15: 1 | C15: ='จน.ปาล์ม 69 '!E42 -> 103 | D15: ='จน.ปาล์ม 69 '!F42 -> 2792 | E15: =ROUND(C15*B15,0) -> 103 | F15: =ROUND(D15*B15,0) -> 2792 | G15: =$G$3 -> 5 | H15: =ROUND(G15*F15,0) -> 13960
A16: รวมค่าแรงแปลงพันไร่ | H16: =SUM(H15:H15) -> 13960
A17: 49-A10-R | B17: 1 | C17: 111 | D17: 2785 | E17: =ROUND(C17*B17,0) -> 111 | F17: =ROUND(D17*B17,0) -> 2785 | G17: =$G$3 -> 5 | H17: =ROUND(G17*F17,0) -> 13925
A18: 50-A04 | B18: 1 | C18: 195 | D18: 4864 | E18: =ROUND(C18*B18,0) -> 195 | F18: =ROUND(D18*B18,0) -> 4864 | G18: =$G$3 -> 5 | H18: =ROUND(G18*F18,0) -> 24320
A19: รวมค่าแรงแปลงกะเปา | H19: =SUM(H17:H18) -> 38245
A20: รวมค่าแรงถางป่าพร้อมทายากาลอนปาล์มตอนล่าง 49-52 | H20: =H19+H16 -> 52205
A21: รวมค่าแรงถางป่าพร้อมทายากาลอนปาล์ม 49-52 | H21: =H20+H13 -> 144010
A22: ปาล์มปี 56
A23: ตอนบน
A24: 56-T08-R | B24: 1 | C24: 113 | D24: 2816 | E24: =ROUND(C24*B24,0) -> 113 | F24: =ROUND(D24*B24,0) -> 2816 | G24: =$G$3 -> 5 | H24: =ROUND(G24*F24,0) -> 14080
A25: 56-T08 | B25: 1 | C25: 9 | D25: 213 | E25: =ROUND(C25*B25,0) -> 9 | F25: =ROUND(D25*B25,0) -> 213 | G25: =$G$3 -> 5 | H25: =ROUND(G25*F25,0) -> 1065
A26: 56-T19-R | B26: 1 | C26: 128 | D26: 3199 | E26: =ROUND(C26*B26,0) -> 128 | F26: =ROUND(D26*B26,0) -> 3199 | G26: =$G$3 -> 5 | H26: =ROUND(G26*F26,0) -> 15995
A27: 56-T21-R | B27: 1 | C27: 121 | D27: 3015 | E27: =ROUND(C27*B27,0) -> 121 | F27: =ROUND(D27*B27,0) -> 3015 | G27: =$G$3 -> 5 | H27: =ROUND(G27*F27,0) -> 15075
A28: 56-T28-R | B28: 1 | C28: 56 | D28: 1403 | E28: =ROUND(C28*B28,0) -> 56 | F28: =ROUND(D28*B28,0) -> 1403 | G28: =$G$3 -> 5 | H28: =ROUND(G28*F28,0) -> 7015
A29: รวมค่าแรงแปลงตะกุก | H29: =SUM(H24:H28) -> 53230
A30: รวมค่าแรงถางป่าพร้อมทายากาลอนปาล์มตอนบน 49-52 | H30: =H29 -> 53230
A31: ตอนล่าง
A32: 56-C10-R | B32: 1 | C32: ='จน.ปาล์ม 69 '!E67 -> 124 | D32: ='จน.ปาล์ม 69 '!F67 -> 3106 | E32: =ROUND(C32*B32,0) -> 124 | F32: =ROUND(D32*B32,0) -> 3106 | G32: =$G$3 -> 5 | H32: =ROUND(G32*F32,0) -> 15530
A33: รวมค่าแรงแปลงพันไร่ | H33: =SUM(H32) -> 15530
A34: 56-A01 | B34: 1 | C34: ='จน.ปาล์ม 69 '!E71 -> 78 | D34: ='จน.ปาล์ม 69 '!F71 -> 1950 | E34: =ROUND(C34*B34,0) -> 78 | F34: =ROUND(D34*B34,0) -> 1950 | G34: =$G$3 -> 5 | H34: =ROUND(G34*F34,0) -> 9750
A35: รวมค่าแรงแปลงกะเปา | H35: =SUM(H34:H34) -> 9750
A36: รวมค่าแรงถางป่าพร้อมทายากาลอนปาล์มตอนล่าง 56 | H36: =H35+H33 -> 25280
A37: รวมปาล์มปี 56 | H37: =H30+H36 -> 78510
A38: ปาล์มปี 57
A39: ตอนบน
A40: 57-B03 | B40: 1 | C40: ='จน.ปาล์ม 69 '!E59 -> 169 | D40: ='จน.ปาล์ม 69 '!F59 -> 4231 | E40: =ROUND(C40*B40,0) -> 169 | F40: =ROUND(D40*B40,0) -> 4231 | G40: =$G$3 -> 5 | H40: =ROUND(G40*F40,0) -> 21155
...

Sheet ถากโคน 69
A1: ค่าใช้จ่ายในการถากโคน 2569
A2: บล็อก | B2: ไร่ | C2: ต้น | D2: ค่าแรงถากโคน (บาท/ต้น) | E2: จำนวน(ครั้ง/ปี) | H2: สูตรการคำนวณ : ค่าแรงถากโคน = (จำนวนต้นในพื้นที่ต้องการถางป่า * ค่าแรง*จำนวนครั้ง)
E3: ตอนบน
E4: ครั้งที่ 1 | F4: ค่าใช้จ่าย (บาท)
A5: ปาล์มปี 67
A6: ตอนบน
A7: 67-T10 | B7: 3 | C7: 61 | D7: 3.5 | E7: 1 | F7: =ROUND(+D7*C7*E7,0) -> 214
A8: 67-T18 | B8: 8 | C8: 171 | D8: 3.5 | E8: 1 | F8: =ROUND(+D8*C8*E8,0) -> 599
A9: 67-T21 | B9: 11 | C9: 241 | D9: 3.5 | E9: 1 | F9: =ROUND(+D9*C9*E9,0) -> 844
A10: 67-T29 | B10: 140 | C10: 3070 | D10: 3.5 | E10: 1 | F10: =ROUND(+D10*C10*E10,0) -> 10745
A11: 67-T30 | B11: 149 | C11: 3270 | D11: 3.5 | E11: 1 | F11: =ROUND(+D11*C11*E11,0) -> 11445
A12: รวมปาล์มปี 67 ตอนบน | F12: =F7+F8+F9+F10+F11 -> 23847
A13: ตอนล่าง
A14: 67-P01-R | B14: 99 | C14: 2167 | D14: 3.5 | E14: 1 | F14: =ROUND(+D14*C14*E14,0) -> 7585
A15: 67-P02-R | B15: 105 | C15: 2320 | D15: 3.5 | E15: 1 | F15: =ROUND(+D15*C15*E15,0) -> 8120
A16: 67-D06-R | B16: 130 | C16: 2865 | D16: 3.5 | E16: 1 | F16: =ROUND(+D16*C16*E16,0) -> 10028
A17: รวมปาล์มปี 67 ตอนล่าง | F17: =F14+F15+F16 -> 25733
A18: รวมค่าใช้จ่ายถากโคน ปาล์มปี 67 | F18: =F17+F12 -> 49580
A19: ปาล์มปี 68
A20: ตอนบน
A21: 68-T01 | B21: 144 | C21: 3171 | D21: 3.5 | E21: 1 | F21: =ROUND(+D21*C21*E21,0) -> 11099
A22: 68-T02 | B22: 134 | C22: 2950 | D22: 3.5 | E22: 1 | F22: =ROUND(+D22*C22*E22,0) -> 10325
A23: รวมตอนบน | F23: =F21+F22 -> 21424
A24: ตอนล่าง
A25: 68-PU1 | B25: 86 | C25: 1892 | D25: 3.5 | E25: 1 | F25: =ROUND(+D25*C25*E25,0) -> 6622
A26: 68-PU3 | B26: 77 | C26: 1686 | D26: 3.5 | E26: 1 | F26: =ROUND(+D26*C26*E26,0) -> 5901
A27: 68-PU4 | B27: 63 | C27: 1380 | D27: 3.5 | E27: 1 | F27: =ROUND(+D27*C27*E27,0) -> 4830
A28: 68-PU5-R | B28: 53 | C28: 1168 | D28: 3.5 | E28: 1 | F28: =ROUND(+D28*C28*E28,0) -> 4088
A29: 68-PU5 | B29: 34 | C29: 751 | D29: 3.5 | E29: 1 | F29: =ROUND(+D29*C29*E29,0) -> 2629
A30: 68-PU6-R | B30: 70 | C30: 1547 | D30: 3.5 | E30: 1 | F30: =ROUND(+D30*C30*E30,0) -> 5415
A31: 68-PU6 | B31: 7 | C31: 145 | D31: 3.5 | E31: 1 | F31: =ROUND(+D31*C31*E31,0) -> 508
A32: รวมตอนล่าง | F32: =F31+F30+F29+F28+F27+F26+F25 -> 29993
A33: รวมค่าใช้จ่ายถากโคน ปาล์มปี 68 | F33: =F23+F32 -> 51417
A34: รวมค่าใช้จ่ายถากโคนทั้งหมด | F34: =F33+F18 -> 100997

Sheet ตัดหญ้า 69
B1: ค่าตัดหญ้า
B2: บล็อก | C2: ไร่ | D2: ต้น | E2: จำนวนไร่ของพื้นที่ทั้งหมด | F2: จำนวนต้นของพื้นที่ทั้งหมด | G2: ค่าแรงตัดหญ้า(บาท/ไร่) | H2: จำนวน(ครั้ง/ปี)
H3: ตอนบน | L3: ตอนล่าง | S3: สูตรการคำนวณ : ค่าแรงตัดหญ้า/ไร่ = (จำนวนต้นในพื้นที่ต้องการตัดหญ้า * ค่าแรง*จำนวนครั้ง)
H4: ครั้งที่1 | I4: บาท | J4: ครั้งที่2 | K4: บาท | L4: ครั้งที่1 | M4: บาท | N4: ครั้งที่2 | O4: บาท | P4: ครั้งที่3 | Q4: บาท
B5: ปาล์มใหญ่
B6: ตอนล่าง
B7: R-22-C5 | C7: 8 | D7: 184 | E7: =+C7*100% -> 8 | F7: =D7*100% -> 184 | G7: 5 | H7: 0 | I7: 0 | J7: =0 -> 0 | K7: =0 -> 0 | L7: 1 | M7: =C7*G7 -> 40 | N7: 0 | O7: 0 | P7: 0 | Q7: 0
B8: รวมตอนล่าง | C8: =C7 -> 8 | D8: =D7 -> 184 | E8: =SUM(E7:E7) -> 8 | F8: =SUM(F7:F7) -> 184 | H8: =SUM(H7:H7) -> 0 | I8: =SUM(I7:I7) -> 0 | J8: =J7 -> 0 | K8: =K7 -> 0 | M8: =M7 -> 40 | N8: =SUM(N7:N7) -> 0 | O8: =SUM(O7:O7) -> 0 | P8: =SUM(P7:P7) -> 0 | Q8: =SUM(Q7:Q7) -> 0
B9: ปาล์มกลาง 49-52
B10: ตอนบน
B11: 50-T10-R | C11: 115 | D11: 2872 | E11: =+C11*100% -> 115 | F11: =D11*80% -> 2297.6 | G11: 5 | H11: 1 | I11: =C11*G11 -> 575 | J11: =0 -> 0 | K11: =0 -> 0 | L11: 0 | M11: 0 | N11: =0 -> 0 | O11: =0 -> 0 | P11: =0 -> 0 | Q11: =0 -> 0
B12: รวมตอนบน | C12: =SUM(C11:C11) -> 115 | D12: =SUM(D11:D11) -> 2872 | E12: =SUM(E11:E11) -> 115 | F12: =SUM(F11:F11) -> 2297.6 | I12: =SUM(I11:I11) -> 575 | J12: =J11 -> 0 | K12: =K11 -> 0
B13: ปาล์มปี 55
B14: ตอนล่าง
B15: 55-P07-R | C15: 4 | D15: 93 | E15: =+C15*100% -> 4 | F15: =D15*100% -> 93 | G15: 5 | H15: 0 | I15: 0 | J15: =0 -> 0 | L15: 1 | M15: =C15*G15 -> 20 | N15: =0 -> 0 | O15: =0 -> 0 | P15: =0 -> 0 | Q15: =0 -> 0
B16: รวมตอนล่าง | C16: =C15 -> 4 | D16: =D15 -> 93 | E16: =E15 -> 4 | F16: =F15 -> 93 | H16: =H15 -> 0 | I16: =I15 -> 0 | J16: =J15 -> 0 | K16: =K15 -> 0 | M16: =M15 -> 20 | N16: =N15 -> 0 | O16: =0 -> 0 | P16: =P15 -> 0 | Q16: =0 -> 0
B17: ปาล์มปี 56
B18: ตอนบน
B19: 56-T08-R | C19: 113 | D19: 2816 | E19: =+C19*100% -> 113 | F19: =D19*100% -> 2816 | G19: 5 | H19: 1 | I19: =+G19*C19*H19 -> 565 | J19: 0 | K19: =0 -> 0 | L19: 0 | M19: 0 | N19: 0 | O19: 0 | P19: 0 | Q19: 0
B20: 56-T08 | C20: 9 | D20: 213 | E20: =+C20*100% -> 9 | F20: =D20*100% -> 213 | G20: 5 | H20: 1 | I20: =+G20*C20*H20 -> 45 | J20: =0 -> 0 | K20: =0 -> 0 | L20: 0 | M20: 0 | N20: 0 | O20: 0 | P20: 0 | Q20: 0
B21: 56-T19-R | C21: 128 | D21: 3199 | E21: =+C21*100% -> 128 | F21: =D21*100% -> 3199 | G21: 5 | H21: 1 | I21: =+G21*C21*H21 -> 640 | J21: =0 -> 0 | K21: =0 -> 0 | L21: 0 | M21: 0 | N21: 0 | O21: 0 | P21: 0 | Q21: 0
B22: 56-T21-R | C22: 121 | D22: 3015 | E22: =+C22*100% -> 121 | F22: =D22*100% -> 3015 | G22: 5 | H22: 1 | I22: =+G22*C22*H22 -> 605 | J22: =0 -> 0 | K22: =0 -> 0 | L22: 0 | M22: 0 | N22: 0 | O22: 0 | P22: 0 | Q22: 0
B23: 56-T28-R | C23: 56 | D23: 1403 | E23: =+C23*100% -> 56 | F23: =D23*100% -> 1403 | G23: 5 | H23: 1 | I23: =+G23*C23*H23 -> 280 | J23: =0 -> 0 | K23: =0 -> 0 | L23: 0 | M23: 0 | N23: 0 | O23: 0 | P23: 0 | Q23: 0
B24: รวมตอนบน | C24: =SUM(C19:C23) -> 427 | D24: =SUM(D19:D23) -> 10646 | E24: =SUM(E19:E23) -> 427 | F24: =SUM(F19:F23) -> 10646 | I24: =SUM(I19:I23) -> 2135 | J24: =0 -> 0 | K24: =SUM(K19:K23) -> 0
B25: ปาล์มปี 57
B26: ตอนบน
B27: 57-B03 | C27: 169 | D27: 4231 | E27: =+C27*100% -> 169 | F27: =D27*100% -> 4231 | G27: 5 | H27: 1 | I27: =+G27*C27*H27 -> 845 | J27: =0 -> 0 | K27: =+G27*C27*J27 -> 0 | L27: 0 | M27: 0 | N27: 0 | O27: 0 | P27: 0 | Q27: 0
B28: 57-B12 | C28: 171 | D28: 4265 | E28: =+C28*100% -> 171 | F28: =D28*100% -> 4265 | G28: 5 | H28: 1 | I28: =+G28*C28*H28 -> 855 | J28: =0 -> 0 | K28: =+G28*C28*J28 -> 0 | L28: =0 -> 0 | M28: =0 -> 0 | N28: =0 -> 0 | O28: =0 -> 0 | P28: =0 -> 0 | Q28: =0 -> 0
B29: 57-B14 | C29: 67 | D29: 1663 | E29: =+C29*100% -> 67 | F29: =D29*100% -> 1663 | G29: 5 | H29: 1 | I29: =+G29*C29*H29 -> 335 | J29: =0 -> 0 | K29: =+G29*C29*J29 -> 0 | L29: 0 | M29: 0 | N29: =0 -> 0 | O29: 0 | P29: =0 -> 0 | Q29: 0
B30: รวมตอนบน | C30: =SUM(C27:C29) -> 407 | D30: =SUM(D27:D29) -> 10159 | E30: =SUM(E27:E29) -> 407 | F30: =SUM(F27:F29) -> 10159 | I30: =SUM(I27:I29) -> 2035 | K30: =SUM(K27:K29) -> 0
B31: ปาล์มปี 58
B32: ตอนบน
B33: 58-T09-R | C33: 117 | D33: 2934 | E33: =+C33*100% -> 117 | F33: =D33*100% -> 2934 | G33: 5 | H33: 1 | I33: =+G33*C33*H33 -> 585 | J33: =0 -> 0 | K33: =0 -> 0 | L33: 0 | M33: 0 | N33: 0 | O33: 0 | P33: 0 | Q33: 0
B34: 58-T11-R | C34: 116 | D34: 2903 | E34: =+C34*100% -> 116 | F34: =D34*100% -> 2903 | G34: 5 | H34: 1 | I34: =+G34*C34*H34 -> 580 | J34: =0 -> 0 | K34: =0 -> 0 | L34: 0 | M34: 0 | N34: 0 | O34: 0 | P34: 0 | Q34: 0
B35: 58-T13-R | C35: 115 | D35: 2864 | E35: =+C35*100% -> 115 | F35: =D35*100% -> 2864 | G35: 5 | H35: 1 | I35: =+G35*C35*H35 -> 575 | J35: =0 -> 0 | K35: =0 -> 0 | L35: 0 | M35: 0 | N35: 0 | O35: 0 | P35: 0 | Q35: 0
B36: 58-T17-R | C36: 128 | D36: 2825 | E36: =+C36*100% -> 128 | F36: =D36*100% -> 2825 | G36: 5 | H36: 1 | I36: =+G36*C36*H36 -> 640 | J36: =0 -> 0 | K36: =0 -> 0 | L36: 0 | M36: 0 | N36: 0 | O36: 0 | P36: 0 | Q36: 0
B37: 58-T18-R | C37: 129 | D37: 2843 | E37: =+C37*100% -> 129 | F37: =D37*100% -> 2843 | G37: 5 | H37: 1 | I37: =+G37*C37*H37 -> 645 | J37: =0 -> 0 | K37: =0 -> 0 | L37: 0 | M37: 0 | N37: 0 | O37: 0 | P37: 0 | Q37: 0
B38: รวมตอนบน | C38: =SUM(C33:C37) -> 605 | D38: =SUM(D33:D37) -> 14369 | E38: =SUM(E33:E37) -> 605 | F38: =SUM(F33:F37) -> 14369 | I38: =SUM(I33:I37) -> 3025 | J38: =SUM(J33:J37) -> 0 | K38: =SUM(K33:K37) -> 0 | L38: =SUM(L33:L37) -> 0 | M38: =SUM(M33:M37) -> 0 | N38: =SUM(N33:N37) -> 0 | O38: =SUM(O33:O37) -> 0 | P38: =SUM(P33:P37) -> 0 | Q38: =SUM(Q33:Q37) -> 0
B39: ปาล์มปี 60
B40: ตอนบน
...

Sheet ไถ,พรวนดิน 69 
B1: ไถ, พรวนดิน 2569
B2: บล็อก | C2: ไร่ | D2: ต้น | E2: จำนวนไร่ของพื้นที่ทั้งหมด | F2: จำนวนต้นของพื้นที่ทั้งหมด | G2: ค่าแรง(บาท/ไร่) | H2: จำนวน(ครั้ง/ปี)
H3: ตอนบน | K3: สูตรการคำนวณ : ค่าแรงไถ,พรวนดิน/ไร่ = (จำนวนไร่ * ค่าแรง*จำนวนครั้ง)
H4: ครั้ง | I4: บาท
B5: ปาล์มปี 68
B6: ตอนบน
B7: 68-T01 | C7: 144 | D7: 3171 | E7: 0 | F7: 0 | G7: 5 | H7: 1 | I7: =+G7*C7*H7 -> 720
B8: 68-T02 | C8: 134 | D8: 2950 | E8: 0 | F8: 0 | G8: 5 | H8: 1 | I8: =+G8*C8* H8 -> 670
B9: รวมปาล์มปี 68 ตอนบน | C9: =SUM(C7:C8) -> 278 | D9: =SUM(D7:D8) -> 6121 | I9: =SUM(I7:I8) -> 1390
B10: รวมปาล์มปี 68 | I10: =I9 -> 1390

Sheet ฟีโรโมน 69 
A1: ล่อฟีโรโมน 10ไร่/ซอง/ครั้ง 2569
A2: บล็อก | B2: ไร่ | C2: ต้น | D2: ฟีโรโมน (ซอง) | E2: ล่อฟีโรโมน (ครั้งที่ 1) | F2: ล่อฟีโรโมน (ครั้งที่ 2) | G2: ล่อฟีโรโมน (ครั้งที่ 3) | H2: ล่อฟีโรโมน (ครั้งที่ 4) | I2: รวม | J2: คงเหลือ
A4: ปาล์มปี 66 | L4: สูตรการคำนวณ : ล่อฟีโรโมน(10ไร่/ซอง/ครั้ง) = (จำนวนไร่/จำนวนซอง*จำนวนครั้ง)
A5: ตอนล่าง
A6: 66-P03-R | B6: 116 | C6: 2550 | D6: =I11 -> 124 | E6: =ROUND(B6/10,0) -> 12 | F6: =ROUND(B6/10,0) -> 12 | I6: =SUM(E6:H6) -> 24
A7: 66-P04-R | B7: 130 | C7: 2854 | E7: =ROUND(B7/10,0) -> 13 | F7: =ROUND(B7/10,0) -> 13 | I7: =SUM(E7:H7) -> 26
A8: 66-P05-R | B8: 141 | C8: 3111 | E8: =ROUND(B8/10,0) -> 14 | F8: =ROUND(B8/10,0) -> 14 | I8: =SUM(E8:H8) -> 28
A9: 66-D09-R | B9: 136 | C9: 2999 | E9: =ROUND(B9/10,0) -> 14 | F9: =ROUND(B9/10,0) -> 14 | I9: =SUM(E9:H9) -> 28
A10: 66-PU-02 | B10: 90 | C10: 1970 | E10: =ROUND(B10/10,0) -> 9 | F10: =ROUND(B10/10,0) -> 9 | I10: =SUM(E10:H10) -> 18
A11: รวมปาล์มตอนล่าง ปี 66 | B11: =SUM(B6:B10) -> 613 | C11: =SUM(C6:C10) -> 13484 | E11: =SUM(E6:E10) -> 62 | F11: =E11 -> 62 | G11: =0 -> 0 | H11: =0 -> 0 | I11: =SUM(I6:I10) -> 124
A12: ปาล์มปี 67
A13: ตอนบน
A14: 67-T10 | B14: 3 | C14: 61 | D14: =I19 -> 124 | E14: 0 | F14: 0 | G14: 0 | H14: 0 | I14: =SUM(E14:H14) -> 0
A15: 67-T18 | B15: 8 | C15: 171 | E15: 1 | F15: =ROUND(B15/10,0) -> 1 | G15: =ROUND(B15/10,0) -> 1 | H15: =ROUND(B15/10,0) -> 1 | I15: =SUM(E15:H15) -> 4
A16: 67-T21 | B16: 11 | C16: 241 | E16: =ROUND(B16/10,0) -> 1 | F16: =ROUND(B16/10,0) -> 1 | G16: =ROUND(B16/10,0) -> 1 | H16: =ROUND(B16/10,0) -> 1 | I16: =SUM(E16:H16) -> 4
A17: 67-T29 | B17: 140 | C17: 3070 | E17: =ROUND(B17/10,0) -> 14 | F17: =ROUND(B17/10,0) -> 14 | G17: =ROUND(B17/10,0) -> 14 | H17: =ROUND(B17/10,0) -> 14 | I17: =SUM(E17:H17) -> 56
A18: 67-T30 | B18: 149 | C18: 3270 | E18: =ROUND(B18/10,0) -> 15 | F18: =ROUND(B18/10,0) -> 15 | G18: =ROUND(B18/10,0) -> 15 | H18: =ROUND(B18/10,0) -> 15 | I18: =SUM(E18:H18) -> 60
A19: รวมปาล์มตอนบน ปี 67 | B19: =SUM(B14:B18) -> 311 | C19: =SUM(C14:C18) -> 6813 | E19: =SUM(E14:E18) -> 31 | F19: =SUM(F14:F18) -> 31 | G19: =SUM(G14:G18) -> 31 | H19: =SUM(H14:H18) -> 31 | I19: =SUM(I14:I18) -> 124
A20: ตอนล่าง
A21: 67-P01-R | B21: 99 | C21: 2167 | D21: =I24 -> 136 | E21: =ROUND(B21/10,0) -> 10 | F21: =ROUND(B21/10,0) -> 10 | G21: =ROUND(B21/10,0) -> 10 | H21: =ROUND(B21/10,0) -> 10 | I21: =SUM(E21:H21) -> 40
A22: 67-P02-R | B22: 105 | C22: 2320 | E22: =ROUND(B22/10,0) -> 11 | F22: =ROUND(B22/10,0) -> 11 | G22: =ROUND(B22/10,0) -> 11 | H22: =ROUND(B22/10,0) -> 11 | I22: =SUM(E22:H22) -> 44
A23: 67-D06-R | B23: 130 | C23: 2865 | E23: =ROUND(B23/10,0) -> 13 | F23: =ROUND(B23/10,0) -> 13 | G23: =ROUND(B23/10,0) -> 13 | H23: =ROUND(B23/10,0) -> 13 | I23: =SUM(E23:H23) -> 52
A24: รวมปาล์มตอนล่าง ปี 67 | B24: =SUM(B21:B23) -> 334 | C24: =SUM(C21:C23) -> 7352 | E24: =SUM(E21:E23) -> 34 | F24: =SUM(F21:F23) -> 34 | G24: =SUM(G21:G23) -> 34 | H24: =SUM(H21:H23) -> 34 | I24: =SUM(I21:I23) -> 136
A25: ปาล์มปี 68
A26: ตอนบน
A27: 68-T01 | B27: 144 | C27: 3171 | D27: =I29 -> 108 | E27: =ROUND(B27/10,0) -> 14 | F27: =ROUND(B27/10,0) -> 14 | G27: =ROUND(B27/10,0) -> 14 | H27: =ROUND(B27/10,0) -> 14 | I27: =SUM(E27:H27) -> 56
A28: 68-T02 | B28: 134 | C28: 2950 | E28: =ROUND(B28/10,0) -> 13 | F28: =ROUND(B28/10,0) -> 13 | G28: =ROUND(B28/10,0) -> 13 | H28: =ROUND(B28/10,0) -> 13 | I28: =SUM(E28:H28) -> 52
A29: รวมปาล์มตอนบน | B29: =SUM(B27:B28) -> 278 | C29: =SUM(C27:C28) -> 6121 | E29: =SUM(E27:E28) -> 27 | F29: =SUM(F27:F28) -> 27 | G29: =SUM(G27:G28) -> 27 | H29: =SUM(H27:H28) -> 27 | I29: =SUM(I27:I28) -> 108
A30: ตอนล่าง
A31: 68-PU1 | B31: 86 | C31: 1892 | D31: =I38 -> 156 | E31: =ROUND(B31/10,0) -> 9 | F31: =ROUND(B31/10,0) -> 9 | G31: =ROUND(B31/10,0) -> 9 | H31: =ROUND(B31/10,0) -> 9 | I31: =SUM(E31:H31) -> 36
A32: 68-PU3 | B32: 77 | C32: 1686 | E32: =ROUND(B32/10,0) -> 8 | F32: =ROUND(B32/10,0) -> 8 | G32: =ROUND(B32/10,0) -> 8 | H32: =ROUND(B32/10,0) -> 8 | I32: =SUM(E32:H32) -> 32
A33: 68-PU4 | B33: 63 | C33: 1380 | E33: =ROUND(B33/10,0) -> 6 | F33: =ROUND(B33/10,0) -> 6 | G33: =ROUND(B33/10,0) -> 6 | H33: =ROUND(B33/10,0) -> 6 | I33: =SUM(E33:H33) -> 24
A34: 68-PU5-R | B34: 53 | C34: 1168 | E34: =ROUND(B34/10,0) -> 5 | F34: =ROUND(B34/10,0) -> 5 | G34: =ROUND(B34/10,0) -> 5 | H34: =ROUND(B34/10,0) -> 5 | I34: =SUM(E34:H34) -> 20
A35: 68-PU5 | B35: 34 | C35: 751 | E35: =ROUND(B35/10,0) -> 3 | F35: =ROUND(B35/10,0) -> 3 | G35: =ROUND(B35/10,0) -> 3 | H35: =ROUND(B35/10,0) -> 3 | I35: =SUM(E35:H35) -> 12
A36: 68-PU6-R | B36: 70 | C36: 1547 | E36: =ROUND(B36/10,0) -> 7 | F36: =ROUND(B36/10,0) -> 7 | G36: =ROUND(B36/10,0) -> 7 | H36: =ROUND(B36/10,0) -> 7 | I36: =SUM(E36:H36) -> 28
A37: 68-PU6 | B37: 7 | C37: 145 | E37: =ROUND(B37/10,0) -> 1 | F37: =ROUND(B37/10,0) -> 1 | G37: =ROUND(B37/10,0) -> 1 | H37: =ROUND(B37/10,0) -> 1 | I37: =SUM(E37:H37) -> 4
A38: รวมปาล์มตอนล่าง ปี 68 | B38: =SUM(B31:B37) -> 390 | C38: =SUM(C31:C37) -> 8569 | E38: =SUM(E31:E37) -> 39 | F38: =SUM(F31:F37) -> 39 | G38: =SUM(G31:G37) -> 39 | H38: =SUM(H31:H37) -> 39 | I38: =SUM(I31:I37) -> 156

Sheet พิโพรนิล 69 
A1: พิโพรนิล 10กรัม/ต้น | I1: 1000 กรัม = 1 กิโลกรัม
A2: บล็อก | B2: ไร่ | C2: ต้น | D2: จำนวนครั้ง/ปี | E2: ปริมาณพิโพรนิล (g) | F2: รวมปริมาณ พิโพรนิล(Kg) | G2: หมายเหตุ
E3: 10
A4: ปาล์มปี 66 | J4: สูตรการคำนวณ : พิโพรนิล (10กรัม/ต้น) = (จำนวนต้น*ปริมาณพิโพรนิล)
A5: ตอนล่าง | K5: กรณีผันกรัมเป็นกิโลกรัม = ( ปริมาณพิโพรนิล/กรัม / 1000 )
A6: 66-P03-R | B6: 116 | C6: 2550 | D6: 24 | E6: =ROUND(C6*$E$3,0) -> 25500 | F6: =ROUND(E6*D6/1000,0) -> 612 | H6: =ROUND(E6/1000,0) -> 26 | I6: kg / 1ครั้ง
A7: 66-P04-R | B7: 130 | C7: 2854 | E7: =ROUND(C7*$E$3,0) -> 28540 | F7: =ROUND(E7*D6/1000,0) -> 685 | H7: =ROUND(E7/1000,0) -> 29 | I7: kg / 1ครั้ง
A8: 66-P05-R | B8: 141 | C8: 3111 | E8: =ROUND(C8*$E$3,0) -> 31110 | F8: =ROUND(E8*D6/1000,0) -> 747 | H8: =ROUND(E8/1000,0) -> 31 | I8: kg / 1ครั้ง
A9: 66-D09-R | B9: 136 | C9: 2999 | E9: =ROUND(C9*$E$3,0) -> 29990 | F9: =ROUND(E9*D6/1000,0) -> 720 | H9: =ROUND(E9/1000,0) -> 30 | I9: kg / 1ครั้ง
A10: 66-PU-02 | B10: 90 | C10: 1970 | E10: =ROUND(C10*$E$3,0) -> 19700 | F10: =ROUND(E10*D6/1000,0) -> 473 | H10: =ROUND(E10/1000,0) -> 20 | I10: kg / 1ครั้ง
A11: รวมปาล์มตอนล่าง ปี 66 | B11: =SUM(B6:B10) -> 613 | C11: =SUM(C6:C10) -> 13484 | E11: =SUM(E6:E10) -> 134840 | F11: =SUM(F6:F10) -> 3237 | H11: =ROUND(E11/1000,0) -> 135 | I11: kg / 1ครั้ง
A12: ปาล์มปี 67
A13: ตอนบน
A14: 67-T10 | B14: 3 | C14: 61 | D14: 24 | E14: =ROUND(C14*$E$3,0) -> 610 | F14: =ROUND(E14*D14/1000,0) -> 15 | H14: =ROUND(E14/1000,0) -> 1 | I14: kg / 1ครั้ง
A15: 67-T18 | B15: 8 | C15: 171 | E15: =ROUND(C15*$E$3,0) -> 1710 | F15: =ROUND(E15*D14/1000,0) -> 41 | H15: =ROUND(E15/1000,0) -> 2 | I15: kg / 1ครั้ง
A16: 67-T21 | B16: 11 | C16: 241 | E16: =ROUND(C16*$E$3,0) -> 2410 | F16: =ROUND(E16*D14/1000,0) -> 58 | H16: =ROUND(E16/1000,0) -> 2 | I16: kg / 1ครั้ง
A17: 67-T29 | B17: 140 | C17: 3070 | E17: =ROUND(C17*$E$3,0) -> 30700 | F17: =ROUND(E17*D14/1000,0) -> 737 | H17: =ROUND(E17/1000,0) -> 31 | I17: kg / 1ครั้ง
A18: 67-T30 | B18: 149 | C18: 3270 | E18: =ROUND(C18*$E$3,0) -> 32700 | F18: =ROUND(E18*D14/1000,0) -> 785 | H18: =ROUND(E18/1000,0) -> 33 | I18: kg / 1ครั้ง
A19: รวมปาล์มตอนบน ปี 67 | B19: =SUM(B14:B18) -> 311 | C19: =SUM(C14:C18) -> 6813 | E19: =SUM(E14:E18) -> 68130 | F19: =SUM(F14:F18) -> 1636 | H19: =ROUND(E19/1000,0) -> 68 | I19: kg / 1ครั้ง
A20: ตอนล่าง
A21: 67-P01-R | B21: 99 | C21: 2167 | D21: 24 | E21: =ROUND(C21*$E$3,0) -> 21670 | F21: =ROUND(E21*D21/1000,0) -> 520 | H21: =ROUND(E21/1000,0) -> 22 | I21: kg / 1ครั้ง
A22: 67-P02-R | B22: 105 | C22: 2320 | E22: =ROUND(C22*$E$3,0) -> 23200 | F22: =ROUND(E22*D21/1000,0) -> 557 | H22: =ROUND(E22/1000,0) -> 23 | I22: kg / 1ครั้ง
A23: 67-D06-R | B23: 130 | C23: 2865 | E23: =ROUND(C23*$E$3,0) -> 28650 | F23: =ROUND(E23*D21/1000,0) -> 688 | H23: =ROUND(E23/1000,0) -> 29 | I23: kg / 1ครั้ง
A24: รวมปาล์มตอนล่าง ปี 67 | B24: =SUM(B21:B23) -> 334 | C24: =SUM(C21:C23) -> 7352 | E24: =SUM(E21:E23) -> 73520 | F24: =SUM(F21:F23) -> 1765 | H24: =ROUND(E24/1000,0) -> 74 | I24: kg / 1ครั้ง
A25: ปาล์มปี 68
A26: ตอนบน
A27: 68-T01 | B27: 144 | C27: 3171 | D27: 24 | E27: =ROUND(C27*$E$3,0) -> 31710 | F27: =ROUND(E27*$D$27/1000,0) -> 761 | H27: =ROUND(E27/1000,0) -> 32 | I27: kg / 1ครั้ง
A28: 68-T02 | B28: 134 | C28: 2950 | E28: =ROUND(C28*$E$3,0) -> 29500 | F28: =ROUND(E28*$D$27/1000,0) -> 708 | H28: =ROUND(E28/1000,0) -> 30 | I28: kg / 1ครั้ง
A29: รวมปาล์มปี 68 | B29: =SUM(B27:B28) -> 278 | C29: =SUM(C27:C28) -> 6121 | E29: =SUM(E27:E28) -> 61210 | F29: =SUM(F27:F28) -> 1469 | H29: =ROUND(E29/1000,0) -> 61 | I29: kg / 1ครั้ง
A30: ตอนล่าง
A31: 68-PU1 | B31: 86 | C31: 1892 | D31: 24 | E31: =ROUND(C31*$E$3,0) -> 18920 | F31: =ROUND(E31*$D$31/1000,0) -> 454 | H31: =ROUND(E31/1000,0) -> 19 | I31: kg / 1ครั้ง
A32: 68-PU3 | B32: 77 | C32: 1686 | E32: =ROUND(C32*$E$3,0) -> 16860 | F32: =ROUND(E32*$D$31/1000,0) -> 405 | H32: =ROUND(E32/1000,0) -> 17 | I32: kg / 1ครั้ง
A33: 68-PU4 | B33: 63 | C33: 1380 | E33: =ROUND(C33*$E$3,0) -> 13800 | F33: =ROUND(E33*$D$31/1000,0) -> 331 | H33: =ROUND(E33/1000,0) -> 14 | I33: kg / 1ครั้ง
A34: 68-PU5-R | B34: 53 | C34: 1168 | E34: =ROUND(C34*$E$3,0) -> 11680 | F34: =ROUND(E34*$D$31/1000,0) -> 280 | H34: =ROUND(E34/1000,0) -> 12 | I34: kg / 1ครั้ง
A35: 68-PU5 | B35: 34 | C35: 751 | E35: =ROUND(C35*$E$3,0) -> 7510 | F35: =ROUND(E35*$D$31/1000,0) -> 180 | H35: =ROUND(E35/1000,0) -> 8 | I35: kg / 1ครั้ง
A36: 68-PU6-R | B36: 70 | C36: 1547 | E36: =ROUND(C36*$E$3,0) -> 15470 | F36: =ROUND(E36*$D$31/1000,0) -> 371 | H36: =ROUND(E36/1000,0) -> 15 | I36: kg / 1ครั้ง
A37: 68-PU6 | B37: 7 | C37: 145 | E37: =ROUND(C37*$E$3,0) -> 1450 | F37: =ROUND(E37*$D$31/1000,0) -> 35 | H37: =ROUND(E37/1000,0) -> 1 | I37: kg / 1ครั้ง
A38: รวมปาล์มปี 68 | B38: =SUM(B31:B37) -> 390 | C38: =SUM(C31:C37) -> 8569 | E38: =SUM(E31:E37) -> 85690 | F38: =SUM(F31:F37) -> 2056 | H38: =ROUND(E38/1000,0) -> 86 | I38: kg / 1ครั้ง

Sheet เจาะฆ่าต้นปาล์ม 69  
B1: เจาะฆ่าต้นปาล์ม 2569 (ไกลโฟเสท)
B2: บล็อก | C2: ไร่ | D2: ต้น | E2: จำนวน(ครั้ง/ปี) | J2: สูตรการคำนวณ : เจาะฆ่าต้นปาล์ม = (จำนวนต้น/ปริมาณสารเคมี(100ซีซี)*จำนวนครั้ง
E3: 100 CC / ต้น
E4: ครั้ง | F4: ไกลโฟเสท / CC | G4: ครั้ง | H4: ไกลโฟเสท / CC
B5: ปาล์มปี 67
B6: ตอนบน
B7: 67-T29 | C7: 140 | D7: 3070 | E7: 1 | F7: =ROUND(D7/100,0) -> 31 | G7: 1 | H7: =ROUND(D7/100,0) -> 31
B8: 67-T30 | C8: 149 | D8: 3270 | E8: 1 | F8: =ROUND(D8/100,0) -> 33 | G8: 1 | H8: =ROUND(D8/100,0) -> 33
B9: รวมปาล์มปี 67 ตอนบน | C9: =SUM(C7:C8) -> 289 | D9: =SUM(D7:D8) -> 6340 | F9: =SUM(F7:F8) -> 64 | H9: =SUM(H7:H8) -> 64
B10: รวมปาล์มปี 67 | F10: =F9 -> 64 | H10: =H9 -> 64
B11: ปาล์มปี 68
B12: ตอนบน
B13: 68-PU1 | C13: 86 | D13: 1892 | E13: 1 | F13: =ROUND(D13/100,0) -> 19 | G13: 1 | H13: =ROUND(D13/100,0) -> 19
B14: 68-PU3 | C14: 77 | D14: 1686 | E14: 1 | F14: =ROUND(D14/100,0) -> 17 | G14: 1 | H14: =ROUND(D14/100,0) -> 17
B15: 68-PU4 | C15: 63 | D15: 1380 | E15: 1 | F15: =ROUND(D15/100,0) -> 14 | G15: 1 | H15: =ROUND(D15/100,0) -> 14
B16: รวมปาล์มปี 67 ตอนบน | C16: =SUM(C13:C15) -> 226 | D16: =SUM(D13:D15) -> 4958 | F16: =SUM(F13:F15) -> 50 | H16: =SUM(H13:H15) -> 50
B17: รวมปาล์มปี 68 | F17: =F16 -> 50 | H17: =H16 -> 50

Sheet แหวกโคน 69
A1: ค่าแรงแหวกโคน
A2: บล็อก | C2: ไร่ | D2: ต้น | E2: จำนวนไร่ของพื้นที่ทั้งหมด | F2: จำนวนต้นของพื้นที่ทั้งหมด | G2: จำนวนครั้ง / ปี | H2: ค่าแรง (บาท/ต้น) | I2: รวมค่าแรงแหวกโคน
K3: สูตรการคำนวณ : ค่าแรงแหวกโคน = (จำนวนต้นในพื้นที่ต้องการแหวกโคน*ค่าแรง*จำนวนครั้ง
A4: ปาล์มปี 57
A5: ตอนบน
A6: 57-B03 | B6: 1 | C6: ='จน.ปาล์ม 69 '!E59 -> 169 | D6: ='จน.ปาล์ม 69 '!F59 -> 4231 | E6: =ROUND(C6*B6,0) -> 169 | F6: =ROUND(D6*B6,0) -> 4231 | G6: 1 | H6: 2 | I6: =ROUND(H6*F6,0) -> 8462
A7: รวมค่าแรงแหวกโคน ปาล์มปี 57 | I7: =I6 -> 8462
A8: ปาล์มปี 58 (ตอนบน)
A9: 58-T09-R | B9: 1 | C9: ='จน.ปาล์ม 69 '!E53 -> 117 | D9: ='จน.ปาล์ม 69 '!F53 -> 2934 | E9: =ROUND(C9*B9,0) -> 117 | F9: =ROUND(D9*B9,0) -> 2934 | G9: 1 | H9: 2 | I9: =ROUND(H9*F9,0) -> 5868
A10: 58-T13-R | B10: 1 | C10: ='จน.ปาล์ม 69 '!E55 -> 115 | D10: ='จน.ปาล์ม 69 '!F55 -> 2864 | E10: =ROUND(C10*B10,0) -> 115 | F10: =ROUND(D10*B10,0) -> 2864 | G10: 1 | H10: 2 | I10: =ROUND(H10*F10,0) -> 5728
A11: รวมค่าแรงแหวกโคน ปาล์มปี 58 | I11: =SUM(I9:I10) -> 11596
A12: ปาล์มปี 60
A13: ตอนบน
A14: 60-B04 | B14: 1 | C14: ='จน.ปาล์ม 69 '!E82 -> 154 | D14: ='จน.ปาล์ม 69 '!F82 -> 3851 | E14: =ROUND(C14*B14,0) -> 154 | F14: =ROUND(D14*B14,0) -> 3851 | G14: 1 | H14: 2 | I14: =ROUND(H14*F14,0) -> 7702
A15: 60-B08 | B15: 1 | C15: ='จน.ปาล์ม 69 '!E83 -> 139 | D15: ='จน.ปาล์ม 69 '!F83 -> 3476 | E15: =ROUND(C15*B15,0) -> 139 | F15: =ROUND(D15*B15,0) -> 3476 | G15: 1 | H15: 2 | I15: =ROUND(H15*F15,0) -> 6952
A16: 60-B09 | B16: 1 | C16: ='จน.ปาล์ม 69 '!E84 -> 165 | D16: ='จน.ปาล์ม 69 '!F84 -> 4127 | E16: =ROUND(C16*B16,0) -> 165 | F16: =ROUND(D16*B16,0) -> 4127 | G16: 1 | H16: 2 | I16: =ROUND(H16*F16,0) -> 8254
A17: รวมค่าแรงแหวกโคนตอนบน ปาล์มปี 60 | I17: =SUM(I14:I16) -> 22908
A18: ตอนล่าง
A19: 60-A06 | B19: 1 | C19: ='จน.ปาล์ม 69 '!E97 -> 142 | D19: ='จน.ปาล์ม 69 '!F97 -> 3259 | E19: =ROUND(C19*B19,0) -> 142 | F19: =ROUND(D19*B19,0) -> 3259 | G19: 1 | H19: 2 | I19: =ROUND(H19*F19,0) -> 6518
A20: 60-C05-R | B20: 1 | C20: ='จน.ปาล์ม 69 '!E95 -> 29 | D20: ='จน.ปาล์ม 69 '!F95 -> 720 | E20: =ROUND(C20*B20,0) -> 29 | F20: =ROUND(D20*B20,0) -> 720 | G20: 1 | H20: 2 | I20: =ROUND(H20*F20,0) -> 1440
A21: รวมค่าแรงแหวกโคนตอนล่าง ปาล์มปี 60 | I21: =SUM(I19:I20) -> 7958
A22: รวมค่าแรงแหวกโคนปาล์ม ปี 60 | I22: =I21+I17 -> 30866
A23: ปาล์มปี 63
A24: ตอนบน
A25: 63-T05-R | B25: 1 | C25: 121 | D25: 3037 | E25: =ROUND(C25*B25,0) -> 121 | F25: =ROUND(D25*B25,0) -> 3037 | G25: 2 | H25: 2 | I25: =ROUND(H25*F25*G25,0) -> 12148
A26: 63-T22-R | B26: 1 | C26: 38 | D26: 842 | E26: =ROUND(C26*B26,0) -> 38 | F26: =ROUND(D26*B26,0) -> 842 | G26: 2 | H26: 2 | I26: =ROUND(H26*F26*G26,0) -> 3368
A27: 63-T23-R | B27: 1 | C27: 38 | D27: 844 | E27: =ROUND(C27*B27,0) -> 38 | F27: =ROUND(D27*B27,0) -> 844 | G27: 2 | H27: 2 | I27: =ROUND(H27*F27*G27,0) -> 3376
A28: รวมค่าแรงแหวกโคนตอนบน ปาล์มปี 63 | I28: =SUM(I25:I27) -> 18892
A29: ตอนล่าง
A30: 63-A01-R | B30: 1 | C30: 24 | D30: 534 | E30: =ROUND(C30*B30,0) -> 24 | F30: =ROUND(D30*B30,0) -> 534 | G30: 2 | H30: 2 | I30: =ROUND(H30*F30*G30,0) -> 2136
A31: 63-A03-R | B31: 1 | C31: 39 | D31: 980 | E31: =ROUND(C31*B31,0) -> 39 | F31: =ROUND(D31*B31,0) -> 980 | G31: 2 | H31: 2 | I31: =ROUND(H31*F31*G31,0) -> 3920
A32: 63-A07-R | B32: 1 | C32: 14 | D32: 309 | E32: =ROUND(C32*B32,0) -> 14 | F32: =ROUND(D32*B32,0) -> 309 | G32: 2 | H32: 2 | I32: =ROUND(H32*F32*G32,0) -> 1236
A33: 63-A07 | B33: 1 | C33: 109 | D33: 2388 | E33: =ROUND(C33*B33,0) -> 109 | F33: =ROUND(D33*B33,0) -> 2388 | G33: 2 | H33: 2 | I33: =ROUND(H33*F33*G33,0) -> 9552
A34: 63-D08-R | B34: 1 | C34: 108 | D34: 2365 | E34: =ROUND(C34*B34,0) -> 108 | F34: =ROUND(D34*B34,0) -> 2365 | G34: 2 | H34: 2 | I34: =ROUND(H34*F34*G34,0) -> 9460
A35: รวมค่าแรงแหวกโคนปาล์ม ปี 63 ตอนล่าง | I35: =SUM(I30:I34) -> 26304
A36: รวมค่าแรงแหวกโคนปาล์มปี 63 | I36: =I35+I28 -> 45196
A37: ปาล์มปี 64
A38: ตอนบน
A39: 64-B02 | B39: 1 | C39: 158 | D39: 3480 | E39: =ROUND(C39*B39,0) -> 158 | F39: =ROUND(D39*B39,0) -> 3480 | G39: 3 | H39: 3.5 | I39: =ROUND(H39*F39*G39,0) -> 36540
A40: 64-B05 | B40: 1 | C40: 143 | D40: 3140 | E40: =ROUND(C40*B40,0) -> 143 | F40: =ROUND(D40*B40,0) -> 3140 | G40: 3 | H40: 3.5 | I40: =ROUND(H40*F40*G40,0) -> 32970
...
