Workbook

Sheet Data1
A1: wpDocNo | B1: wpInOutType | C1: wpOriginal | D1: wpDocDate | E1: wptypecar | F1: wpctCode | G1: wpctName | H1: wpRspo | I1: wpCash | J1: wpPartNo | K1: wpPlot | L1: wpBlock | M1: wpArea | N1: wpCarLicense | O1: wpCarProvince | P1: wplf2 | Q1: wpDriver | R1: wpBunchWeight | S1: wpGrade | T1: wpemCodeWeighter | U1: wpemCodeAppraisal | V1: wpAdCode | W1: wpHeadCode | X1: wpPlotRain | Y1: wpRampRain | Z1: wpTranRain | AA1: wpProduct | AB1: wpBunchPrice | AC1: wpFallPrice | AD1: wpCustWeight | AE1: wpCarWeightDate | AF1: wpCarWeightNo | AG1: wpCarWeight | AH1: wpTotalWeightDate | AI1: wpTotalWeightNo | AJ1: wpTotalWeight | AK1: wpNetWeight | AL1: wpRipePercent | AM1: wpRawPercent | AN1: wpFallPercent | AO1: wpMixRawPercent | AP1: wpBadPercent | AQ1: wpDuraPercent | AR1: wpOtherPercent | AS1: wpLongStemPercent | AT1: wpContract | AU1: wpRampAmount | AV1: wpReturnFFB | AW1: wpreturnffb2 | AX1: wpblock1 | AY1: wpblock2 | AZ1: wpblock3 | BA1: wpblock4 | BB1: wpblock5 | BC1: wpblock6 | BD1: wpblock7 | BE1: wppunch1 | BF1: wppunch2 | BG1: wppunch3 | BH1: wppunch4 | BI1: wppunch5 | BJ1: wppunch6 | BK1: wppunch7 | BL1: wpweight1 | BM1: wpweight2 | BN1: wpweight3 | BO1: wpweight4 | BP1: wpweight5 | BQ1: wpweight6 | BR1: wpweight7 | BS1: wpFacDocNo | BT1: wpFacDocDate | BU1: wpFacGrade | BV1: wpFacCarWeight | BW1: wpFacTotalWeight | BX1: wpFacNetWeight | BY1: wpFacDocNo2 | BZ1: wpFacGrade2 | CA1: wpFacCarWeight2 | CB1: wpFacTotalWeight2 | CC1: wpFacNetWeight2 | CD1: wpReturnPalm | CE1: wpftcode | CF1: wpfacprice | CG1: wpintime | CH1: wpouttime | CI1: location
A2: 2071 | B2: O | C2: N | D2: 46113 | E2: 3 | F2: 99000 | G2: {=_xlfn.XLOOKUP(TRIM(F2), TRIM(Wpct!$A$2:$A$1000), Wpct!$B$2:$B$1000, "ไม่พบชื่อ", 0) & IF(_xlfn.XLOOKUP(TRIM(F2), TRIM(Terrain!$N$2:$N$1002), Terrain!$I$2:$I$1002, "NO", 0)="YES", " (R)", "")} -> บจก.ทักษิณปาล์ม (ฝ่ายสวนปาล์ม) | H2: {=IFERROR(_xlfn.SWITCH(_xlfn.XLOOKUP(TRIM(F2), TRIM(Terrain!$N:$N), Terrain!$I:$I), "YES", "RSPO", "NO", "NON-RSPO", "OB", "Outbound Logistics"), "Contract Farmer")} -> Outbound Logistics | I2: N | K2: {=IFERROR(INDEX(Terrain!$D:$D, MATCH(TEXT(F2,"0"), TEXT(Terrain!$N:$N,"0"), 0)), "-")} -> Outbound | L2: {=IFERROR(INDEX(Terrain!$E:$E, MATCH(TEXT(F2,"0"), TEXT(Terrain!$N:$N,"0"), 0)), "-")} -> Ramp | M2: {=IFERROR(INDEX(Terrain!$C:$C, MATCH(TEXT(F2,"0"), TEXT(Terrain!$N:$N,"0"), 0)), "Contract")} -> EST | N2: 83-5636,83-5637 | O2: สฎ | P2: 0 | Q2: ประฏิพัทธิ์ คุณสุทธิ์ | R2: 0 | S2: 18 | T2: 004 | U2: 004 | X2: N | Y2: N | Z2: N | AA2: FFB | AB2: 0 | AC2: 0 | AD2: 0 | AE2: 46113.365 | AF2: 3 | AG2: 22960 | AH2: 46113.38 | AI2: 4 | AJ2: 27180 | AK2: 4220 | AL2: 0 | AM2: 0 | AN2: 0 | AO2: 0 | AP2: 0 | AQ2: 0 | AR2: 0 | AS2: 0 | AU2: 0 | AV2: 0 | AW2: 0 | BE2: 0 | BF2: 0 | BG2: 0 | BH2: 0 | BI2: 0 | BJ2: 0 | BK2: 0 | BL2: 0 | BM2: 0 | BN2: 0 | BO2: 0 | BP2: 0 | BQ2: 0 | BR2: 0 | BS2: 03172 | BT2: 46113 | BU2: 18 | BV2: 46120 | BW2: 50320 | BX2: 4200 | BZ2: 0 | CA2: 0 | CB2: 0 | CC2: 0 | CD2: 0 | CE2: SPC | CF2: 0 | CG2: 46113.619 | CH2: 46113.639 | CI2: E2071
A3: 2072 | B3: O | C3: N | D3: 46113 | E3: 3 | F3: 99000 | G3: {=_xlfn.XLOOKUP(TRIM(F3), TRIM(Wpct!$A$2:$A$1000), Wpct!$B$2:$B$1000, "ไม่พบชื่อ", 0) & IF(_xlfn.XLOOKUP(TRIM(F3), TRIM(Terrain!$N$2:$N$1002), Terrain!$I$2:$I$1002, "NO", 0)="YES", " (R)", "")} -> บจก.ทักษิณปาล์ม (ฝ่ายสวนปาล์ม) | H3: {=IFERROR(_xlfn.SWITCH(_xlfn.XLOOKUP(TRIM(F3), TRIM(Terrain!$N:$N), Terrain!$I:$I), "YES", "RSPO", "NO", "NON-RSPO", "OB", "Outbound Logistics"), "Contract Farmer")} -> Outbound Logistics | I3: N | K3: {=IFERROR(INDEX(Terrain!$D:$D, MATCH(TEXT(F3,"0"), TEXT(Terrain!$N:$N,"0"), 0)), "-")} -> Outbound | L3: {=IFERROR(INDEX(Terrain!$E:$E, MATCH(TEXT(F3,"0"), TEXT(Terrain!$N:$N,"0"), 0)), "-")} -> Ramp | M3: {=IFERROR(INDEX(Terrain!$C:$C, MATCH(TEXT(F3,"0"), TEXT(Terrain!$N:$N,"0"), 0)), "Contract")} -> EST | N3: 83-5636,83-5637 | O3: สฎ | P3: 0 | Q3: ประฏิพัทธิ์ คุณสุทธิ์ | R3: 0 | S3: 18 | T3: 004 | U3: 004 | X3: N | Y3: N | Z3: N | AA3: FFB | AB3: 0 | AC3: 0 | AD3: 0 | AE3: 46113.38 | AF3: 5 | AG3: 27180 | AH3: 46113.567 | AI3: 38 | AJ3: 50480 | AK3: 23300 | AL3: 0 | AM3: 0 | AN3: 0 | AO3: 0 | AP3: 0 | AQ3: 0 | AR3: 0 | AS3: 0 | AU3: 0 | AV3: 0 | AW3: 0 | BE3: 0 | BF3: 0 | BG3: 0 | BH3: 0 | BI3: 0 | BJ3: 0 | BK3: 0 | BL3: 0 | BM3: 0 | BN3: 0 | BO3: 0 | BP3: 0 | BQ3: 0 | BR3: 0 | BS3: N03172 | BT3: 46113 | BU3: 18 | BV3: 27100 | BW3: 50320 | BX3: 23220 | BZ3: 0 | CA3: 0 | CB3: 0 | CC3: 0 | CD3: 0 | CE3: SPC | CF3: 0 | CG3: 46113.619 | CH3: 46113.639 | CI3: E2072
A4: 2073 | B4: I | C4: N | D4: 46113 | E4: 1 | F4: 91002_2 | G4: {=_xlfn.XLOOKUP(TRIM(F4), TRIM(Wpct!$A$2:$A$1000), Wpct!$B$2:$B$1000, "ไม่พบชื่อ", 0) & IF(_xlfn.XLOOKUP(TRIM(F4), TRIM(Terrain!$N$2:$N$1002), Terrain!$I$2:$I$1002, "NO", 0)="YES", " (R)", "")} -> บางกัน 02 | H4: {=IFERROR(_xlfn.SWITCH(_xlfn.XLOOKUP(TRIM(F4), TRIM(Terrain!$N:$N), Terrain!$I:$I), "YES", "RSPO", "NO", "NON-RSPO", "OB", "Outbound Logistics"), "Contract Farmer")} -> NON-RSPO | I4: N | K4: {=IFERROR(INDEX(Terrain!$D:$D, MATCH(TEXT(F4,"0"), TEXT(Terrain!$N:$N,"0"), 0)), "-")} -> Banggun | L4: {=IFERROR(INDEX(Terrain!$E:$E, MATCH(TEXT(F4,"0"), TEXT(Terrain!$N:$N,"0"), 0)), "-")} -> 64-B02 | M4: {=IFERROR(INDEX(Terrain!$C:$C, MATCH(TEXT(F4,"0"), TEXT(Terrain!$N:$N,"0"), 0)), "Contract")} -> Upper | N4: บร5489 | O4: สฎ | P4: 0 | R4: 0 | S4: 18 | T4: 001 | U4: 001 | W4: 911_2 | X4: N | Y4: N | Z4: N | AA4: FFB | AB4: 0 | AC4: 0 | AD4: 0 | AE4: 46113.445 | AF4: 7 | AG4: 2120 | AH4: 46113.434 | AI4: 6 | AJ4: 4450 | AK4: 2330 | AL4: 0 | AM4: 0 | AN4: 0 | AO4: 0 | AP4: 0 | AQ4: 0 | AR4: 0 | AS4: 0 | AU4: 353 | AV4: 0 | AW4: 0 | BE4: 0 | BF4: 0 | BG4: 0 | BH4: 0 | BI4: 0 | BJ4: 0 | BK4: 0 | BL4: 0 | BM4: 0 | BN4: 0 | BO4: 0 | BP4: 0 | BQ4: 0 | BR4: 0 | BT4: 46113 | BU4: 0 | BV4: 0 | BW4: 0 | BX4: 0 | BZ4: 0 | CA4: 0 | CB4: 0 | CC4: 0 | CD4: 0 | CF4: 0 | CG4: 46113 | CH4: 46113 | CI4: E2073
A5: 2074 | B5: I | C5: N | D5: 46113 | E5: 1 | F5: 90009 | G5: {=_xlfn.XLOOKUP(TRIM(F5), TRIM(Wpct!$A$2:$A$1000), Wpct!$B$2:$B$1000, "ไม่พบชื่อ", 0) & IF(_xlfn.XLOOKUP(TRIM(F5), TRIM(Terrain!$N$2:$N$1002), Terrain!$I$2:$I$1002, "NO", 0)="YES", " (R)", "")} -> กะเปา 09 (R) | H5: {=IFERROR(_xlfn.SWITCH(_xlfn.XLOOKUP(TRIM(F5), TRIM(Terrain!$N:$N), Terrain!$I:$I), "YES", "RSPO", "NO", "NON-RSPO", "OB", "Outbound Logistics"), "Contract Farmer")} -> RSPO | I5: N | K5: {=IFERROR(INDEX(Terrain!$D:$D, MATCH(TEXT(F5,"0"), TEXT(Terrain!$N:$N,"0"), 0)), "-")} -> Kapao | L5: {=IFERROR(INDEX(Terrain!$E:$E, MATCH(TEXT(F5,"0"), TEXT(Terrain!$N:$N,"0"), 0)), "-")} -> 57-A09-R | M5: {=IFERROR(INDEX(Terrain!$C:$C, MATCH(TEXT(F5,"0"), TEXT(Terrain!$N:$N,"0"), 0)), "Contract")} -> Lower | N5: ผบ3033 | O5: สฎ | P5: 0 | Q5: อุทุมพร วิเชียร | R5: 0 | S5: 18 | T5: 001 | U5: 001 | W5: 902_6 | X5: N | Y5: N | Z5: N | AA5: FFB | AB5: 0 | AC5: 0 | AD5: 0 | AE5: 46113.475 | AF5: 11 | AG5: 1900 | AH5: 46113.458 | AI5: 8 | AJ5: 4920 | AK5: 3020 | AL5: 0 | AM5: 0 | AN5: 0 | AO5: 0 | AP5: 0 | AQ5: 0 | AR5: 0 | AS5: 0 | AU5: 175 | AV5: 0 | AW5: 0 | BE5: 0 | BF5: 0 | BG5: 0 | BH5: 0 | BI5: 0 | BJ5: 0 | BK5: 0 | BL5: 0 | BM5: 0 | BN5: 0 | BO5: 0 | BP5: 0 | BQ5: 0 | BR5: 0 | BT5: 46113 | BU5: 0 | BV5: 0 | BW5: 0 | BX5: 0 | BZ5: 0 | CA5: 0 | CB5: 0 | CC5: 0 | CD5: 0 | CF5: 0 | CG5: 46113 | CH5: 46113 | CI5: E2074
A6: 2075 | B6: I | C6: N | D6: 46113 | E6: 1 | F6: 22456 | G6: {=_xlfn.XLOOKUP(TRIM(F6), TRIM(Wpct!$A$2:$A$1000), Wpct!$B$2:$B$1000, "ไม่พบชื่อ", 0) & IF(_xlfn.XLOOKUP(TRIM(F6), TRIM(Terrain!$N$2:$N$1002), Terrain!$I$2:$I$1002, "NO", 0)="YES", " (R)", "")} -> บริษัท ฟี.บี. จำกัด | H6: {=IFERROR(_xlfn.SWITCH(_xlfn.XLOOKUP(TRIM(F6), TRIM(Terrain!$N:$N), Terrain!$I:$I), "YES", "RSPO", "NO", "NON-RSPO", "OB", "Outbound Logistics"), "Contract Farmer")} -> Contract Farmer | I6: N | K6: {=IFERROR(INDEX(Terrain!$D:$D, MATCH(TEXT(F6,"0"), TEXT(Terrain!$N:$N,"0"), 0)), "-")} -> - | L6: {=IFERROR(INDEX(Terrain!$E:$E, MATCH(TEXT(F6,"0"), TEXT(Terrain!$N:$N,"0"), 0)), "-")} -> - | M6: {=IFERROR(INDEX(Terrain!$C:$C, MATCH(TEXT(F6,"0"), TEXT(Terrain!$N:$N,"0"), 0)), "Contract")} -> Contract | N6: 81-0395 | O6: สฎ | P6: 0 | Q6: สมศักดิ์ รอกระโทก | R6: 0 | S6: 18 | T6: 001 | U6: 001 | X6: N | Y6: N | Z6: N | AA6: FFB | AB6: 8.2 | AC6: 0 | AD6: 0 | AE6: 46113.467 | AF6: 10 | AG6: 4060 | AH6: 46113.465 | AI6: 9 | AJ6: 6420 | AK6: 2360 | AL6: 0 | AM6: 0 | AN6: 0 | AO6: 0 | AP6: 0 | AQ6: 0 | AR6: 0 | AS6: 0 | AU6: 0 | AV6: 0 | AW6: 0 | BE6: 0 | BF6: 0 | BG6: 0 | BH6: 0 | BI6: 0 | BJ6: 0 | BK6: 0 | BL6: 0 | BM6: 0 | BN6: 0 | BO6: 0 | BP6: 0 | BQ6: 0 | BR6: 0 | BT6: 46113 | BU6: 0 | BV6: 0 | BW6: 0 | BX6: 0 | BZ6: 0 | CA6: 0 | CB6: 0 | CC6: 0 | CD6: 0 | CF6: 0 | CG6: 46113 | CH6: 46113 | CI6: E2075
A7: 2076 | B7: I | C7: N | D7: 46113 | E7: 1 | F7: 92011 | G7: {=_xlfn.XLOOKUP(TRIM(F7), TRIM(Wpct!$A$2:$A$1000), Wpct!$B$2:$B$1000, "ไม่พบชื่อ", 0) & IF(_xlfn.XLOOKUP(TRIM(F7), TRIM(Terrain!$N$2:$N$1002), Terrain!$I$2:$I$1002, "NO", 0)="YES", " (R)", "")} -> พันไร่ 11 (R) | H7: {=IFERROR(_xlfn.SWITCH(_xlfn.XLOOKUP(TRIM(F7), TRIM(Terrain!$N:$N), Terrain!$I:$I), "YES", "RSPO", "NO", "NON-RSPO", "OB", "Outbound Logistics"), "Contract Farmer")} -> RSPO | I7: N | K7: {=IFERROR(INDEX(Terrain!$D:$D, MATCH(TEXT(F7,"0"), TEXT(Terrain!$N:$N,"0"), 0)), "-")} -> Panrai | L7: {=IFERROR(INDEX(Terrain!$E:$E, MATCH(TEXT(F7,"0"), TEXT(Terrain!$N:$N,"0"), 0)), "-")} -> 59-C11-R | M7: {=IFERROR(INDEX(Terrain!$C:$C, MATCH(TEXT(F7,"0"), TEXT(Terrain!$N:$N,"0"), 0)), "Contract")} -> Lower | N7: บร2653 | O7: สฎ | P7: 0 | Q7: สันติภาพ | R7: 0 | S7: 18 | T7: 001 | U7: 001 | W7: 922_4 | X7: N | Y7: N | Z7: N | AA7: FFB | AB7: 0 | AC7: 0 | AD7: 0 | AE7: 46113.486 | AF7: 16 | AG7: 1520 | AH7: 46113.477 | AI7: 13 | AJ7: 3490 | AK7: 1970 | AL7: 0 | AM7: 0 | AN7: 0 | AO7: 0 | AP7: 0 | AQ7: 0 | AR7: 0 | AS7: 0 | AU7: 105 | AV7: 0 | AW7: 0 | BE7: 0 | BF7: 0 | BG7: 0 | BH7: 0 | BI7: 0 | BJ7: 0 | BK7: 0 | BL7: 0 | BM7: 0 | BN7: 0 | BO7: 0 | BP7: 0 | BQ7: 0 | BR7: 0 | BT7: 46113 | BU7: 0 | BV7: 0 | BW7: 0 | BX7: 0 | BZ7: 0 | CA7: 0 | CB7: 0 | CC7: 0 | CD7: 0 | CF7: 0 | CG7: 46113 | CH7: 46113 | CI7: E2076
A8: 2077 | B8: I | C8: N | D8: 46113 | E8: 1 | F8: 22455 | G8: {=_xlfn.XLOOKUP(TRIM(F8), TRIM(Wpct!$A$2:$A$1000), Wpct!$B$2:$B$1000, "ไม่พบชื่อ", 0) & IF(_xlfn.XLOOKUP(TRIM(F8), TRIM(Terrain!$N$2:$N$1002), Terrain!$I$2:$I$1002, "NO", 0)="YES", " (R)", "")} -> บริษัท สวนนายห้าง จำกัด | H8: {=IFERROR(_xlfn.SWITCH(_xlfn.XLOOKUP(TRIM(F8), TRIM(Terrain!$N:$N), Terrain!$I:$I), "YES", "RSPO", "NO", "NON-RSPO", "OB", "Outbound Logistics"), "Contract Farmer")} -> Contract Farmer | I8: N | K8: {=IFERROR(INDEX(Terrain!$D:$D, MATCH(TEXT(F8,"0"), TEXT(Terrain!$N:$N,"0"), 0)), "-")} -> - | L8: {=IFERROR(INDEX(Terrain!$E:$E, MATCH(TEXT(F8,"0"), TEXT(Terrain!$N:$N,"0"), 0)), "-")} -> - | M8: {=IFERROR(INDEX(Terrain!$C:$C, MATCH(TEXT(F8,"0"), TEXT(Terrain!$N:$N,"0"), 0)), "Contract")} -> Contract | N8: ผท1425 | O8: สฎ | P8: 0 | Q8: สมบูรณ์ | R8: 0 | S8: 18 | T8: 001 | U8: 001 | X8: N | Y8: N | Z8: N | AA8: FFB | AB8: 8.3 | AC8: 0 | AD8: 0 | AE8: 46113.495 | AF8: 18 | AG8: 2050 | AH8: 46113.483 | AI8: 14 | AJ8: 5380 | AK8: 3330 | AL8: 0 | AM8: 0 | AN8: 0 | AO8: 0 | AP8: 0 | AQ8: 0 | AR8: 0 | AS8: 0 | AU8: 0 | AV8: 0 | AW8: 4 | BE8: 0 | BF8: 0 | BG8: 0 | BH8: 0 | BI8: 0 | BJ8: 0 | BK8: 0 | BL8: 0 | BM8: 0 | BN8: 0 | BO8: 0 | BP8: 0 | BQ8: 0 | BR8: 0 | BT8: 46113 | BU8: 0 | BV8: 0 | BW8: 0 | BX8: 0 | BZ8: 0 | CA8: 0 | CB8: 0 | CC8: 0 | CD8: 0 | CF8: 0 | CG8: 46113 | CH8: 46113 | CI8: E2077
A9: 2078 | B9: I | C9: N | D9: 46113 | E9: 1 | F9: 92001 | G9: {=_xlfn.XLOOKUP(TRIM(F9), TRIM(Wpct!$A$2:$A$1000), Wpct!$B$2:$B$1000, "ไม่พบชื่อ", 0) & IF(_xlfn.XLOOKUP(TRIM(F9), TRIM(Terrain!$N$2:$N$1002), Terrain!$I$2:$I$1002, "NO", 0)="YES", " (R)", "")} -> พันไร่ 01 (R) | H9: {=IFERROR(_xlfn.SWITCH(_xlfn.XLOOKUP(TRIM(F9), TRIM(Terrain!$N:$N), Terrain!$I:$I), "YES", "RSPO", "NO", "NON-RSPO", "OB", "Outbound Logistics"), "Contract Farmer")} -> RSPO | I9: N | K9: {=IFERROR(INDEX(Terrain!$D:$D, MATCH(TEXT(F9,"0"), TEXT(Terrain!$N:$N,"0"), 0)), "-")} -> Panrai | L9: {=IFERROR(INDEX(Terrain!$E:$E, MATCH(TEXT(F9,"0"), TEXT(Terrain!$N:$N,"0"), 0)), "-")} -> 60-C01-R | M9: {=IFERROR(INDEX(Terrain!$C:$C, MATCH(TEXT(F9,"0"), TEXT(Terrain!$N:$N,"0"), 0)), "Contract")} -> Lower | N9: 81-9344 | O9: สฎ | P9: 0 | Q9: ทวีศักดิ์ วิโรจน์ | R9: 0 | S9: 18 | T9: 001 | U9: 001 | W9: 922_5 | X9: N | Y9: N | Z9: N | AA9: FFB | AB9: 0 | AC9: 0 | AD9: 0 | AE9: 46113.498 | AF9: 20 | AG9: 3440 | AH9: 46113.485 | AI9: 15 | AJ9: 8030 | AK9: 4590 | AL9: 0 | AM9: 0 | AN9: 0 | AO9: 0 | AP9: 0 | AQ9: 0 | AR9: 0 | AS9: 0 | AU9: 249 | AV9: 0 | AW9: 0 | BE9: 0 | BF9: 0 | BG9: 0 | BH9: 0 | BI9: 0 | BJ9: 0 | BK9: 0 | BL9: 0 | BM9: 0 | BN9: 0 | BO9: 0 | BP9: 0 | BQ9: 0 | BR9: 0 | BT9: 46113 | BU9: 0 | BV9: 0 | BW9: 0 | BX9: 0 | BZ9: 0 | CA9: 0 | CB9: 0 | CC9: 0 | CD9: 0 | CF9: 0 | CG9: 46113 | CH9: 46113 | CI9: E2078
A10: 2079 | B10: I | C10: N | D10: 46113 | E10: 1 | F10: 90009 | G10: {=_xlfn.XLOOKUP(TRIM(F10), TRIM(Wpct!$A$2:$A$1000), Wpct!$B$2:$B$1000, "ไม่พบชื่อ", 0) & IF(_xlfn.XLOOKUP(TRIM(F10), TRIM(Terrain!$N$2:$N$1002), Terrain!$I$2:$I$1002, "NO", 0)="YES", " (R)", "")} -> กะเปา 09 (R) | H10: {=IFERROR(_xlfn.SWITCH(_xlfn.XLOOKUP(TRIM(F10), TRIM(Terrain!$N:$N), Terrain!$I:$I), "YES", "RSPO", "NO", "NON-RSPO", "OB", "Outbound Logistics"), "Contract Farmer")} -> RSPO | I10: N | K10: {=IFERROR(INDEX(Terrain!$D:$D, MATCH(TEXT(F10,"0"), TEXT(Terrain!$N:$N,"0"), 0)), "-")} -> Kapao | L10: {=IFERROR(INDEX(Terrain!$E:$E, MATCH(TEXT(F10,"0"), TEXT(Terrain!$N:$N,"0"), 0)), "-")} -> 57-A09-R | M10: {=IFERROR(INDEX(Terrain!$C:$C, MATCH(TEXT(F10,"0"), TEXT(Terrain!$N:$N,"0"), 0)), "Contract")} -> Lower | N10: บร3677 | O10: สฎ | P10: 0 | R10: 0 | S10: 18 | T10: 001 | U10: 001 | W10: 902_6 | X10: N | Y10: N | Z10: N | AA10: FFB | AB10: 0 | AC10: 0 | AD10: 0 | AE10: 46113.501 | AF10: 24 | AG10: 1490 | AH10: 46113.489 | AI10: 17 | AJ10: 2820 | AK10: 1330 | AL10: 0 | AM10: 0 | AN10: 0 | AO10: 0 | AP10: 0 | AQ10: 0 | AR10: 0 | AS10: 0 | AU10: 91 | AV10: 0 | AW10: 0 | BE10: 0 | BF10: 0 | BG10: 0 | BH10: 0 | BI10: 0 | BJ10: 0 | BK10: 0 | BL10: 0 | BM10: 0 | BN10: 0 | BO10: 0 | BP10: 0 | BQ10: 0 | BR10: 0 | BT10: 46113 | BU10: 0 | BV10: 0 | BW10: 0 | BX10: 0 | BZ10: 0 | CA10: 0 | CB10: 0 | CC10: 0 | CD10: 0 | CF10: 0 | CG10: 46113 | CH10: 46113 | CI10: E2079
A11: 2080 | B11: I | C11: N | D11: 46113 | E11: 1 | F11: 22456 | G11: {=_xlfn.XLOOKUP(TRIM(F11), TRIM(Wpct!$A$2:$A$1000), Wpct!$B$2:$B$1000, "ไม่พบชื่อ", 0) & IF(_xlfn.XLOOKUP(TRIM(F11), TRIM(Terrain!$N$2:$N$1002), Terrain!$I$2:$I$1002, "NO", 0)="YES", " (R)", "")} -> บริษัท ฟี.บี. จำกัด | H11: {=IFERROR(_xlfn.SWITCH(_xlfn.XLOOKUP(TRIM(F11), TRIM(Terrain!$N:$N), Terrain!$I:$I), "YES", "RSPO", "NO", "NON-RSPO", "OB", "Outbound Logistics"), "Contract Farmer")} -> Contract Farmer | I11: N | K11: {=IFERROR(INDEX(Terrain!$D:$D, MATCH(TEXT(F11,"0"), TEXT(Terrain!$N:$N,"0"), 0)), "-")} -> - | L11: {=IFERROR(INDEX(Terrain!$E:$E, MATCH(TEXT(F11,"0"), TEXT(Terrain!$N:$N,"0"), 0)), "-")} -> - | M11: {=IFERROR(INDEX(Terrain!$C:$C, MATCH(TEXT(F11,"0"), TEXT(Terrain!$N:$N,"0"), 0)), "Contract")} -> Contract | N11: 81-2209 | O11: สฎ | P11: 0 | Q11: นายสุธีร์ เกตุแย้ม | R11: 0 | S11: 18 | T11: 001 | U11: 001 | X11: N | Y11: N | Z11: N | AA11: FFB | AB11: 8.2 | AC11: 0 | AD11: 0 | AE11: 46113.5 | AF11: 23 | AG11: 4490 | AH11: 46113.496 | AI11: 19 | AJ11: 7400 | AK11: 2910 | AL11: 0 | AM11: 0 | AN11: 0 | AO11: 0 | AP11: 0 | AQ11: 0 | AR11: 0 | AS11: 0 | AU11: 0 | AV11: 0 | AW11: 0 | BE11: 0 | BF11: 0 | BG11: 0 | BH11: 0 | BI11: 0 | BJ11: 0 | BK11: 0 | BL11: 0 | BM11: 0 | BN11: 0 | BO11: 0 | BP11: 0 | BQ11: 0 | BR11: 0 | BT11: 46113 | BU11: 0 | BV11: 0 | BW11: 0 | BX11: 0 | BZ11: 0 | CA11: 0 | CB11: 0 | CC11: 0 | CD11: 0 | CF11: 0 | CG11: 46113 | CH11: 46113 | CI11: E2080
A12: 2081 | B12: I | C12: N | D12: 46113 | E12: 1 | F12: 22455 | G12: {=_xlfn.XLOOKUP(TRIM(F12), TRIM(Wpct!$A$2:$A$1000), Wpct!$B$2:$B$1000, "ไม่พบชื่อ", 0) & IF(_xlfn.XLOOKUP(TRIM(F12), TRIM(Terrain!$N$2:$N$1002), Terrain!$I$2:$I$1002, "NO", 0)="YES", " (R)", "")} -> บริษัท สวนนายห้าง จำกัด | H12: {=IFERROR(_xlfn.SWITCH(_xlfn.XLOOKUP(TRIM(F12), TRIM(Terrain!$N:$N), Terrain!$I:$I), "YES", "RSPO", "NO", "NON-RSPO", "OB", "Outbound Logistics"), "Contract Farmer")} -> Contract Farmer | I12: N | K12: {=IFERROR(INDEX(Terrain!$D:$D, MATCH(TEXT(F12,"0"), TEXT(Terrain!$N:$N,"0"), 0)), "-")} -> - | L12: {=IFERROR(INDEX(Terrain!$E:$E, MATCH(TEXT(F12,"0"), TEXT(Terrain!$N:$N,"0"), 0)), "-")} -> - | M12: {=IFERROR(INDEX(Terrain!$C:$C, MATCH(TEXT(F12,"0"), TEXT(Terrain!$N:$N,"0"), 0)), "Contract")} -> Contract | N12: ผต1807 | O12: สฎ | P12: 0 | Q12: ชัชพิสิฐ มวนนามอญ | R12: 0 | S12: 18 | T12: 001 | U12: 001 | X12: N | Y12: N | Z12: N | AA12: FFB | AB12: 8.3 | AC12: 0 | AD12: 0 | AE12: 46113.507 | AF12: 25 | AG12: 2210 | AH12: 46113.499 | AI12: 21 | AJ12: 4700 | AK12: 2490 | AL12: 0 | AM12: 0 | AN12: 0 | AO12: 0 | AP12: 0 | AQ12: 0 | AR12: 0 | AS12: 0 | AU12: 0 | AV12: 0 | AW12: 0 | BE12: 0 | BF12: 0 | BG12: 0 | BH12: 0 | BI12: 0 | BJ12: 0 | BK12: 0 | BL12: 0 | BM12: 0 | BN12: 0 | BO12: 0 | BP12: 0 | BQ12: 0 | BR12: 0 | BT12: 46113 | BU12: 0 | BV12: 0 | BW12: 0 | BX12: 0 | BZ12: 0 | CA12: 0 | CB12: 0 | CC12: 0 | CD12: 0 | CF12: 0 | CG12: 46113 | CH12: 46113 | CI12: E2081
A13: 2082 | B13: I | C13: N | D13: 46113 | E13: 1 | F13: 91001_2 | G13: {=_xlfn.XLOOKUP(TRIM(F13), TRIM(Wpct!$A$2:$A$1000), Wpct!$B$2:$B$1000, "ไม่พบชื่อ", 0) & IF(_xlfn.XLOOKUP(TRIM(F13), TRIM(Terrain!$N$2:$N$1002), Terrain!$I$2:$I$1002, "NO", 0)="YES", " (R)", "")} -> บางกัน 01 | H13: {=IFERROR(_xlfn.SWITCH(_xlfn.XLOOKUP(TRIM(F13), TRIM(Terrain!$N:$N), Terrain!$I:$I), "YES", "RSPO", "NO", "NON-RSPO", "OB", "Outbound Logistics"), "Contract Farmer")} -> NON-RSPO | I13: N | K13: {=IFERROR(INDEX(Terrain!$D:$D, MATCH(TEXT(F13,"0"), TEXT(Terrain!$N:$N,"0"), 0)), "-")} -> Banggun | L13: {=IFERROR(INDEX(Terrain!$E:$E, MATCH(TEXT(F13,"0"), TEXT(Terrain!$N:$N,"0"), 0)), "-")} -> 65-B01 | M13: {=IFERROR(INDEX(Terrain!$C:$C, MATCH(TEXT(F13,"0"), TEXT(Terrain!$N:$N,"0"), 0)), "Contract")} -> Upper | N13: 82-5318 | O13: สฎ | P13: 0 | Q13: นายพรชัย ช่วยจำ | R13: 0 | S13: 18 | T13: 001 | U13: 001 | W13: 911_4 | X13: N | Y13: N | Z13: N | AA13: FFB | AB13: 0 | AC13: 0 | AD13: 0 | AE13: 46113.537 | AF13: 27 | AG13: 5070 | AH13: 46113.536 | AI13: 26 | AJ13: 7370 | AK13: 2300 | AL13: 0 | AM13: 0 | AN13: 0 | AO13: 0 | AP13: 0 | AQ13: 0 | AR13: 0 | AS13: 0 | AU13: 807 | AV13: 0 | AW13: 0 | BE13: 0 | BF13: 0 | BG13: 0 | BH13: 0 | BI13: 0 | BJ13: 0 | BK13: 0 | BL13: 0 | BM13: 0 | BN13: 0 | BO13: 0 | BP13: 0 | BQ13: 0 | BR13: 0 | BT13: 46113 | BU13: 0 | BV13: 0 | BW13: 0 | BX13: 0 | BZ13: 0 | CA13: 0 | CB13: 0 | CC13: 0 | CD13: 0 | CF13: 0 | CG13: 46113 | CH13: 46113 | CI13: E2082
A14: 2083 | B14: I | C14: N | D14: 46113 | E14: 1 | F14: 91013 | G14: {=_xlfn.XLOOKUP(TRIM(F14), TRIM(Wpct!$A$2:$A$1000), Wpct!$B$2:$B$1000, "ไม่พบชื่อ", 0) & IF(_xlfn.XLOOKUP(TRIM(F14), TRIM(Terrain!$N$2:$N$1002), Terrain!$I$2:$I$1002, "NO", 0)="YES", " (R)", "")} -> บางกัน 13 | H14: {=IFERROR(_xlfn.SWITCH(_xlfn.XLOOKUP(TRIM(F14), TRIM(Terrain!$N:$N), Terrain!$I:$I), "YES", "RSPO", "NO", "NON-RSPO", "OB", "Outbound Logistics"), "Contract Farmer")} -> NON-RSPO | I14: N | K14: {=IFERROR(INDEX(Terrain!$D:$D, MATCH(TEXT(F14,"0"), TEXT(Terrain!$N:$N,"0"), 0)), "-")} -> Banggun | L14: {=IFERROR(INDEX(Terrain!$E:$E, MATCH(TEXT(F14,"0"), TEXT(Terrain!$N:$N,"0"), 0)), "-")} -> 49-B13 | M14: {=IFERROR(INDEX(Terrain!$C:$C, MATCH(TEXT(F14,"0"), TEXT(Terrain!$N:$N,"0"), 0)), "Contract")} -> Upper | N14: 82-2952 | O14: สฎ | P14: 0 | Q14: ธวัชชัย ชูจอน | R14: 0 | S14: 18 | T14: 001 | U14: 001 | W14: 919 | X14: N | Y14: N | Z14: N | AA14: FFB | AB14: 0 | AC14: 0 | AD14: 0 | AE14: 46113.542 | AF14: 29 | AG14: 7230 | AH14: 46113.54 | AI14: 28 | AJ14: 15280 | AK14: 8050 | AL14: 0 | AM14: 0 | AN14: 0 | AO14: 0 | AP14: 0 | AQ14: 0 | AR14: 0 | AS14: 0 | AU14: 335 | AV14: 0 | AW14: 0 | BE14: 0 | BF14: 0 | BG14: 0 | BH14: 0 | BI14: 0 | BJ14: 0 | BK14: 0 | BL14: 0 | BM14: 0 | BN14: 0 | BO14: 0 | BP14: 0 | BQ14: 0 | BR14: 0 | BT14: 46113 | BU14: 0 | BV14: 0 | BW14: 0 | BX14: 0 | BZ14: 0 | CA14: 0 | CB14: 0 | CC14: 0 | CD14: 0 | CF14: 0 | CG14: 46113 | CH14: 46113 | CI14: E2083
A15: 2084 | B15: I | C15: N | D15: 46113 | E15: 1 | F15: 92011 | G15: {=_xlfn.XLOOKUP(TRIM(F15), TRIM(Wpct!$A$2:$A$1000), Wpct!$B$2:$B$1000, "ไม่พบชื่อ", 0) & IF(_xlfn.XLOOKUP(TRIM(F15), TRIM(Terrain!$N$2:$N$1002), Terrain!$I$2:$I$1002, "NO", 0)="YES", " (R)", "")} -> พันไร่ 11 (R) | H15: {=IFERROR(_xlfn.SWITCH(_xlfn.XLOOKUP(TRIM(F15), TRIM(Terrain!$N:$N), Terrain!$I:$I), "YES", "RSPO", "NO", "NON-RSPO", "OB", "Outbound Logistics"), "Contract Farmer")} -> RSPO | I15: N | K15: {=IFERROR(INDEX(Terrain!$D:$D, MATCH(TEXT(F15,"0"), TEXT(Terrain!$N:$N,"0"), 0)), "-")} -> Panrai | L15: {=IFERROR(INDEX(Terrain!$E:$E, MATCH(TEXT(F15,"0"), TEXT(Terrain!$N:$N,"0"), 0)), "-")} -> 59-C11-R | M15: {=IFERROR(INDEX(Terrain!$C:$C, MATCH(TEXT(F15,"0"), TEXT(Terrain!$N:$N,"0"), 0)), "Contract")} -> Lower | N15: บร2653 | O15: สฎ | P15: 0 | Q15: สันติภาพ | R15: 0 | S15: 18 | T15: 001 | U15: 001 | W15: 922_4 | X15: N | Y15: N | Z15: N | AA15: FFB | AB15: 0 | AC15: 0 | AD15: 0 | AE15: 46113.551 | AF15: 32 | AG15: 1520 | AH15: 46113.544 | AI15: 30 | AJ15: 3100 | AK15: 1580 | AL15: 0 | AM15: 0 | AN15: 0 | AO15: 0 | AP15: 0 | AQ15: 0 | AR15: 0 | AS15: 0 | AU15: 74 | AV15: 0 | AW15: 0 | BE15: 0 | BF15: 0 | BG15: 0 | BH15: 0 | BI15: 0 | BJ15: 0 | BK15: 0 | BL15: 0 | BM15: 0 | BN15: 0 | BO15: 0 | BP15: 0 | BQ15: 0 | BR15: 0 | BT15: 46113 | BU15: 0 | BV15: 0 | BW15: 0 | BX15: 0 | BZ15: 0 | CA15: 0 | CB15: 0 | CC15: 0 | CD15: 0 | CF15: 0 | CG15: 46113 | CH15: 46113 | CI15: E2084
A16: 2085 | B16: I | C16: N | D16: 46113 | E16: 1 | F16: 94006_2 | G16: {=_xlfn.XLOOKUP(TRIM(F16), TRIM(Wpct!$A$2:$A$1000), Wpct!$B$2:$B$1000, "ไม่พบชื่อ", 0) & IF(_xlfn.XLOOKUP(TRIM(F16), TRIM(Terrain!$N$2:$N$1002), Terrain!$I$2:$I$1002, "NO", 0)="YES", " (R)", "")} -> ปลายราง 06 (R) | H16: {=IFERROR(_xlfn.SWITCH(_xlfn.XLOOKUP(TRIM(F16), TRIM(Terrain!$N:$N), Terrain!$I:$I), "YES", "RSPO", "NO", "NON-RSPO", "OB", "Outbound Logistics"), "Contract Farmer")} -> RSPO | I16: N | K16: {=IFERROR(INDEX(Terrain!$D:$D, MATCH(TEXT(F16,"0"), TEXT(Terrain!$N:$N,"0"), 0)), "-")} -> Plairang | L16: {=IFERROR(INDEX(Terrain!$E:$E, MATCH(TEXT(F16,"0"), TEXT(Terrain!$N:$N,"0"), 0)), "-")} -> 64-P06-R | M16: {=IFERROR(INDEX(Terrain!$C:$C, MATCH(TEXT(F16,"0"), TEXT(Terrain!$N:$N,"0"), 0)), "Contract")} -> Lower | N16: ผท9991 | O16: สฎ | P16: 0 | R16: 0 | S16: 18 | T16: 001 | U16: 001 | W16: 942_3 | X16: N | Y16: N | Z16: N | AA16: FFB | AB16: 0 | AC16: 0 | AD16: 0 | AE16: 46113.553 | AF16: 33 | AG16: 2120 | AH16: 46113.549 | AI16: 31 | AJ16: 4130 | AK16: 2010 | AL16: 0 | AM16: 0 | AN16: 0 | AO16: 0 | AP16: 0 | AQ16: 0 | AR16: 0 | AS16: 0 | AU16: 320 | AV16: 0 | AW16: 0 | BE16: 0 | BF16: 0 | BG16: 0 | BH16: 0 | BI16: 0 | BJ16: 0 | BK16: 0 | BL16: 0 | BM16: 0 | BN16: 0 | BO16: 0 | BP16: 0 | BQ16: 0 | BR16: 0 | BT16: 46113 | BU16: 0 | BV16: 0 | BW16: 0 | BX16: 0 | BZ16: 0 | CA16: 0 | CB16: 0 | CC16: 0 | CD16: 0 | CF16: 0 | CG16: 46113 | CH16: 46113 | CI16: E2085
A17: 2086 | B17: I | C17: N | D17: 46113 | E17: 1 | F17: 92001 | G17: {=_xlfn.XLOOKUP(TRIM(F17), TRIM(Wpct!$A$2:$A$1000), Wpct!$B$2:$B$1000, "ไม่พบชื่อ", 0) & IF(_xlfn.XLOOKUP(TRIM(F17), TRIM(Terrain!$N$2:$N$1002), Terrain!$I$2:$I$1002, "NO", 0)="YES", " (R)", "")} -> พันไร่ 01 (R) | H17: {=IFERROR(_xlfn.SWITCH(_xlfn.XLOOKUP(TRIM(F17), TRIM(Terrain!$N:$N), Terrain!$I:$I), "YES", "RSPO", "NO", "NON-RSPO", "OB", "Outbound Logistics"), "Contract Farmer")} -> RSPO | I17: N | K17: {=IFERROR(INDEX(Terrain!$D:$D, MATCH(TEXT(F17,"0"), TEXT(Terrain!$N:$N,"0"), 0)), "-")} -> Panrai | L17: {=IFERROR(INDEX(Terrain!$E:$E, MATCH(TEXT(F17,"0"), TEXT(Terrain!$N:$N,"0"), 0)), "-")} -> 60-C01-R | M17: {=IFERROR(INDEX(Terrain!$C:$C, MATCH(TEXT(F17,"0"), TEXT(Terrain!$N:$N,"0"), 0)), "Contract")} -> Lower | N17: 81-9344 | O17: สฎ | P17: 0 | Q17: ทวีศักดิ์ วิโรจน์ | R17: 0 | S17: 18 | T17: 001 | U17: 001 | W17: 922_5 | X17: N | Y17: N | Z17: N | AA17: FFB | AB17: 0 | AC17: 0 | AD17: 0 | AE17: 46113.562 | AF17: 37 | AG17: 3440 | AH17: 46113.559 | AI17: 34 | AJ17: 7060 | AK17: 3620 | AL17: 0 | AM17: 0 | AN17: 0 | AO17: 0 | AP17: 0 | AQ17: 0 | AR17: 0 | AS17: 0 | AU17: 228 | AV17: 0 | AW17: 0 | BE17: 0 | BF17: 0 | BG17: 0 | BH17: 0 | BI17: 0 | BJ17: 0 | BK17: 0 | BL17: 0 | BM17: 0 | BN17: 0 | BO17: 0 | BP17: 0 | BQ17: 0 | BR17: 0 | BT17: 46113 | BU17: 0 | BV17: 0 | BW17: 0 | BX17: 0 | BZ17: 0 | CA17: 0 | CB17: 0 | CC17: 0 | CD17: 0 | CF17: 0 | CG17: 46113 | CH17: 46113 | CI17: E2086
A18: 2087 | B18: O | C18: N | D18: 46113 | E18: 1 | F18: 99000 | G18: {=_xlfn.XLOOKUP(TRIM(F18), TRIM(Wpct!$A$2:$A$1000), Wpct!$B$2:$B$1000, "ไม่พบชื่อ", 0) & IF(_xlfn.XLOOKUP(TRIM(F18), TRIM(Terrain!$N$2:$N$1002), Terrain!$I$2:$I$1002, "NO", 0)="YES", " (R)", "")} -> บจก.ทักษิณปาล์ม (ฝ่ายสวนปาล์ม) | H18: {=IFERROR(_xlfn.SWITCH(_xlfn.XLOOKUP(TRIM(F18), TRIM(Terrain!$N:$N), Terrain!$I:$I), "YES", "RSPO", "NO", "NON-RSPO", "OB", "Outbound Logistics"), "Contract Farmer")} -> Outbound Logistics | I18: N | K18: {=IFERROR(INDEX(Terrain!$D:$D, MATCH(TEXT(F18,"0"), TEXT(Terrain!$N:$N,"0"), 0)), "-")} -> Outbound | L18: {=IFERROR(INDEX(Terrain!$E:$E, MATCH(TEXT(F18,"0"), TEXT(Terrain!$N:$N,"0"), 0)), "-")} -> Ramp | M18: {=IFERROR(INDEX(Terrain!$C:$C, MATCH(TEXT(F18,"0"), TEXT(Terrain!$N:$N,"0"), 0)), "Contract")} -> EST | N18: 81-5257 | O18: สฎ | P18: 0 | Q18: นายพจร เคลื่อนทอง | R18: 0 | S18: 18 | T18: 001 | U18: 001 | X18: N | Y18: N | Z18: N | AA18: FFB | AB18: 0 | AC18: 0 | AD18: 0 | AE18: 46113.561 | AF18: 36 | AG18: 10750 | AH18: 46113.601 | AI18: 47 | AJ18: 24970 | AK18: 14220 | AL18: 0 | AM18: 0 | AN18: 0 | AO18: 0 | AP18: 0 | AQ18: 0 | AR18: 0 | AS18: 0 | AU18: 0 | AV18: 0 | AW18: 0 | BE18: 0 | BF18: 0 | BG18: 0 | BH18: 0 | BI18: 0 | BJ18: 0 | BK18: 0 | BL18: 0 | BM18: 0 | BN18: 0 | BO18: 0 | BP18: 0 | BQ18: 0 | BR18: 0 | BS18: 03175 | BT18: 46113 | BU18: 18 | BV18: 10720 | BW18: 24890 | BX18: 14170 | BZ18: 0 | CA18: 0 | CB18: 0 | CC18: 0 | CD18: 0 | CE18: SPC | CF18: 0 | CG18: 46113.647 | CH18: 46113.663 | CI18: E2087
A19: 2088 | B19: I | C19: N | D19: 46113 | E19: 1 | F19: 22424 | G19: {=_xlfn.XLOOKUP(TRIM(F19), TRIM(Wpct!$A$2:$A$1000), Wpct!$B$2:$B$1000, "ไม่พบชื่อ", 0) & IF(_xlfn.XLOOKUP(TRIM(F19), TRIM(Terrain!$N$2:$N$1002), Terrain!$I$2:$I$1002, "NO", 0)="YES", " (R)", "")} -> บริษัทศรีสุบรรณฟาร์ม จำกัด | H19: {=IFERROR(_xlfn.SWITCH(_xlfn.XLOOKUP(TRIM(F19), TRIM(Terrain!$N:$N), Terrain!$I:$I), "YES", "RSPO", "NO", "NON-RSPO", "OB", "Outbound Logistics"), "Contract Farmer")} -> Contract Farmer | I19: N | K19: {=IFERROR(INDEX(Terrain!$D:$D, MATCH(TEXT(F19,"0"), TEXT(Terrain!$N:$N,"0"), 0)), "-")} -> - | L19: {=IFERROR(INDEX(Terrain!$E:$E, MATCH(TEXT(F19,"0"), TEXT(Terrain!$N:$N,"0"), 0)), "-")} -> - | M19: {=IFERROR(INDEX(Terrain!$C:$C, MATCH(TEXT(F19,"0"), TEXT(Terrain!$N:$N,"0"), 0)), "Contract")} -> Contract | N19: 82-0528 | O19: สฎ | P19: 0 | R19: 0 | S19: 18 | T19: 001 | U19: 001 | X19: N | Y19: N | Z19: N | AA19: FFB | AB19: 8.6 | AC19: 0 | AD19: 0 | AE19: 46113.58 | AF19: 42 | AG19: 5440 | AH19: 46113.57 | AI19: 40 | AJ19: 11010 | AK19: 5570 | AL19: 0 | AM19: 0 | AN19: 0 | AO19: 0 | AP19: 0 | AQ19: 0 | AR19: 0 | AS19: 0 | AU19: 0 | AV19: 0 | AW19: 20 | BE19: 0 | BF19: 0 | BG19: 0 | BH19: 0 | BI19: 0 | BJ19: 0 | BK19: 0 | BL19: 0 | BM19: 0 | BN19: 0 | BO19: 0 | BP19: 0 | BQ19: 0 | BR19: 0 | BT19: 46113 | BU19: 0 | BV19: 0 | BW19: 0 | BX19: 0 | BZ19: 0 | CA19: 0 | CB19: 0 | CC19: 0 | CD19: 0 | CF19: 0 | CG19: 46113 | CH19: 46113 | CI19: E2088
A20: 2089 | B20: I | C20: N | D20: 46113 | E20: 1 | F20: 22456 | G20: {=_xlfn.XLOOKUP(TRIM(F20), TRIM(Wpct!$A$2:$A$1000), Wpct!$B$2:$B$1000, "ไม่พบชื่อ", 0) & IF(_xlfn.XLOOKUP(TRIM(F20), TRIM(Terrain!$N$2:$N$1002), Terrain!$I$2:$I$1002, "NO", 0)="YES", " (R)", "")} -> บริษัท ฟี.บี. จำกัด | H20: {=IFERROR(_xlfn.SWITCH(_xlfn.XLOOKUP(TRIM(F20), TRIM(Terrain!$N:$N), Terrain!$I:$I), "YES", "RSPO", "NO", "NON-RSPO", "OB", "Outbound Logistics"), "Contract Farmer")} -> Contract Farmer | I20: N | K20: {=IFERROR(INDEX(Terrain!$D:$D, MATCH(TEXT(F20,"0"), TEXT(Terrain!$N:$N,"0"), 0)), "-")} -> - | L20: {=IFERROR(INDEX(Terrain!$E:$E, MATCH(TEXT(F20,"0"), TEXT(Terrain!$N:$N,"0"), 0)), "-")} -> - | M20: {=IFERROR(INDEX(Terrain!$C:$C, MATCH(TEXT(F20,"0"), TEXT(Terrain!$N:$N,"0"), 0)), "Contract")} -> Contract | N20: 81-0395 | O20: สฎ | P20: 0 | Q20: สมศักดิ์ รอกระโทก | R20: 0 | S20: 18 | T20: 001 | U20: 001 | X20: N | Y20: N | Z20: N | AA20: FFB | AB20: 8.2 | AC20: 0 | AD20: 0 | AE20: 46113.582 | AF20: 43 | AG20: 4060 | AH20: 46113.572 | AI20: 41 | AJ20: 8100 | AK20: 4040 | AL20: 0 | AM20: 0 | AN20: 0 | AO20: 0 | AP20: 0 | AQ20: 0 | AR20: 0 | AS20: 0 | AU20: 0 | AV20: 0 | AW20: 0 | BE20: 0 | BF20: 0 | BG20: 0 | BH20: 0 | BI20: 0 | BJ20: 0 | BK20: 0 | BL20: 0 | BM20: 0 | BN20: 0 | BO20: 0 | BP20: 0 | BQ20: 0 | BR20: 0 | BT20: 46113 | BU20: 0 | BV20: 0 | BW20: 0 | BX20: 0 | BZ20: 0 | CA20: 0 | CB20: 0 | CC20: 0 | CD20: 0 | CF20: 0 | CG20: 46113 | CH20: 46113 | CI20: E2089
A21: 2090 | B21: I | C21: N | D21: 46113 | E21: 1 | F21: 94008_2 | G21: {=_xlfn.XLOOKUP(TRIM(F21), TRIM(Wpct!$A$2:$A$1000), Wpct!$B$2:$B$1000, "ไม่พบชื่อ", 0) & IF(_xlfn.XLOOKUP(TRIM(F21), TRIM(Terrain!$N$2:$N$1002), Terrain!$I$2:$I$1002, "NO", 0)="YES", " (R)", "")} -> ปลายราง 08 (R) | H21: {=IFERROR(_xlfn.SWITCH(_xlfn.XLOOKUP(TRIM(F21), TRIM(Terrain!$N:$N), Terrain!$I:$I), "YES", "RSPO", "NO", "NON-RSPO", "OB", "Outbound Logistics"), "Contract Farmer")} -> RSPO | I21: N | K21: {=IFERROR(INDEX(Terrain!$D:$D, MATCH(TEXT(F21,"0"), TEXT(Terrain!$N:$N,"0"), 0)), "-")} -> Plairang | L21: {=IFERROR(INDEX(Terrain!$E:$E, MATCH(TEXT(F21,"0"), TEXT(Terrain!$N:$N,"0"), 0)), "-")} -> 64-P08-R | M21: {=IFERROR(INDEX(Terrain!$C:$C, MATCH(TEXT(F21,"0"), TEXT(Terrain!$N:$N,"0"), 0)), "Contract")} -> Lower | N21: 81-1907 | O21: สฎ | P21: 0 | Q21: นายศุภชัย ว่างงาน | R21: 0 | S21: 18 | T21: 001 | U21: 001 | W21: 942_1 | X21: N | Y21: N | Z21: N | AA21: FFB | AB21: 0 | AC21: 0 | AD21: 0 | AE21: 46113.595 | AF21: 45 | AG21: 6660 | AH21: 46113.592 | AI21: 44 | AJ21: 11490 | AK21: 4830 | AL21: 0 | AM21: 0 | AN21: 0 | AO21: 0 | AP21: 0 | AQ21: 0 | AR21: 0 | AS21: 0 | AU21: 921 | AV21: 0 | AW21: 0 | BE21: 0 | BF21: 0 | BG21: 0 | BH21: 0 | BI21: 0 | BJ21: 0 | BK21: 0 | BL21: 0 | BM21: 0 | BN21: 0 | BO21: 0 | BP21: 0 | BQ21: 0 | BR21: 0 | BT21: 46113 | BU21: 0 | BV21: 0 | BW21: 0 | BX21: 0 | BZ21: 0 | CA21: 0 | CB21: 0 | CC21: 0 | CD21: 0 | CF21: 0 | CG21: 46113 | CH21: 46113 | CI21: E2090
A22: 2091 | B22: I | C22: N | D22: 46113 | E22: 1 | F22: 22455 | G22: {=_xlfn.XLOOKUP(TRIM(F22), TRIM(Wpct!$A$2:$A$1000), Wpct!$B$2:$B$1000, "ไม่พบชื่อ", 0) & IF(_xlfn.XLOOKUP(TRIM(F22), TRIM(Terrain!$N$2:$N$1002), Terrain!$I$2:$I$1002, "NO", 0)="YES", " (R)", "")} -> บริษัท สวนนายห้าง จำกัด | H22: {=IFERROR(_xlfn.SWITCH(_xlfn.XLOOKUP(TRIM(F22), TRIM(Terrain!$N:$N), Terrain!$I:$I), "YES", "RSPO", "NO", "NON-RSPO", "OB", "Outbound Logistics"), "Contract Farmer")} -> Contract Farmer | I22: N | K22: {=IFERROR(INDEX(Terrain!$D:$D, MATCH(TEXT(F22,"0"), TEXT(Terrain!$N:$N,"0"), 0)), "-")} -> - | L22: {=IFERROR(INDEX(Terrain!$E:$E, MATCH(TEXT(F22,"0"), TEXT(Terrain!$N:$N,"0"), 0)), "-")} -> - | M22: {=IFERROR(INDEX(Terrain!$C:$C, MATCH(TEXT(F22,"0"), TEXT(Terrain!$N:$N,"0"), 0)), "Contract")} -> Contract | N22: ผต1807 | O22: สฎ | P22: 0 | Q22: ชัชพิสิฐ มวนนามอญ | R22: 0 | S22: 18 | T22: 001 | U22: 001 | X22: N | Y22: N | Z22: N | AA22: FFB | AB22: 8.3 | AC22: 0 | AD22: 0 | AE22: 46113.611 | AF22: 51 | AG22: 2180 | AH22: 46113.598 | AI22: 46 | AJ22: 5440 | AK22: 3260 | AL22: 0 | AM22: 0 | AN22: 0 | AO22: 0 | AP22: 0 | AQ22: 0 | AR22: 0 | AS22: 0 | AU22: 0 | AV22: 0 | AW22: 0 | BE22: 0 | BF22: 0 | BG22: 0 | BH22: 0 | BI22: 0 | BJ22: 0 | BK22: 0 | BL22: 0 | BM22: 0 | BN22: 0 | BO22: 0 | BP22: 0 | BQ22: 0 | BR22: 0 | BT22: 46113 | BU22: 0 | BV22: 0 | BW22: 0 | BX22: 0 | BZ22: 0 | CA22: 0 | CB22: 0 | CC22: 0 | CD22: 0 | CF22: 0 | CG22: 46113 | CH22: 46113 | CI22: E2091
A23: 2092 | B23: I | C23: N | D23: 46113 | E23: 1 | F23: 22455 | G23: {=_xlfn.XLOOKUP(TRIM(F23), TRIM(Wpct!$A$2:$A$1000), Wpct!$B$2:$B$1000, "ไม่พบชื่อ", 0) & IF(_xlfn.XLOOKUP(TRIM(F23), TRIM(Terrain!$N$2:$N$1002), Terrain!$I$2:$I$1002, "NO", 0)="YES", " (R)", "")} -> บริษัท สวนนายห้าง จำกัด | H23: {=IFERROR(_xlfn.SWITCH(_xlfn.XLOOKUP(TRIM(F23), TRIM(Terrain!$N:$N), Terrain!$I:$I), "YES", "RSPO", "NO", "NON-RSPO", "OB", "Outbound Logistics"), "Contract Farmer")} -> Contract Farmer | I23: N | K23: {=IFERROR(INDEX(Terrain!$D:$D, MATCH(TEXT(F23,"0"), TEXT(Terrain!$N:$N,"0"), 0)), "-")} -> - | L23: {=IFERROR(INDEX(Terrain!$E:$E, MATCH(TEXT(F23,"0"), TEXT(Terrain!$N:$N,"0"), 0)), "-")} -> - | M23: {=IFERROR(INDEX(Terrain!$C:$C, MATCH(TEXT(F23,"0"), TEXT(Terrain!$N:$N,"0"), 0)), "Contract")} -> Contract | N23: ผท1425 | O23: สฎ | P23: 0 | Q23: สมบูรณ์ | R23: 0 | S23: 18 | T23: 001 | U23: 001 | X23: N | Y23: N | Z23: N | AA23: FFB | AB23: 8.3 | AC23: 0 | AD23: 0 | AE23: 46113.621 | AF23: 55 | AG23: 2020 | AH23: 46113.603 | AI23: 48 | AJ23: 5350 | AK23: 3330 | AL23: 0 | AM23: 0 | AN23: 0 | AO23: 0 | AP23: 0 | AQ23: 0 | AR23: 0 | AS23: 0 | AU23: 0 | AV23: 0 | AW23: 4 | BE23: 0 | BF23: 0 | BG23: 0 | BH23: 0 | BI23: 0 | BJ23: 0 | BK23: 0 | BL23: 0 | BM23: 0 | BN23: 0 | BO23: 0 | BP23: 0 | BQ23: 0 | BR23: 0 | BT23: 46113 | BU23: 0 | BV23: 0 | BW23: 0 | BX23: 0 | BZ23: 0 | CA23: 0 | CB23: 0 | CC23: 0 | CD23: 0 | CF23: 0 | CG23: 46113 | CH23: 46113 | CI23: E2092
A24: 2093 | B24: I | C24: N | D24: 46113 | E24: 1 | F24: 92001 | G24: {=_xlfn.XLOOKUP(TRIM(F24), TRIM(Wpct!$A$2:$A$1000), Wpct!$B$2:$B$1000, "ไม่พบชื่อ", 0) & IF(_xlfn.XLOOKUP(TRIM(F24), TRIM(Terrain!$N$2:$N$1002), Terrain!$I$2:$I$1002, "NO", 0)="YES", " (R)", "")} -> พันไร่ 01 (R) | H24: {=IFERROR(_xlfn.SWITCH(_xlfn.XLOOKUP(TRIM(F24), TRIM(Terrain!$N:$N), Terrain!$I:$I), "YES", "RSPO", "NO", "NON-RSPO", "OB", "Outbound Logistics"), "Contract Farmer")} -> RSPO | I24: N | K24: {=IFERROR(INDEX(Terrain!$D:$D, MATCH(TEXT(F24,"0"), TEXT(Terrain!$N:$N,"0"), 0)), "-")} -> Panrai | L24: {=IFERROR(INDEX(Terrain!$E:$E, MATCH(TEXT(F24,"0"), TEXT(Terrain!$N:$N,"0"), 0)), "-")} -> 60-C01-R | M24: {=IFERROR(INDEX(Terrain!$C:$C, MATCH(TEXT(F24,"0"), TEXT(Terrain!$N:$N,"0"), 0)), "Contract")} -> Lower | N24: 81-9344 | O24: สฎ | P24: 0 | Q24: ทวีศักดิ์ วิโรจน์ | R24: 0 | S24: 18 | T24: 001 | U24: 001 | W24: 922_5 | X24: N | Y24: N | Z24: N | AA24: FFB | AB24: 0 | AC24: 0 | AD24: 0 | AE24: 46113.61 | AF24: 50 | AG24: 3440 | AH24: 46113.607 | AI24: 49 | AJ24: 6270 | AK24: 2830 | AL24: 0 | AM24: 0 | AN24: 0 | AO24: 0 | AP24: 0 | AQ24: 0 | AR24: 0 | AS24: 0 | AU24: 145 | AV24: 0 | AW24: 0 | BE24: 0 | BF24: 0 | BG24: 0 | BH24: 0 | BI24: 0 | BJ24: 0 | BK24: 0 | BL24: 0 | BM24: 0 | BN24: 0 | BO24: 0 | BP24: 0 | BQ24: 0 | BR24: 0 | BT24: 46113 | BU24: 0 | BV24: 0 | BW24: 0 | BX24: 0 | BZ24: 0 | CA24: 0 | CB24: 0 | CC24: 0 | CD24: 0 | CF24: 0 | CG24: 46113 | CH24: 46113 | CI24: E2093
A25: 2094 | B25: O | C25: N | D25: 46113 | E25: 2 | F25: 99000 | G25: {=_xlfn.XLOOKUP(TRIM(F25), TRIM(Wpct!$A$2:$A$1000), Wpct!$B$2:$B$1000, "ไม่พบชื่อ", 0) & IF(_xlfn.XLOOKUP(TRIM(F25), TRIM(Terrain!$N$2:$N$1002), Terrain!$I$2:$I$1002, "NO", 0)="YES", " (R)", "")} -> บจก.ทักษิณปาล์ม (ฝ่ายสวนปาล์ม) | H25: {=IFERROR(_xlfn.SWITCH(_xlfn.XLOOKUP(TRIM(F25), TRIM(Terrain!$N:$N), Terrain!$I:$I), "YES", "RSPO", "NO", "NON-RSPO", "OB", "Outbound Logistics"), "Contract Farmer")} -> Outbound Logistics | I25: N | K25: {=IFERROR(INDEX(Terrain!$D:$D, MATCH(TEXT(F25,"0"), TEXT(Terrain!$N:$N,"0"), 0)), "-")} -> Outbound | L25: {=IFERROR(INDEX(Terrain!$E:$E, MATCH(TEXT(F25,"0"), TEXT(Terrain!$N:$N,"0"), 0)), "-")} -> Ramp | M25: {=IFERROR(INDEX(Terrain!$C:$C, MATCH(TEXT(F25,"0"), TEXT(Terrain!$N:$N,"0"), 0)), "Contract")} -> EST | N25: 82-8674 | O25: สฎ | P25: 0 | Q25: นายพยุงศักดิ์ สมเพชร | R25: 0 | S25: 18 | T25: 001 | U25: 001 | X25: N | Y25: N | Z25: N | AA25: FFB | AB25: 0 | AC25: 0 | AD25: 0 | AE25: 46113.613 | AF25: 52 | AG25: 13850 | AH25: 46113.631 | AI25: 60 | AJ25: 24970 | AK25: 11120 | AL25: 0 | AM25: 0 | AN25: 0 | AO25: 0 | AP25: 0 | AQ25: 0 | AR25: 0 | AS25: 0 | AU25: 0 | AV25: 0 | AW25: 0 | BE25: 0 | BF25: 0 | BG25: 0 | BH25: 0 | BI25: 0 | BJ25: 0 | BK25: 0 | BL25: 0 | BM25: 0 | BN25: 0 | BO25: 0 | BP25: 0 | BQ25: 0 | BR25: 0 | BS25: 03178 | BT25: 46113 | BU25: 12 | BV25: 13830 | BW25: 24890 | BX25: 11060 | BZ25: 0 | CA25: 0 | CB25: 0 | CC25: 0 | CD25: 0 | CE25: SPC | CF25: 0 | CG25: 46113.683 | CH25: 46113.754 | CI25: E2094
A26: 2095 | B26: I | C26: N | D26: 46113 | E26: 1 | F26: 91003_1 | G26: {=_xlfn.XLOOKUP(TRIM(F26), TRIM(Wpct!$A$2:$A$1000), Wpct!$B$2:$B$1000, "ไม่พบชื่อ", 0) & IF(_xlfn.XLOOKUP(TRIM(F26), TRIM(Terrain!$N$2:$N$1002), Terrain!$I$2:$I$1002, "NO", 0)="YES", " (R)", "")} -> บางกัน 03 | H26: {=IFERROR(_xlfn.SWITCH(_xlfn.XLOOKUP(TRIM(F26), TRIM(Terrain!$N:$N), Terrain!$I:$I), "YES", "RSPO", "NO", "NON-RSPO", "OB", "Outbound Logistics"), "Contract Farmer")} -> NON-RSPO | I26: N | K26: {=IFERROR(INDEX(Terrain!$D:$D, MATCH(TEXT(F26,"0"), TEXT(Terrain!$N:$N,"0"), 0)), "-")} -> Banggun | L26: {=IFERROR(INDEX(Terrain!$E:$E, MATCH(TEXT(F26,"0"), TEXT(Terrain!$N:$N,"0"), 0)), "-")} -> 57-B03 | M26: {=IFERROR(INDEX(Terrain!$C:$C, MATCH(TEXT(F26,"0"), TEXT(Terrain!$N:$N,"0"), 0)), "Contract")} -> Upper | N26: ผธ236 | O26: สฎ | P26: 0 | Q26: ธนาวุฒิ เพชรสังวาลย์ | R26: 0 | S26: 18 | T26: 001 | U26: 001 | W26: 918_1 | X26: N | Y26: N | Z26: N | AA26: FFB | AB26: 0 | AC26: 0 | AD26: 0 | AE26: 46113.628 | AF26: 58 | AG26: 1600 | AH26: 46113.618 | AI26: 53 | AJ26: 3680 | AK26: 2080 | AL26: 0 | AM26: 0 | AN26: 0 | AO26: 0 | AP26: 0 | AQ26: 0 | AR26: 0 | AS26: 0 | AU26: 124 | AV26: 0 | AW26: 0 | BE26: 0 | BF26: 0 | BG26: 0 | BH26: 0 | BI26: 0 | BJ26: 0 | BK26: 0 | BL26: 0 | BM26: 0 | BN26: 0 | BO26: 0 | BP26: 0 | BQ26: 0 | BR26: 0 | BT26: 46113 | BU26: 0 | BV26: 0 | BW26: 0 | BX26: 0 | BZ26: 0 | CA26: 0 | CB26: 0 | CC26: 0 | CD26: 0 | CF26: 0 | CG26: 46113 | CH26: 46113 | CI26: E2095
A27: 2096 | B27: I | C27: N | D27: 46113 | E27: 1 | F27: 91003_1 | G27: {=_xlfn.XLOOKUP(TRIM(F27), TRIM(Wpct!$A$2:$A$1000), Wpct!$B$2:$B$1000, "ไม่พบชื่อ", 0) & IF(_xlfn.XLOOKUP(TRIM(F27), TRIM(Terrain!$N$2:$N$1002), Terrain!$I$2:$I$1002, "NO", 0)="YES", " (R)", "")} -> บางกัน 03 | H27: {=IFERROR(_xlfn.SWITCH(_xlfn.XLOOKUP(TRIM(F27), TRIM(Terrain!$N:$N), Terrain!$I:$I), "YES", "RSPO", "NO", "NON-RSPO", "OB", "Outbound Logistics"), "Contract Farmer")} -> NON-RSPO | I27: N | K27: {=IFERROR(INDEX(Terrain!$D:$D, MATCH(TEXT(F27,"0"), TEXT(Terrain!$N:$N,"0"), 0)), "-")} -> Banggun | L27: {=IFERROR(INDEX(Terrain!$E:$E, MATCH(TEXT(F27,"0"), TEXT(Terrain!$N:$N,"0"), 0)), "-")} -> 57-B03 | M27: {=IFERROR(INDEX(Terrain!$C:$C, MATCH(TEXT(F27,"0"), TEXT(Terrain!$N:$N,"0"), 0)), "Contract")} -> Upper | N27: ผพ229 | O27: สฎ | P27: 0 | R27: 0 | S27: 18 | T27: 001 | U27: 001 | W27: 918_1 | X27: N | Y27: N | Z27: N | AA27: FFB | AB27: 0 | AC27: 0 | AD27: 0 | AE27: 46113.629 | AF27: 59 | AG27: 1530 | AH27: 46113.619 | AI27: 54 | AJ27: 3630 | AK27: 2100 | AL27: 0 | AM27: 0 | AN27: 0 | AO27: 0 | AP27: 0 | AQ27: 0 | AR27: 0 | AS27: 0 | AU27: 127 | AV27: 0 | AW27: 0 | BE27: 0 | BF27: 0 | BG27: 0 | BH27: 0 | BI27: 0 | BJ27: 0 | BK27: 0 | BL27: 0 | BM27: 0 | BN27: 0 | BO27: 0 | BP27: 0 | BQ27: 0 | BR27: 0 | BT27: 46113 | BU27: 0 | BV27: 0 | BW27: 0 | BX27: 0 | BZ27: 0 | CA27: 0 | CB27: 0 | CC27: 0 | CD27: 0 | CF27: 0 | CG27: 46113 | CH27: 46113 | CI27: E2096
A28: 2097 | B28: I | C28: N | D28: 46113 | E28: 1 | F28: 91014 | G28: {=_xlfn.XLOOKUP(TRIM(F28), TRIM(Wpct!$A$2:$A$1000), Wpct!$B$2:$B$1000, "ไม่พบชื่อ", 0) & IF(_xlfn.XLOOKUP(TRIM(F28), TRIM(Terrain!$N$2:$N$1002), Terrain!$I$2:$I$1002, "NO", 0)="YES", " (R)", "")} -> บางกัน 14 | H28: {=IFERROR(_xlfn.SWITCH(_xlfn.XLOOKUP(TRIM(F28), TRIM(Terrain!$N:$N), Terrain!$I:$I), "YES", "RSPO", "NO", "NON-RSPO", "OB", "Outbound Logistics"), "Contract Farmer")} -> NON-RSPO | I28: N | K28: {=IFERROR(INDEX(Terrain!$D:$D, MATCH(TEXT(F28,"0"), TEXT(Terrain!$N:$N,"0"), 0)), "-")} -> Banggun | L28: {=IFERROR(INDEX(Terrain!$E:$E, MATCH(TEXT(F28,"0"), TEXT(Terrain!$N:$N,"0"), 0)), "-")} -> 57-B14 | M28: {=IFERROR(INDEX(Terrain!$C:$C, MATCH(TEXT(F28,"0"), TEXT(Terrain!$N:$N,"0"), 0)), "Contract")} -> Upper | N28: 81-9790 | O28: สฎ | P28: 0 | Q28: รถสำรอง | R28: 0 | S28: 18 | T28: 001 | U28: 001 | W28: 914 | X28: N | Y28: N | Z28: N | AA28: FFB | AB28: 0 | AC28: 0 | AD28: 0 | AE28: 46113.633 | AF28: 61 | AG28: 4150 | AH28: 46113.625 | AI28: 56 | AJ28: 10990 | AK28: 6840 | AL28: 0 | AM28: 0 | AN28: 0 | AO28: 0 | AP28: 0 | AQ28: 0 | AR28: 0 | AS28: 0 | AU28: 430 | AV28: 0 | AW28: 0 | BE28: 0 | BF28: 0 | BG28: 0 | BH28: 0 | BI28: 0 | BJ28: 0 | BK28: 0 | BL28: 0 | BM28: 0 | BN28: 0 | BO28: 0 | BP28: 0 | BQ28: 0 | BR28: 0 | BT28: 46113 | BU28: 0 | BV28: 0 | BW28: 0 | BX28: 0 | BZ28: 0 | CA28: 0 | CB28: 0 | CC28: 0 | CD28: 0 | CF28: 0 | CG28: 46113 | CH28: 46113 | CI28: E2097
A29: 2098 | B29: I | C29: N | D29: 46113 | E29: 1 | F29: 90009 | G29: {=_xlfn.XLOOKUP(TRIM(F29), TRIM(Wpct!$A$2:$A$1000), Wpct!$B$2:$B$1000, "ไม่พบชื่อ", 0) & IF(_xlfn.XLOOKUP(TRIM(F29), TRIM(Terrain!$N$2:$N$1002), Terrain!$I$2:$I$1002, "NO", 0)="YES", " (R)", "")} -> กะเปา 09 (R) | H29: {=IFERROR(_xlfn.SWITCH(_xlfn.XLOOKUP(TRIM(F29), TRIM(Terrain!$N:$N), Terrain!$I:$I), "YES", "RSPO", "NO", "NON-RSPO", "OB", "Outbound Logistics"), "Contract Farmer")} -> RSPO | I29: N | K29: {=IFERROR(INDEX(Terrain!$D:$D, MATCH(TEXT(F29,"0"), TEXT(Terrain!$N:$N,"0"), 0)), "-")} -> Kapao | L29: {=IFERROR(INDEX(Terrain!$E:$E, MATCH(TEXT(F29,"0"), TEXT(Terrain!$N:$N,"0"), 0)), "-")} -> 57-A09-R | M29: {=IFERROR(INDEX(Terrain!$C:$C, MATCH(TEXT(F29,"0"), TEXT(Terrain!$N:$N,"0"), 0)), "Contract")} -> Lower | N29: ผบ3033 | O29: สฎ | P29: 0 | Q29: อุทุมพร วิเชียร | R29: 0 | S29: 18 | T29: 001 | U29: 001 | W29: 902_6 | X29: N | Y29: N | Z29: N | AA29: FFB | AB29: 0 | AC29: 0 | AD29: 0 | AE29: 46113.639 | AF29: 63 | AG29: 1860 | AH29: 46113.627 | AI29: 57 | AJ29: 5190 | AK29: 3330 | AL29: 0 | AM29: 0 | AN29: 0 | AO29: 0 | AP29: 0 | AQ29: 0 | AR29: 0 | AS29: 0 | AU29: 189 | AV29: 0 | AW29: 0 | BE29: 0 | BF29: 0 | BG29: 0 | BH29: 0 | BI29: 0 | BJ29: 0 | BK29: 0 | BL29: 0 | BM29: 0 | BN29: 0 | BO29: 0 | BP29: 0 | BQ29: 0 | BR29: 0 | BT29: 46113 | BU29: 0 | BV29: 0 | BW29: 0 | BX29: 0 | BZ29: 0 | CA29: 0 | CB29: 0 | CC29: 0 | CD29: 0 | CF29: 0 | CG29: 46113 | CH29: 46113 | CI29: E2098
A30: 2099 | B30: O | C30: N | D30: 46113 | E30: 1 | F30: 99000 | G30: {=_xlfn.XLOOKUP(TRIM(F30), TRIM(Wpct!$A$2:$A$1000), Wpct!$B$2:$B$1000, "ไม่พบชื่อ", 0) & IF(_xlfn.XLOOKUP(TRIM(F30), TRIM(Terrain!$N$2:$N$1002), Terrain!$I$2:$I$1002, "NO", 0)="YES", " (R)", "")} -> บจก.ทักษิณปาล์ม (ฝ่ายสวนปาล์ม) | H30: {=IFERROR(_xlfn.SWITCH(_xlfn.XLOOKUP(TRIM(F30), TRIM(Terrain!$N:$N), Terrain!$I:$I), "YES", "RSPO", "NO", "NON-RSPO", "OB", "Outbound Logistics"), "Contract Farmer")} -> Outbound Logistics | I30: N | K30: {=IFERROR(INDEX(Terrain!$D:$D, MATCH(TEXT(F30,"0"), TEXT(Terrain!$N:$N,"0"), 0)), "-")} -> Outbound | L30: {=IFERROR(INDEX(Terrain!$E:$E, MATCH(TEXT(F30,"0"), TEXT(Terrain!$N:$N,"0"), 0)), "-")} -> Ramp | M30: {=IFERROR(INDEX(Terrain!$C:$C, MATCH(TEXT(F30,"0"), TEXT(Terrain!$N:$N,"0"), 0)), "Contract")} -> EST | N30: 82-0103 | O30: สฎ | P30: 0 | Q30: นายพจร เคลื่อนทอง | R30: 0 | S30: 18 | T30: 001 | U30: 001 | X30: N | Y30: N | Z30: N | AA30: FFB | AB30: 0 | AC30: 0 | AD30: 0 | AE30: 46113.635 | AF30: 62 | AG30: 11200 | AH30: 46113.663 | AI30: 64 | AJ30: 24980 | AK30: 13780 | AL30: 0 | AM30: 0 | AN30: 0 | AO30: 0 | AP30: 0 | AQ30: 0 | AR30: 0 | AS30: 0 | AU30: 0 | AV30: 0 | AW30: 0 | BE30: 0 | BF30: 0 | BG30: 0 | BH30: 0 | BI30: 0 | BJ30: 0 | BK30: 0 | BL30: 0 | BM30: 0 | BN30: 0 | BO30: 0 | BP30: 0 | BQ30: 0 | BR30: 0 | BS30: 03183 | BT30: 46113 | BU30: 18 | BV30: 11180 | BW30: 24890 | BX30: 13710 | BZ30: 0 | CA30: 0 | CB30: 0 | CC30: 0 | CD30: 0 | CE30: SPC | CF30: 0 | CG30: 46113.713 | CH30: 46113.758 | CI30: E2099
A31: 2100 | B31: O | C31: N | D31: 46113 | E31: 1 | F31: 99000 | G31: {=_xlfn.XLOOKUP(TRIM(F31), TRIM(Wpct!$A$2:$A$1000), Wpct!$B$2:$B$1000, "ไม่พบชื่อ", 0) & IF(_xlfn.XLOOKUP(TRIM(F31), TRIM(Terrain!$N$2:$N$1002), Terrain!$I$2:$I$1002, "NO", 0)="YES", " (R)", "")} -> บจก.ทักษิณปาล์ม (ฝ่ายสวนปาล์ม) | H31: {=IFERROR(_xlfn.SWITCH(_xlfn.XLOOKUP(TRIM(F31), TRIM(Terrain!$N:$N), Terrain!$I:$I), "YES", "RSPO", "NO", "NON-RSPO", "OB", "Outbound Logistics"), "Contract Farmer")} -> Outbound Logistics | I31: N | K31: {=IFERROR(INDEX(Terrain!$D:$D, MATCH(TEXT(F31,"0"), TEXT(Terrain!$N:$N,"0"), 0)), "-")} -> Outbound | L31: {=IFERROR(INDEX(Terrain!$E:$E, MATCH(TEXT(F31,"0"), TEXT(Terrain!$N:$N,"0"), 0)), "-")} -> Ramp | M31: {=IFERROR(INDEX(Terrain!$C:$C, MATCH(TEXT(F31,"0"), TEXT(Terrain!$N:$N,"0"), 0)), "Contract")} -> EST | N31: 81-1941 | O31: สฎ | P31: 0 | Q31: นายประจักษ์ กิ่งก้าน | R31: 0 | S31: 18 | T31: 001 | U31: 001 | X31: N | Y31: N | Z31: N | AA31: FFB | AB31: 0 | AC31: 0 | AD31: 0 | AE31: 46113.664 | AF31: 65 | AG31: 10960 | AH31: 46113.699 | AI31: 72 | AJ31: 24980 | AK31: 14020 | AL31: 0 | AM31: 0 | AN31: 0 | AO31: 0 | AP31: 0 | AQ31: 0 | AR31: 0 | AS31: 0 | AU31: 0 | AV31: 0 | AW31: 0 | BE31: 0 | BF31: 0 | BG31: 0 | BH31: 0 | BI31: 0 | BJ31: 0 | BK31: 0 | BL31: 0 | BM31: 0 | BN31: 0 | BO31: 0 | BP31: 0 | BQ31: 0 | BR31: 0 | BS31: 03191 | BT31: 46113 | BU31: 18 | BV31: 10930 | BW31: 24890 | BX31: 13960 | BZ31: 0 | CA31: 0 | CB31: 0 | CC31: 0 | CD31: 0 | CE31: SPC | CF31: 0 | CG31: 46113.751 | CH31: 46113.785 | CI31: E2100
A32: 2101 | B32: I | C32: N | D32: 46113 | E32: 1 | F32: 94006_2 | G32: {=_xlfn.XLOOKUP(TRIM(F32), TRIM(Wpct!$A$2:$A$1000), Wpct!$B$2:$B$1000, "ไม่พบชื่อ", 0) & IF(_xlfn.XLOOKUP(TRIM(F32), TRIM(Terrain!$N$2:$N$1002), Terrain!$I$2:$I$1002, "NO", 0)="YES", " (R)", "")} -> ปลายราง 06 (R) | H32: {=IFERROR(_xlfn.SWITCH(_xlfn.XLOOKUP(TRIM(F32), TRIM(Terrain!$N:$N), Terrain!$I:$I), "YES", "RSPO", "NO", "NON-RSPO", "OB", "Outbound Logistics"), "Contract Farmer")} -> RSPO | I32: N | K32: {=IFERROR(INDEX(Terrain!$D:$D, MATCH(TEXT(F32,"0"), TEXT(Terrain!$N:$N,"0"), 0)), "-")} -> Plairang | L32: {=IFERROR(INDEX(Terrain!$E:$E, MATCH(TEXT(F32,"0"), TEXT(Terrain!$N:$N,"0"), 0)), "-")} -> 64-P06-R | M32: {=IFERROR(INDEX(Terrain!$C:$C, MATCH(TEXT(F32,"0"), TEXT(Terrain!$N:$N,"0"), 0)), "Contract")} -> Lower | N32: ผท9991 | O32: สฎ | P32: 0 | R32: 0 | S32: 18 | T32: 001 | U32: 001 | W32: 942_3 | X32: N | Y32: N | Z32: N | AA32: FFB | AB32: 0 | AC32: 0 | AD32: 0 | AE32: 46113.674 | AF32: 67 | AG32: 2120 | AH32: 46113.668 | AI32: 66 | AJ32: 3970 | AK32: 1850 | AL32: 0 | AM32: 0 | AN32: 0 | AO32: 0 | AP32: 0 | AQ32: 0 | AR32: 0 | AS32: 0 | AU32: 331 | AV32: 0 | AW32: 0 | BE32: 0 | BF32: 0 | BG32: 0 | BH32: 0 | BI32: 0 | BJ32: 0 | BK32: 0 | BL32: 0 | BM32: 0 | BN32: 0 | BO32: 0 | BP32: 0 | BQ32: 0 | BR32: 0 | BT32: 46113 | BU32: 0 | BV32: 0 | BW32: 0 | BX32: 0 | BZ32: 0 | CA32: 0 | CB32: 0 | CC32: 0 | CD32: 0 | CF32: 0 | CG32: 46113 | CH32: 46113 | CI32: E2101
A33: 2102 | B33: I | C33: N | D33: 46113 | E33: 1 | F33: 91013 | G33: {=_xlfn.XLOOKUP(TRIM(F33), TRIM(Wpct!$A$2:$A$1000), Wpct!$B$2:$B$1000, "ไม่พบชื่อ", 0) & IF(_xlfn.XLOOKUP(TRIM(F33), TRIM(Terrain!$N$2:$N$1002), Terrain!$I$2:$I$1002, "NO", 0)="YES", " (R)", "")} -> บางกัน 13 | H33: {=IFERROR(_xlfn.SWITCH(_xlfn.XLOOKUP(TRIM(F33), TRIM(Terrain!$N:$N), Terrain!$I:$I), "YES", "RSPO", "NO", "NON-RSPO", "OB", "Outbound Logistics"), "Contract Farmer")} -> NON-RSPO | I33: N | K33: {=IFERROR(INDEX(Terrain!$D:$D, MATCH(TEXT(F33,"0"), TEXT(Terrain!$N:$N,"0"), 0)), "-")} -> Banggun | L33: {=IFERROR(INDEX(Terrain!$E:$E, MATCH(TEXT(F33,"0"), TEXT(Terrain!$N:$N,"0"), 0)), "-")} -> 49-B13 | M33: {=IFERROR(INDEX(Terrain!$C:$C, MATCH(TEXT(F33,"0"), TEXT(Terrain!$N:$N,"0"), 0)), "Contract")} -> Upper | N33: 82-5318 | O33: สฎ | P33: 0 | Q33: นายพรชัย ช่วยจำ | R33: 0 | S33: 18 | T33: 001 | U33: 001 | W33: 919 | X33: N | Y33: N | Z33: N | AA33: FFB | AB33: 0 | AC33: 0 | AD33: 0 | AE33: 46113.681 | AF33: 69 | AG33: 5070 | AH33: 46113.678 | AI33: 68 | AJ33: 12650 | AK33: 7580 | AL33: 0 | AM33: 0 | AN33: 0 | AO33: 0 | AP33: 0 | AQ33: 0 | AR33: 0 | AS33: 0 | AU33: 285 | AV33: 0 | AW33: 0 | BE33: 0 | BF33: 0 | BG33: 0 | BH33: 0 | BI33: 0 | BJ33: 0 | BK33: 0 | BL33: 0 | BM33: 0 | BN33: 0 | BO33: 0 | BP33: 0 | BQ33: 0 | BR33: 0 | BT33: 46113 | BU33: 0 | BV33: 0 | BW33: 0 | BX33: 0 | BZ33: 0 | CA33: 0 | CB33: 0 | CC33: 0 | CD33: 0 | CF33: 0 | CG33: 46113 | CH33: 46113 | CI33: E2102
A34: 2103 | B34: I | C34: N | D34: 46113 | E34: 1 | F34: 91014 | G34: {=_xlfn.XLOOKUP(TRIM(F34), TRIM(Wpct!$A$2:$A$1000), Wpct!$B$2:$B$1000, "ไม่พบชื่อ", 0) & IF(_xlfn.XLOOKUP(TRIM(F34), TRIM(Terrain!$N$2:$N$1002), Terrain!$I$2:$I$1002, "NO", 0)="YES", " (R)", "")} -> บางกัน 14 | H34: {=IFERROR(_xlfn.SWITCH(_xlfn.XLOOKUP(TRIM(F34), TRIM(Terrain!$N:$N), Terrain!$I:$I), "YES", "RSPO", "NO", "NON-RSPO", "OB", "Outbound Logistics"), "Contract Farmer")} -> NON-RSPO | I34: N | K34: {=IFERROR(INDEX(Terrain!$D:$D, MATCH(TEXT(F34,"0"), TEXT(Terrain!$N:$N,"0"), 0)), "-")} -> Banggun | L34: {=IFERROR(INDEX(Terrain!$E:$E, MATCH(TEXT(F34,"0"), TEXT(Terrain!$N:$N,"0"), 0)), "-")} -> 57-B14 | M34: {=IFERROR(INDEX(Terrain!$C:$C, MATCH(TEXT(F34,"0"), TEXT(Terrain!$N:$N,"0"), 0)), "Contract")} -> Upper | N34: 81-9790 | O34: สฎ | P34: 0 | Q34: รถสำรอง | R34: 0 | S34: 18 | T34: 001 | U34: 001 | W34: 914 | X34: N | Y34: N | Z34: N | AA34: FFB | AB34: 0 | AC34: 0 | AD34: 0 | AE34: 46113.684 | AF34: 71 | AG34: 4160 | AH34: 46113.682 | AI34: 70 | AJ34: 8690 | AK34: 4530 | AL34: 0 | AM34: 0 | AN34: 0 | AO34: 0 | AP34: 0 | AQ34: 0 | AR34: 0 | AS34: 0 | AU34: 364 | AV34: 0 | AW34: 0 | BE34: 0 | BF34: 0 | BG34: 0 | BH34: 0 | BI34: 0 | BJ34: 0 | BK34: 0 | BL34: 0 | BM34: 0 | BN34: 0 | BO34: 0 | BP34: 0 | BQ34: 0 | BR34: 0 | BT34: 46113 | BU34: 0 | BV34: 0 | BW34: 0 | BX34: 0 | BZ34: 0 | CA34: 0 | CB34: 0 | CC34: 0 | CD34: 0 | CF34: 0 | CG34: 46113 | CH34: 46113 | CI34: E2103
A35: 2104 | B35: I | C35: N | D35: 46113 | E35: 1 | F35: 22455 | G35: {=_xlfn.XLOOKUP(TRIM(F35), TRIM(Wpct!$A$2:$A$1000), Wpct!$B$2:$B$1000, "ไม่พบชื่อ", 0) & IF(_xlfn.XLOOKUP(TRIM(F35), TRIM(Terrain!$N$2:$N$1002), Terrain!$I$2:$I$1002, "NO", 0)="YES", " (R)", "")} -> บริษัท สวนนายห้าง จำกัด | H35: {=IFERROR(_xlfn.SWITCH(_xlfn.XLOOKUP(TRIM(F35), TRIM(Terrain!$N:$N), Terrain!$I:$I), "YES", "RSPO", "NO", "NON-RSPO", "OB", "Outbound Logistics"), "Contract Farmer")} -> Contract Farmer | I35: N | K35: {=IFERROR(INDEX(Terrain!$D:$D, MATCH(TEXT(F35,"0"), TEXT(Terrain!$N:$N,"0"), 0)), "-")} -> - | L35: {=IFERROR(INDEX(Terrain!$E:$E, MATCH(TEXT(F35,"0"), TEXT(Terrain!$N:$N,"0"), 0)), "-")} -> - | M35: {=IFERROR(INDEX(Terrain!$C:$C, MATCH(TEXT(F35,"0"), TEXT(Terrain!$N:$N,"0"), 0)), "Contract")} -> Contract | N35: ผต1807 | O35: สฎ | P35: 0 | Q35: ชัชพิสิฐ มวนนามอญ | R35: 0 | S35: 18 | T35: 001 | U35: 001 | X35: N | Y35: N | Z35: N | AA35: FFB | AB35: 8.3 | AC35: 0 | AD35: 0 | AE35: 46113.708 | AF35: 78 | AG35: 2200 | AH35: 46113.7 | AI35: 73 | AJ35: 5800 | AK35: 3600 | AL35: 0 | AM35: 0 | AN35: 0 | AO35: 0 | AP35: 0 | AQ35: 0 | AR35: 0 | AS35: 0 | AU35: 0 | AV35: 0 | AW35: 1 | BE35: 0 | BF35: 0 | BG35: 0 | BH35: 0 | BI35: 0 | BJ35: 0 | BK35: 0 | BL35: 0 | BM35: 0 | BN35: 0 | BO35: 0 | BP35: 0 | BQ35: 0 | BR35: 0 | BT35: 46113 | BU35: 0 | BV35: 0 | BW35: 0 | BX35: 0 | BZ35: 0 | CA35: 0 | CB35: 0 | CC35: 0 | CD35: 0 | CF35: 0 | CG35: 46113 | CH35: 46113 | CI35: E2104
A36: 2105 | B36: I | C36: N | D36: 46113 | E36: 1 | F36: 90011 | G36: {=_xlfn.XLOOKUP(TRIM(F36), TRIM(Wpct!$A$2:$A$1000), Wpct!$B$2:$B$1000, "ไม่พบชื่อ", 0) & IF(_xlfn.XLOOKUP(TRIM(F36), TRIM(Terrain!$N$2:$N$1002), Terrain!$I$2:$I$1002, "NO", 0)="YES", " (R)", "")} -> กะเปา 11 (R) | H36: {=IFERROR(_xlfn.SWITCH(_xlfn.XLOOKUP(TRIM(F36), TRIM(Terrain!$N:$N), Terrain!$I:$I), "YES", "RSPO", "NO", "NON-RSPO", "OB", "Outbound Logistics"), "Contract Farmer")} -> RSPO | I36: N | K36: {=IFERROR(INDEX(Terrain!$D:$D, MATCH(TEXT(F36,"0"), TEXT(Terrain!$N:$N,"0"), 0)), "-")} -> Kapao | L36: {=IFERROR(INDEX(Terrain!$E:$E, MATCH(TEXT(F36,"0"), TEXT(Terrain!$N:$N,"0"), 0)), "-")} -> 49-A11-R | M36: {=IFERROR(INDEX(Terrain!$C:$C, MATCH(TEXT(F36,"0"), TEXT(Terrain!$N:$N,"0"), 0)), "Contract")} -> Lower | N36: 83-5638 | O36: สฎ | P36: 0 | Q36: นฤพน สินธู | R36: 0 | S36: 18 | T36: 001 | U36: 001 | W36: 901_9 | X36: N | Y36: N | Z36: N | AA36: FFB | AB36: 0 | AC36: 0 | AD36: 0 | AE36: 46113.704 | AF36: 75 | AG36: 5540 | AH36: 46113.701 | AI36: 74 | AJ36: 11420 | AK36: 5880 | AL36: 0 | AM36: 0 | AN36: 0 | AO36: 0 | AP36: 0 | AQ36: 0 | AR36: 0 | AS36: 0 | AU36: 299 | AV36: 0 | AW36: 0 | BE36: 0 | BF36: 0 | BG36: 0 | BH36: 0 | BI36: 0 | BJ36: 0 | BK36: 0 | BL36: 0 | BM36: 0 | BN36: 0 | BO36: 0 | BP36: 0 | BQ36: 0 | BR36: 0 | BT36: 46113 | BU36: 0 | BV36: 0 | BW36: 0 | BX36: 0 | BZ36: 0 | CA36: 0 | CB36: 0 | CC36: 0 | CD36: 0 | CF36: 0 | CG36: 46113 | CH36: 46113 | CI36: E2105
A37: 2106 | B37: O | C37: N | D37: 46113 | E37: 1 | F37: 99000 | G37: {=_xlfn.XLOOKUP(TRIM(F37), TRIM(Wpct!$A$2:$A$1000), Wpct!$B$2:$B$1000, "ไม่พบชื่อ", 0) & IF(_xlfn.XLOOKUP(TRIM(F37), TRIM(Terrain!$N$2:$N$1002), Terrain!$I$2:$I$1002, "NO", 0)="YES", " (R)", "")} -> บจก.ทักษิณปาล์ม (ฝ่ายสวนปาล์ม) | H37: {=IFERROR(_xlfn.SWITCH(_xlfn.XLOOKUP(TRIM(F37), TRIM(Terrain!$N:$N), Terrain!$I:$I), "YES", "RSPO", "NO", "NON-RSPO", "OB", "Outbound Logistics"), "Contract Farmer")} -> Outbound Logistics | I37: N | K37: {=IFERROR(INDEX(Terrain!$D:$D, MATCH(TEXT(F37,"0"), TEXT(Terrain!$N:$N,"0"), 0)), "-")} -> Outbound | L37: {=IFERROR(INDEX(Terrain!$E:$E, MATCH(TEXT(F37,"0"), TEXT(Terrain!$N:$N,"0"), 0)), "-")} -> Ramp | M37: {=IFERROR(INDEX(Terrain!$C:$C, MATCH(TEXT(F37,"0"), TEXT(Terrain!$N:$N,"0"), 0)), "Contract")} -> EST | N37: 81-5257 | O37: สฎ | P37: 0 | Q37: นายพจร เคลื่อนทอง | R37: 0 | S37: 18 | T37: 001 | U37: 001 | X37: N | Y37: N | Z37: N | AA37: FFB | AB37: 0 | AC37: 0 | AD37: 0 | AE37: 46113.705 | AF37: 76 | AG37: 10720 | AH37: 46113.722 | AI37: 81 | AJ37: 24880 | AK37: 14160 | AL37: 0 | AM37: 0 | AN37: 0 | AO37: 0 | AP37: 0 | AQ37: 0 | AR37: 0 | AS37: 0 | AU37: 0 | AV37: 0 | AW37: 0 | BE37: 0 | BF37: 0 | BG37: 0 | BH37: 0 | BI37: 0 | BJ37: 0 | BK37: 0 | BL37: 0 | BM37: 0 | BN37: 0 | BO37: 0 | BP37: 0 | BQ37: 0 | BR37: 0 | BS37: 03192 | BT37: 46113 | BU37: 18 | BV37: 10700 | BW37: 24810 | BX37: 14110 | BZ37: 0 | CA37: 0 | CB37: 0 | CC37: 0 | CD37: 0 | CE37: SPC | CF37: 0 | CG37: 46113.767 | CH37: 46113.796 | CI37: E2106
A38: 2107 | B38: I | C38: N | D38: 46113 | E38: 1 | F38: 91013 | G38: {=_xlfn.XLOOKUP(TRIM(F38), TRIM(Wpct!$A$2:$A$1000), Wpct!$B$2:$B$1000, "ไม่พบชื่อ", 0) & IF(_xlfn.XLOOKUP(TRIM(F38), TRIM(Terrain!$N$2:$N$1002), Terrain!$I$2:$I$1002, "NO", 0)="YES", " (R)", "")} -> บางกัน 13 | H38: {=IFERROR(_xlfn.SWITCH(_xlfn.XLOOKUP(TRIM(F38), TRIM(Terrain!$N:$N), Terrain!$I:$I), "YES", "RSPO", "NO", "NON-RSPO", "OB", "Outbound Logistics"), "Contract Farmer")} -> NON-RSPO | I38: N | K38: {=IFERROR(INDEX(Terrain!$D:$D, MATCH(TEXT(F38,"0"), TEXT(Terrain!$N:$N,"0"), 0)), "-")} -> Banggun | L38: {=IFERROR(INDEX(Terrain!$E:$E, MATCH(TEXT(F38,"0"), TEXT(Terrain!$N:$N,"0"), 0)), "-")} -> 49-B13 | M38: {=IFERROR(INDEX(Terrain!$C:$C, MATCH(TEXT(F38,"0"), TEXT(Terrain!$N:$N,"0"), 0)), "Contract")} -> Upper | N38: 82-2952 | O38: สฎ | P38: 0 | Q38: ธวัชชัย ชูจอน | R38: 0 | S38: 18 | T38: 001 | U38: 001 | W38: 919 | X38: N | Y38: N | Z38: N | AA38: FFB | AB38: 0 | AC38: 0 | AD38: 0 | AE38: 46113.714 | AF38: 79 | AG38: 7360 | AH38: 46113.707 | AI38: 77 | AJ38: 13870 | AK38: 6510 | AL38: 0 | AM38: 0 | AN38: 0 | AO38: 0 | AP38: 0 | AQ38: 0 | AR38: 0 | AS38: 0 | AU38: 257 | AV38: 3 | AW38: 4 | BE38: 0 | BF38: 0 | BG38: 0 | BH38: 0 | BI38: 0 | BJ38: 0 | BK38: 0 | BL38: 0 | BM38: 0 | BN38: 0 | BO38: 0 | BP38: 0 | BQ38: 0 | BR38: 0 | BT38: 46113 | BU38: 0 | BV38: 0 | BW38: 0 | BX38: 0 | BZ38: 0 | CA38: 0 | CB38: 0 | CC38: 0 | CD38: 0 | CF38: 0 | CG38: 46113 | CH38: 46113 | CI38: E2107
A39: 2108 | B39: I | C39: N | D39: 46113 | E39: 1 | F39: 90009 | G39: {=_xlfn.XLOOKUP(TRIM(F39), TRIM(Wpct!$A$2:$A$1000), Wpct!$B$2:$B$1000, "ไม่พบชื่อ", 0) & IF(_xlfn.XLOOKUP(TRIM(F39), TRIM(Terrain!$N$2:$N$1002), Terrain!$I$2:$I$1002, "NO", 0)="YES", " (R)", "")} -> กะเปา 09 (R) | H39: {=IFERROR(_xlfn.SWITCH(_xlfn.XLOOKUP(TRIM(F39), TRIM(Terrain!$N:$N), Terrain!$I:$I), "YES", "RSPO", "NO", "NON-RSPO", "OB", "Outbound Logistics"), "Contract Farmer")} -> RSPO | I39: N | K39: {=IFERROR(INDEX(Terrain!$D:$D, MATCH(TEXT(F39,"0"), TEXT(Terrain!$N:$N,"0"), 0)), "-")} -> Kapao | L39: {=IFERROR(INDEX(Terrain!$E:$E, MATCH(TEXT(F39,"0"), TEXT(Terrain!$N:$N,"0"), 0)), "-")} -> 57-A09-R | M39: {=IFERROR(INDEX(Terrain!$C:$C, MATCH(TEXT(F39,"0"), TEXT(Terrain!$N:$N,"0"), 0)), "Contract")} -> Lower | N39: บร3677 | O39: สฎ | P39: 0 | R39: 0 | S39: 18 | T39: 001 | U39: 001 | W39: 902_6 | X39: N | Y39: N | Z39: N | AA39: FFB | AB39: 0 | AC39: 0 | AD39: 0 | AE39: 46113.724 | AF39: 82 | AG39: 1480 | AH39: 46113.717 | AI39: 80 | AJ39: 2990 | AK39: 1510 | AL39: 0 | AM39: 0 | AN39: 0 | AO39: 0 | AP39: 0 | AQ39: 0 | AR39: 0 | AS39: 0 | AU39: 103 | AV39: 0 | AW39: 0 | BE39: 0 | BF39: 0 | BG39: 0 | BH39: 0 | BI39: 0 | BJ39: 0 | BK39: 0 | BL39: 0 | BM39: 0 | BN39: 0 | BO39: 0 | BP39: 0 | BQ39: 0 | BR39: 0 | BT39: 46113 | BU39: 0 | BV39: 0 | BW39: 0 | BX39: 0 | BZ39: 0 | CA39: 0 | CB39: 0 | CC39: 0 | CD39: 0 | CF39: 0 | CG39: 46113 | CH39: 46113 | CI39: E2108
A40: 2109 | B40: I | C40: N | D40: 46113 | E40: 1 | F40: 90009 | G40: {=_xlfn.XLOOKUP(TRIM(F40), TRIM(Wpct!$A$2:$A$1000), Wpct!$B$2:$B$1000, "ไม่พบชื่อ", 0) & IF(_xlfn.XLOOKUP(TRIM(F40), TRIM(Terrain!$N$2:$N$1002), Terrain!$I$2:$I$1002, "NO", 0)="YES", " (R)", "")} -> กะเปา 09 (R) | H40: {=IFERROR(_xlfn.SWITCH(_xlfn.XLOOKUP(TRIM(F40), TRIM(Terrain!$N:$N), Terrain!$I:$I), "YES", "RSPO", "NO", "NON-RSPO", "OB", "Outbound Logistics"), "Contract Farmer")} -> RSPO | I40: N | K40: {=IFERROR(INDEX(Terrain!$D:$D, MATCH(TEXT(F40,"0"), TEXT(Terrain!$N:$N,"0"), 0)), "-")} -> Kapao | L40: {=IFERROR(INDEX(Terrain!$E:$E, MATCH(TEXT(F40,"0"), TEXT(Terrain!$N:$N,"0"), 0)), "-")} -> 57-A09-R | M40: {=IFERROR(INDEX(Terrain!$C:$C, MATCH(TEXT(F40,"0"), TEXT(Terrain!$N:$N,"0"), 0)), "Contract")} -> Lower | N40: ผบ3033 | O40: สฎ | P40: 0 | Q40: อุทุมพร วิเชียร | R40: 0 | S40: 18 | T40: 001 | U40: 001 | W40: 902_6 | X40: N | Y40: N | Z40: N | AA40: FFB | AB40: 0 | AC40: 0 | AD40: 0 | AE40: 46113.775 | AF40: 84 | AG40: 1890 | AH40: 46113.759 | AI40: 83 | AJ40: 4530 | AK40: 2640 | AL40: 0 | AM40: 0 | AN40: 0 | AO40: 0 | AP40: 0 | AQ40: 0 | AR40: 0 | AS40: 0 | AU40: 154 | AV40: 0 | AW40: 0 | BE40: 0 | BF40: 0 | BG40: 0 | BH40: 0 | BI40: 0 | BJ40: 0 | BK40: 0 | BL40: 0 | BM40: 0 | BN40: 0 | BO40: 0 | BP40: 0 | BQ40: 0 | BR40: 0 | BT40: 46113 | BU40: 0 | BV40: 0 | BW40: 0 | BX40: 0 | BZ40: 0 | CA40: 0 | CB40: 0 | CC40: 0 | CD40: 0 | CF40: 0 | CG40: 46113 | CH40: 46113 | CI40: E2109
...

Sheet Data
