Workbook

Sheet แรมป์สวน
A1: บริษัท ทักษิณปาล์ม (2521) จำกัด
A2: รายงานสต๊อคผลปาล์มสด เดือน มีนาคม 2569
A3: เครื่องชั่งแรมป์ปลายราง
A5: วันที่ | B5: น้ำหนัก ยกมา | C5: เทปลายราง | I5: น้ำหนักชั่งผ่าน | L5: รวมน้ำหนัก ลงแรมป์ | M5: ช่วงเวลา | O5: รวมน้ำหนักทั้งหมด | P5: น้ำหนักส่งออก | T5: รวมน้ำหนักส่งออก | U5: น้ำหนักคงเหลือ | V5: เคลียร์ แรมป์ | W5: น้ำหนัก โรงงาน | X5: น้ำหนักสูญหาย | AA5: จำนวน คัน | AB5: น้ำหนักคัดคืน
C6: ลูกค้า | D6: ตอนล่าง | E6: บางกัน | F6: ตะกุก | G6: ลูกค้า | H6: ปลายราง | I6: บางกัน | J6: กะเปา | K6: ตะกุก | M6: 8.00-17.00 | N6: 17.00-19.00 | P6: ปลายราง | Q6: บางกัน | R6: กะเปา | S6: ตะกุก | X6: แรมป์ | Y6: ขนส่ง | Z6: รวม
A7: 1 | B7: 25330 | C7: 11640 | D7: 0 | E7: 6990 | F7: 0 | G7: =+C7 -> 11640 | H7: =+D7+E7+F7 -> 6990 | I7: 0 | J7: 0 | K7: 0 | L7: =SUM(G7:K7) -> 18630 | M7: 18630 | N7: 0 | O7: =+B7+L7 -> 43960 | P7: =+T7-Q7-R7-S7 -> 44030 | Q7: 0 | R7: 0 | S7: 0 | T7: 44030 | U7: =+O7-T7 -> -70 | V7: 0 | W7: 43970 | X7: =IF(V7="-",0,V7-U7) -> 70 | Y7: =+W7-T7 -> -60 | Z7: =+X7+Y7 -> 10 | AA7: 2 | AC7: =Y7*100/T7 -> -0.13627072
A8: =+A7+1 -> 2 | B8: =IF(V7="-",U7,V7) -> 0 | C8: 32370 | D8: 47070 | E8: 14670 | F8: 0 | G8: =+C8 -> 32370 | H8: =+D8+E8+F8 -> 61740 | I8: 0 | J8: 0 | K8: 0 | L8: =SUM(G8:K8) -> 94110 | M8: 92830 | N8: 1280 | O8: =+B8+L8 -> 94110 | P8: =+T8-Q8-R8-S8 -> 93660 | Q8: 0 | R8: 0 | S8: 0 | T8: 93660 | U8: =+O8-T8 -> 450 | V8: 0 | W8: 93310 | X8: =IF(V8="-",0,V8-U8) -> -450 | Y8: =+W8-T8 -> -350 | Z8: =+X8+Y8 -> -800 | AA8: 4 | AC8: =Y8*100/T8 -> -0.37369208
A9: =+A8+1 -> 3 | B9: =IF(V8="-",U8,V8) -> 0 | C9: 0 | D9: 0 | E9: 0 | F9: 0 | G9: =+C9 -> 0 | H9: =+D9+E9+F9 -> 0 | I9: 0 | J9: 0 | K9: 0 | L9: =SUM(G9:K9) -> 0 | M9: 0 | N9: 0 | O9: =+B9+L9 -> 0 | P9: =+T9-Q9-R9-S9 -> 0 | Q9: 0 | R9: 0 | S9: 0 | T9: 0 | U9: =+O9-T9 -> 0 | V9: 0 | W9: 0 | X9: =IF(V9="-",0,V9-U9) -> 0 | Y9: =+W9-T9 -> 0 | Z9: =+X9+Y9 -> 0 | AA9: 0 | AC9: =Y9*100/T9 -> #DIV/0!
A10: =+A9+1 -> 4 | B10: =IF(V9="-",U9,V9) -> 0 | C10: 37830 | D10: 56230 | E10: 38910 | F10: 0 | G10: =+C10 -> 37830 | H10: =+D10+E10+F10 -> 95140 | I10: 0 | J10: 0 | K10: 0 | L10: =SUM(G10:K10) -> 132970 | M10: 111870 | N10: 21100 | O10: =+B10+L10 -> 132970 | P10: =+T10-Q10-R10-S10 -> 112800 | Q10: 0 | R10: 0 | S10: 0 | T10: 112800 | U10: =+O10-T10 -> 20170 | V10: 19320 | W10: 112450 | X10: =IF(V10="-",0,V10-U10) -> -850 | Y10: =+W10-T10 -> -350 | Z10: =+X10+Y10 -> -1200 | AA10: 4 | AC10: =Y10*100/T10 -> -0.31028369
A11: =+A10+1 -> 5 | B11: =IF(V10="-",U10,V10) -> 19320 | C11: 29930 | D11: 34210 | E11: 35090 | F11: 0 | G11: =+C11 -> 29930 | H11: =+D11+E11+F11 -> 69300 | I11: 0 | J11: 0 | K11: 0 | L11: =SUM(G11:K11) -> 99230 | M11: 88600 | N11: 10630 | O11: =+B11+L11 -> 118550 | P11: =+T11-Q11-R11-S11 -> 84680 | Q11: 0 | R11: 0 | S11: 0 | T11: 84680 | U11: =+O11-T11 -> 33870 | V11: 33020 | W11: 84410 | X11: =IF(V11="-",0,V11-U11) -> -850 | Y11: =+W11-T11 -> -270 | Z11: =+X11+Y11 -> -1120 | AA11: 3 | AC11: =Y11*100/T11 -> -0.31884743
A12: =+A11+1 -> 6 | B12: =IF(V11="-",U11,V11) -> 33020 | C12: 29170 | D12: 45580 | E12: 22460 | F12: 0 | G12: =+C12 -> 29170 | H12: =+D12+E12+F12 -> 68040 | I12: 0 | J12: 0 | K12: 0 | L12: =SUM(G12:K12) -> 97210 | M12: 87080 | N12: 10130 | O12: =+B12+L12 -> 130230 | P12: =+T12-Q12-R12-S12 -> 129910 | Q12: 0 | R12: 0 | S12: 0 | T12: 129910 | U12: =+O12-T12 -> 320 | V12: 0 | W12: 129650 | X12: =IF(V12="-",0,V12-U12) -> -320 | Y12: =+W12-T12 -> -260 | Z12: =+X12+Y12 -> -580 | AA12: 5 | AC12: =Y12*100/T12 -> -0.20013856
A13: =+A12+1 -> 7 | B13: =IF(V12="-",U12,V12) -> 0 | C13: 33230 | D13: 49060 | E13: 16600 | F13: 0 | G13: =+C13 -> 33230 | H13: =+D13+E13+F13 -> 65660 | I13: 0 | J13: 0 | K13: 0 | L13: =SUM(G13:K13) -> 98890 | M13: 91770 | N13: 7120 | O13: =+B13+L13 -> 98890 | P13: =+T13-Q13-R13-S13 -> 77250 | Q13: 0 | R13: 0 | S13: 0 | T13: 77250 | U13: =+O13-T13 -> 21640 | V13: 21190 | W13: 77080 | X13: =IF(V13="-",0,V13-U13) -> -450 | Y13: =+W13-T13 -> -170 | Z13: =+X13+Y13 -> -620 | AA13: 3 | AC13: =Y13*100/T13 -> -0.22006472
A14: =+A13+1 -> 8 | B14: =IF(V13="-",U13,V13) -> 21190 | C14: 0 | D14: 0 | E14: 0 | F14: 0 | G14: =+C14 -> 0 | H14: =+D14+E14+F14 -> 0 | I14: 0 | J14: 0 | K14: 0 | L14: =SUM(G14:K14) -> 0 | M14: 0 | N14: 0 | O14: =+B14+L14 -> 21190 | P14: =+T14-Q14-R14-S14 -> 21190 | Q14: 0 | R14: 0 | S14: 0 | T14: 21190 | U14: =+O14-T14 -> 0 | V14: 0 | W14: 21130 | X14: =IF(V14="-",0,V14-U14) -> 0 | Y14: =+W14-T14 -> -60 | Z14: =+X14+Y14 -> -60 | AA14: 1 | AC14: =Y14*100/T14 -> -0.28315243
A15: =+A14+1 -> 9 | B15: =IF(V14="-",U14,V14) -> 0 | C15: 20710 | D15: 48700 | E15: 15430 | F15: 0 | G15: =+C15 -> 20710 | H15: =+D15+E15+F15 -> 64130 | I15: 0 | J15: 0 | K15: 0 | L15: =SUM(G15:K15) -> 84840 | M15: 84840 | N15: 0 | O15: =+B15+L15 -> 84840 | P15: 55060 | Q15: 0 | R15: 0 | S15: 0 | T15: 55060 | U15: =+O15-T15 -> 29780 | V15: 28840 | W15: 54910 | X15: =IF(V15="-",0,V15-U15) -> -940 | Y15: =+W15-T15 -> -150 | Z15: =+X15+Y15 -> -1090 | AA15: 3 | AC15: =Y15*100/T15 -> -0.27243008
A16: =+A15+1 -> 10 | B16: =IF(V15="-",U15,V15) -> 28840 | C16: 27140 | D16: 47690 | E16: 14250 | F16: 0 | G16: =+C16 -> 27140 | H16: =+D16+E16+F16 -> 61940 | I16: 0 | J16: 0 | K16: 0 | L16: =SUM(G16:K16) -> 89080 | M16: 83810 | N16: 5270 | O16: =+B16+L16 -> 117920 | P16: 77460 | Q16: 0 | R16: 0 | S16: 0 | T16: 77460 | U16: =+O16-T16 -> 40460 | V16: 39970 | W16: 77380 | X16: =IF(V16="-",0,V16-U16) -> -490 | Y16: =+W16-T16 -> -80 | Z16: =+X16+Y16 -> -570 | AA16: 3 | AC16: =Y16*100/T16 -> -0.10327911
A17: =+A16+1 -> 11 | B17: =IF(V16="-",U16,V16) -> 39970 | C17: 37540 | D17: 45590 | E17: 17890 | F17: 0 | G17: =+C17 -> 37540 | H17: =+D17+E17+F17 -> 63480 | I17: 0 | J17: 0 | K17: 0 | L17: =SUM(G17:K17) -> 101020 | M17: 92390 | N17: 8630 | O17: =+B17+L17 -> 140990 | P17: =+T17-Q17-R17-S17 -> 110600 | Q17: 0 | R17: 0 | S17: 0 | T17: 110600 | U17: =+O17-T17 -> 30390 | V17: 29800 | W17: 110380 | X17: =IF(V17="-",0,V17-U17) -> -590 | Y17: =+W17-T17 -> -220 | Z17: =+X17+Y17 -> -810 | AA17: 6 | AC17: =Y17*100/T17 -> -0.19891501
A18: =+A17+1 -> 12 | B18: =IF(V17="-",U17,V17) -> 29800 | C18: 32580 | D18: 43430 | E18: 20620 | F18: 0 | G18: =+C18 -> 32580 | H18: =+D18+E18+F18 -> 64050 | I18: 0 | J18: 0 | K18: 0 | L18: =SUM(G18:K18) -> 96630 | M18: 85410 | N18: 11220 | O18: =+B18+L18 -> 126430 | P18: =+T18-Q18-R18-S18 -> 122140 | Q18: 0 | R18: 0 | S18: 0 | T18: 122140 | U18: =+O18-T18 -> 4290 | V18: 3750 | W18: 121800 | X18: =IF(V18="-",0,V18-U18) -> -540 | Y18: =+W18-T18 -> -340 | Z18: =+X18+Y18 -> -880 | AA18: 7 | AC18: =Y18*100/T18 -> -0.27836908
A19: =+A18+1 -> 13 | B19: =IF(V18="-",U18,V18) -> 3750 | C19: 23530 | D19: 56040 | E19: 13360 | F19: 0 | G19: =+C19 -> 23530 | H19: =+D19+E19+F19 -> 69400 | I19: 0 | J19: 0 | K19: 0 | L19: =SUM(G19:K19) -> 92930 | M19: 81310 | N19: 11620 | O19: =+B19+L19 -> 96680 | P19: =+T19-Q19-R19-S19 -> 83380 | Q19: 0 | R19: 0 | S19: 0 | T19: 83380 | U19: =+O19-T19 -> 13300 | V19: 13030 | W19: 83170 | X19: =IF(V19="-",0,V19-U19) -> -270 | Y19: =+W19-T19 -> -210 | Z19: =+X19+Y19 -> -480 | AA19: 4 | AC19: =Y19*100/T19 -> -0.25185896
A20: =+A19+1 -> 14 | B20: =IF(V19="-",U19,V19) -> 13030 | C20: 24570 | D20: 60690 | E20: 15160 | F20: 0 | G20: =+C20 -> 24570 | H20: =+D20+E20+F20 -> 75850 | I20: 0 | J20: 0 | K20: 0 | L20: =SUM(G20:K20) -> 100420 | M20: 87880 | N20: 12540 | O20: =+B20+L20 -> 113450 | P20: =+T20-Q20-R20-S20 -> 97770 | Q20: 0 | R20: 0 | S20: 0 | T20: 97770 | U20: =+O20-T20 -> 15680 | V20: - | W20: 97500 | X20: =IF(V20="-",0,V20-U20) -> 0 | Y20: =+W20-T20 -> -270 | Z20: =+X20+Y20 -> -270 | AA20: 6 | AC20: =Y20*100/T20 -> -0.27615833
A21: =+A20+1 -> 15 | B21: =IF(V20="-",U20,V20) -> 15680 | C21: 15530 | D21: 13770 | E21: 13410 | F21: 0 | G21: =+C21 -> 15530 | H21: =+D21+E21+F21 -> 27180 | I21: 0 | J21: 0 | K21: 0 | L21: =SUM(G21:K21) -> 42710 | M21: 42710 | N21: 0 | O21: =+B21+L21 -> 58390 | P21: =+T21-Q21-R21-S21 -> 55370 | Q21: 0 | R21: 0 | S21: 0 | T21: 55370 | U21: =+O21-T21 -> 3020 | V21: 2330 | W21: 55140 | X21: =IF(V21="-",0,V21-U21) -> -690 | Y21: =+W21-T21 -> -230 | Z21: =+X21+Y21 -> -920 | AA21: 3 | AC21: =Y21*100/T21 -> -0.41538739
A22: =+A21+1 -> 16 | B22: =IF(V21="-",U21,V21) -> 2330 | C22: 23370 | D22: 49740 | E22: 18540 | F22: 0 | G22: =+C22 -> 23370 | H22: =+D22+E22+F22 -> 68280 | I22: 0 | J22: 0 | K22: 0 | L22: =SUM(G22:K22) -> 91650 | M22: 82670 | N22: 8980 | O22: =+B22+L22 -> 93980 | P22: =+T22-Q22-R22-S22 -> 80480 | Q22: 0 | R22: 0 | S22: 0 | T22: 80480 | U22: =+O22-T22 -> 13500 | V22: 13170 | W22: 80130 | X22: =IF(V22="-",0,V22-U22) -> -330 | Y22: =+W22-T22 -> -350 | Z22: =+X22+Y22 -> -680 | AA22: 5 | AC22: =Y22*100/T22 -> -0.43489066
A23: =+A22+1 -> 17 | B23: =IF(V22="-",U22,V22) -> 13170 | C23: 25450 | D23: 56550 | E23: 27770 | F23: 0 | G23: =+C23 -> 25450 | H23: =+D23+E23+F23 -> 84320 | I23: 0 | J23: 0 | K23: 0 | L23: =SUM(G23:K23) -> 109770 | M23: 100380 | N23: 9390 | O23: =+B23+L23 -> 122940 | P23: =+T23-Q23-R23-S23 -> 98570 | Q23: 0 | R23: 0 | S23: 0 | T23: 98570 | U23: =+O23-T23 -> 24370 | V23: 23930 | W23: 98380 | X23: =IF(V23="-",0,V23-U23) -> -440 | Y23: =+W23-T23 -> -190 | Z23: =+X23+Y23 -> -630 | AA23: 5 | AC23: =Y23*100/T23 -> -0.19275642
A24: =+A23+1 -> 18 | B24: =IF(V23="-",U23,V23) -> 23930 | C24: 19750 | D24: 54620 | E24: 36540 | F24: 0 | G24: =+C24 -> 19750 | H24: =+D24+E24+F24 -> 91160 | I24: 0 | J24: 0 | K24: 0 | L24: =SUM(G24:K24) -> 110910 | M24: 102180 | N24: 8730 | O24: =+B24+L24 -> 134840 | P24: =+T24-Q24-R24-S24 -> 109190 | Q24: 0 | R24: 0 | S24: 0 | T24: 109190 | U24: =+O24-T24 -> 25650 | V24: 25000 | W24: 108760 | X24: =IF(V24="-",0,V24-U24) -> -650 | Y24: =+W24-T24 -> -430 | Z24: =+X24+Y24 -> -1080 | AA24: 8 | AC24: =Y24*100/T24 -> -0.39380896
A25: =+A24+1 -> 19 | B25: =IF(V24="-",U24,V24) -> 25000 | C25: 22600 | D25: 37400 | E25: 21030 | F25: 0 | G25: =+C25 -> 22600 | H25: =+D25+E25+F25 -> 58430 | I25: 0 | J25: 0 | K25: 0 | L25: =SUM(G25:K25) -> 81030 | M25: 78020 | N25: 3010 | O25: =+B25+L25 -> 106030 | P25: =+T25-Q25-R25-S25 -> 105850 | Q25: 0 | R25: 0 | S25: 0 | T25: 105850 | U25: =+O25-T25 -> 180 | V25: 0 | W25: 105420 | X25: =IF(V25="-",0,V25-U25) -> -180 | Y25: =+W25-T25 -> -430 | Z25: =+X25+Y25 -> -610 | AA25: 7 | AB25: 120 | AC25: =Y25*100/T25 -> -0.40623524 | AD25: คัดกลับพี่กุ้ง1เที่ยว
A26: =+A25+1 -> 20 | B26: =IF(V25="-",U25,V25) -> 0 | C26: 27980 | D26: 48180 | E26: 21600 | F26: 0 | G26: =+C26 -> 27980 | H26: =+D26+E26+F26 -> 69780 | I26: 0 | J26: 0 | K26: 0 | L26: =SUM(G26:K26) -> 97760 | M26: 90810 | N26: 6950 | O26: =+B26+L26 -> 97760 | P26: =+T26-Q26-R26-S26 -> 83910 | Q26: 0 | R26: 0 | S26: 0 | T26: 83910 | U26: =+O26-T26 -> 13850 | V26: 13490 | W26: 83570 | X26: =IF(V26="-",0,V26-U26) -> -360 | Y26: =+W26-T26 -> -340 | Z26: =+X26+Y26 -> -700 | AA26: 5 | AC26: =Y26*100/T26 -> -0.40519604
A27: =+A26+1 -> 21 | B27: =IF(V26="-",U26,V26) -> 13490 | C27: 19030 | D27: 43010 | E27: 20310 | F27: 0 | G27: =+C27 -> 19030 | H27: =+D27+E27+F27 -> 63320 | I27: 0 | J27: 0 | K27: 0 | L27: =SUM(G27:K27) -> 82350 | M27: 78490 | N27: 3860 | O27: =+B27+L27 -> 95840 | P27: =+T27-Q27-R27-S27 -> 83700 | Q27: 0 | R27: 0 | S27: 0 | T27: 83700 | U27: =+O27-T27 -> 12140 | V27: - | W27: 83410 | X27: =IF(V27="-",0,V27-U27) -> 0 | Y27: =+W27-T27 -> -290 | Z27: =+X27+Y27 -> -290 | AA27: 6 | AC27: =Y27*100/T27 -> -0.34647551
A28: 22 | B28: =IF(V27="-",U27,V27) -> 12140 | C28: 0 | D28: 12280 | E28: 0 | F28: 0 | G28: =+C28 -> 0 | H28: =+D28+E28+F28 -> 12280 | I28: 0 | J28: 0 | K28: 0 | L28: =SUM(G28:K28) -> 12280 | M28: 12280 | N28: 0 | O28: =+B28+L28 -> 24420 | P28: =+T28-Q28-R28-S28 -> 21350 | Q28: 0 | R28: 0 | S28: 0 | T28: 21350 | U28: =+O28-T28 -> 3070 | V28: 3220 | W28: 21320 | X28: =IF(V28="-",0,V28-U28) -> 150 | Y28: =+W28-T28 -> -30 | Z28: =+X28+Y28 -> 120 | AA28: 1 | AC28: =Y28*100/T28 -> -0.14051522
A29: =+A28+1 -> 23 | B29: =IF(V28="-",U28,V28) -> 3220 | C29: 16270 | D29: 48720 | E29: 13810 | F29: 0 | G29: =+C29 -> 16270 | H29: =+D29+E29+F29 -> 62530 | I29: 0 | J29: 0 | K29: 0 | L29: =SUM(G29:K29) -> 78800 | M29: 70240 | N29: 8560 | O29: =+B29+L29 -> 82020 | P29: =+T29-Q29-R29-S29 -> 70040 | Q29: 0 | R29: 0 | S29: 0 | T29: 70040 | U29: =+O29-T29 -> 11980 | V29: 11660 | W29: 69760 | X29: =IF(V29="-",0,V29-U29) -> -320 | Y29: =+W29-T29 -> -280 | Z29: =+X29+Y29 -> -600 | AA29: 4 | AC29: =Y29*100/T29 -> -0.39977156
A30: =+A29+1 -> 24 | B30: =IF(V29="-",U29,V29) -> 11660 | C30: 16320 | D30: 53050 | E30: 16950 | F30: 0 | G30: =+C30 -> 16320 | H30: =+D30+E30+F30 -> 70000 | I30: 0 | J30: 0 | K30: 0 | L30: =SUM(G30:K30) -> 86320 | M30: 71910 | N30: 14410 | O30: =+B30+L30 -> 97980 | P30: =+T30-Q30-R30-S30 -> 83360 | Q30: 0 | R30: 0 | S30: 0 | T30: 83360 | U30: =+O30-T30 -> 14620 | V30: 14240 | W30: 83070 | X30: =IF(V30="-",0,V30-U30) -> -380 | Y30: =+W30-T30 -> -290 | Z30: =+X30+Y30 -> -670 | AA30: 5 | AC30: =Y30*100/T30 -> -0.34788868
A31: =+A30+1 -> 25 | B31: =IF(V30="-",U30,V30) -> 14240 | C31: 8490 | D31: 42290 | E31: 11380 | F31: 0 | G31: =+C31 -> 8490 | H31: =+D31+E31+F31 -> 53670 | I31: 0 | J31: 0 | K31: 0 | L31: =SUM(G31:K31) -> 62160 | M31: 50160 | N31: 12000 | O31: =+B31+L31 -> 76400 | P31: =+T31-Q31-R31-S31 -> 55290 | Q31: 0 | R31: 0 | S31: 0 | T31: 55290 | U31: =+O31-T31 -> 21110 | V31: 20690 | W31: 54890 | X31: =IF(V31="-",0,V31-U31) -> -420 | Y31: =+W31-T31 -> -400 | Z31: =+X31+Y31 -> -820 | AA31: 3 | AB31: 210 | AC31: =Y31*100/T31 -> -0.72345813 | AD31: คัดกลับพี่ตั้ง1เที่ยว/คัดกลับพี่เจี๊ยบ1เที่ยว
A32: =+A31+1 -> 26 | B32: =IF(V31="-",U31,V31) -> 20690 | C32: 34770 | D32: 54990 | E32: 13730 | F32: 0 | G32: =+C32 -> 34770 | H32: =+D32+E32+F32 -> 68720 | I32: 0 | J32: 0 | K32: 0 | L32: =SUM(G32:K32) -> 103490 | M32: 87500 | N32: 15990 | O32: =+B32+L32 -> 124180 | P32: =+T32-Q32-R32-S32 -> 111470 | Q32: 0 | R32: 0 | S32: 0 | T32: 111470 | U32: =+O32-T32 -> 12710 | V32: 12300 | W32: 111070 | X32: =IF(V32="-",0,V32-U32) -> -410 | Y32: =+W32-T32 -> -400 | Z32: =+X32+Y32 -> -810 | AA32: 6 | AC32: =Y32*100/T32 -> -0.35884094
A33: =+A32+1 -> 27 | B33: =IF(V32="-",U32,V32) -> 12300 | C33: 23870 | D33: 41700 | E33: 16570 | F33: 1550 | G33: =+C33 -> 23870 | H33: =+D33+E33+F33 -> 59820 | I33: 0 | J33: 0 | K33: 0 | L33: =SUM(G33:K33) -> 83690 | M33: 79980 | N33: 3710 | O33: =+B33+L33 -> 95990 | P33: =+T33-Q33-R33-S33 -> 69410 | Q33: 0 | R33: 0 | S33: 0 | T33: 69410 | U33: =+O33-T33 -> 26580 | V33: 26010 | W33: 69120 | X33: =IF(V33="-",0,V33-U33) -> -570 | Y33: =+W33-T33 -> -290 | Z33: =+X33+Y33 -> -860 | AA33: 4 | AC33: =Y33*100/T33 -> -0.41780723
A34: =+A33+1 -> 28 | B34: =IF(V33="-",U33,V33) -> 26010 | C34: 36940 | D34: 58390 | E34: 12580 | F34: 0 | G34: =+C34 -> 36940 | H34: =+D34+E34+F34 -> 70970 | I34: 0 | J34: 0 | K34: 0 | L34: =SUM(G34:K34) -> 107910 | M34: 100140 | N34: 7770 | O34: =+B34+L34 -> 133920 | P34: =+T34-Q34-R34-S34 -> 122640 | Q34: 0 | R34: 0 | S34: 0 | T34: 122640 | U34: =+O34-T34 -> 11280 | V34: - | W34: 122260 | X34: =IF(V34="-",0,V34-U34) -> 0 | Y34: =+W34-T34 -> -380 | Z34: =+X34+Y34 -> -380 | AA34: 7 | AC34: =Y34*100/T34 -> -0.30984997
A35: =+A34+1 -> 29 | B35: =IF(V34="-",U34,V34) -> 11280 | C35: 17790 | D35: 18160 | E35: 0 | F35: 0 | G35: =+C35 -> 17790 | H35: =+D35+E35+F35 -> 18160 | I35: 0 | J35: 0 | K35: 0 | L35: =SUM(G35:K35) -> 35950 | M35: 35950 | N35: 0 | O35: =+B35+L35 -> 47230 | P35: =+T35-Q35-R35-S35 -> 42190 | Q35: 0 | R35: 0 | S35: 0 | T35: 42190 | U35: =+O35-T35 -> 5040 | V35: 4770 | W35: 42010 | X35: =IF(V35="-",0,V35-U35) -> -270 | Y35: =+W35-T35 -> -180 | Z35: =+X35+Y35 -> -450 | AA35: 3 | AC35: =Y35*100/T35 -> -0.42664138
A36: =+A35+1 -> 30 | B36: =IF(V35="-",U35,V35) -> 4770 | C36: 46450 | D36: 39870 | E36: 5800 | F36: 0 | G36: =+C36 -> 46450 | H36: =+D36+E36+F36 -> 45670 | I36: 0 | J36: 0 | K36: 0 | L36: =SUM(G36:K36) -> 92120 | M36: 77890 | N36: 14230 | O36: =+B36+L36 -> 96890 | P36: =+T36-Q36-R36-S36 -> 80720 | Q36: 0 | R36: 0 | S36: 0 | T36: 80720 | U36: =+O36-T36 -> 16170 | V36: 16540 | W36: 80460 | X36: =IF(V36="-",0,V36-U36) -> 370 | Y36: =+W36-T36 -> -260 | Z36: =+X36+Y36 -> 110 | AA36: 5 | AC36: =Y36*100/T36 -> -0.32210109
A37: 31 | B37: =IF(V36="-",U36,V36) -> 16540 | C37: 25150 | D37: 35020 | E37: 8300 | F37: 0 | G37: =+C37 -> 25150 | H37: =+D37+E37+F37 -> 43320 | I37: 0 | J37: 0 | K37: 0 | L37: =SUM(G37:K37) -> 68470 | M37: 64670 | N37: 3800 | O37: =+B37+L37 -> 85010 | P37: =+T37-Q37-R37-S37 -> 80930 | Q37: 0 | R37: 0 | S37: 0 | T37: 80930 | U37: =+O37-T37 -> 4080 | V37: 4220 | W37: 80590 | X37: =IF(V37="-",0,V37-U37) -> 140 | Y37: =+W37-T37 -> -340 | Z37: =+X37+Y37 -> -200 | AA37: 6 | AB37: 30 | AC37: =Y37*100/T37 -> -0.42011615 | AD37: คัดกลับพี่เจี๊ยบ1เที่ยว/คัดกลับพี่กุ้ง1เที่ยว
A38: รวม | B38: =+B7 -> 25330 | C38: =SUM(C7:C37) -> 720000 | D38: =SUM(D7:D37) -> 1242030 | E38: =SUM(E7:E37) -> 489750 | F38: =SUM(F7:F37) -> 1550 | G38: =SUM(G7:G37) -> 720000 | H38: =SUM(H7:H37) -> 1733330 | I38: =SUM(I7:I37) -> 0 | J38: =SUM(J7:J37) -> 0 | ... N38: =SUM(N7:N37) -> 220930 | O38: =+B38+L38 -> 2478660 | P38: =SUM(P7:P37) -> 2464400 | Q38: =SUM(Q7:Q37) -> 0 | R38: =SUM(R7:R37) -> 0 | S38: =SUM(S7:S37) -> 0 | T38: =SUM(T7:T37) -> 2464400 | U38: =+O38-T38 -> 14260 | V38: =+V37 -> 4220 | W38: =SUM(W7:W37) -> 2456500 | X38: =SUM(X7:X37) -> -10040 | Y38: =SUM(Y7:Y37) -> -7900 | Z38: =SUM(Z7:Z37) -> -17940 | AA38: =SUM(AA7:AA37) -> 134 | AB38: =SUM(AB7:AB37) -> 360 | AC38: =AB38*100/T38 -> 0.014608018
A39: เฉลี่ย / วัน | C39: =+C38/$A$36 -> 24000 | D39: =+D38/$A$36 -> 41401 | E39: =+E38/$A$36 -> 16325 | F39: =+F38/$A$36 -> 51.666667 | G39: =+G38/$A$36 -> 24000 | H39: =+H38/$A$36 -> 57777.667 | I39: =+I38/$A$36 -> 0 | J39: =+J38/$A$36 -> 0 | ... U39: =+U38/$A$36 -> 475.33333 | V39: =+V38 -> 4220 | W39: =+W38/$A$36 -> 81883.333 | X39: =+X38*100/O38 -> -0.40505757 | Y39: =+Y38*100/T38 -> -0.32056484 | Z39: =+Z38*100/(O38) -> -0.72377817 | AA39: =+AA38/A36 -> 4.4666667

Sheet ตะกุก
A1: บริษัท ทักษิณปาล์ม (2521) จำกัด
A2: รายงานสต๊อคผลปาล์มสด เดือน มีนาคม 2569
A3: เครื่องชั่งแรมป์ตะกุก
A5: วันที่ | B5: น้ำหนัก ยกมา | C5: คีรีรัฐ | F5: น้ำหนักลงแรมป์ | J5: รวมน้ำหนัก ลงแรมป์ | K5: ช่วงเวลา | M5: รวมน้ำหนักทั้งหมด | N5: น้ำหนักส่งออก | R5: รวมน้ำหนักส่งออก | S5: น้ำหนักคงเหลือ | T5: เคลียร์ แรมป์ | U5: น้ำหนัก โรงงาน | V5: น้ำหนักสูญหาย | Y5: จำนวน เที่ยว | Z5: น้ำหนักคัดคืน
C6: ลูกค้า | D6: ปลายราง | E6: บางกัน | F6: ปลายราง | G6: บางกัน | H6: ตะกุกเหนือ | I6: ตะกุก | K6: 8.00-17.00 | L6: 17.00-19.00 | N6: ปลายราง | O6: บางกัน | P6: ตะกุกเหนือ | Q6: ตะกุก | V6: แรมป์ | W6: ขนส่ง | X6: รวม
A7: 1 | B7: 0 | H7: 0 | I7: 0 | J7: =SUM(F7:I7) -> 0 | K7: 0 | L7: 0 | M7: =+B7+J7 -> 0 | N7: 0 | O7: 0 | P7: 0 | Q7: =+R7-P7 -> 0 | R7: 0 | S7: =+M7-R7 -> 0 | T7: 0 | U7: 0 | V7: =IF(T7="-",0,T7-S7) -> 0 | W7: =+U7-R7 -> 0 | X7: =+V7+W7 -> 0 | Y7: 0
A8: =+A7+1 -> 2 | B8: =IF(T7="-",S7,T7) -> 0 | H8: 0 | I8: 8790 | J8: =SUM(F8:I8) -> 8790 | K8: 8790 | L8: 0 | M8: =+B8+J8 -> 8790 | N8: 0 | O8: 0 | P8: 0 | Q8: =+R8-P8 -> 8740 | R8: 8740 | S8: =+M8-R8 -> 50 | T8: 0 | U8: 8730 | V8: =IF(T8="-",0,T8-S8) -> -50 | W8: =+U8-R8 -> -10 | X8: =+V8+W8 -> -60 | Y8: 1 | AA8: =W8*100/R8 -> -0.11441648
A9: 3 | B9: =IF(T8="-",S8,T8) -> 0 | H9: 0 | I9: 0 | J9: =SUM(F9:I9) -> 0 | K9: 0 | L9: 0 | M9: =+B9+J9 -> 0 | N9: 0 | O9: 0 | P9: 0 | Q9: =+R9-P9 -> 0 | R9: 0 | S9: =+M9-R9 -> 0 | T9: 0 | U9: 0 | V9: =IF(T9="-",0,T9-S9) -> 0 | W9: =+U9-R9 -> 0 | X9: =+V9+W9 -> 0 | Y9: 0 | AA9: =W9*100/R9 -> #DIV/0!
A10: =+A9+1 -> 4 | B10: =IF(T9="-",S9,T9) -> 0 | H10: 0 | I10: 8860 | J10: =SUM(F10:I10) -> 8860 | K10: 8860 | L10: 0 | M10: =+B10+J10 -> 8860 | N10: 0 | O10: 0 | P10: 0 | Q10: =+R10-P10 -> 8850 | R10: 8850 | S10: =+M10-R10 -> 10 | T10: 0 | U10: 8810 | V10: =IF(T10="-",0,T10-S10) -> -10 | W10: =+U10-R10 -> -40 | X10: =+V10+W10 -> -50 | Y10: 1 | AA10: =W10*100/R10 -> -0.4519774
A11: =+A10+1 -> 5 | B11: =IF(T10="-",S10,T10) -> 0 | H11: 0 | I11: 9400 | J11: =SUM(F11:I11) -> 9400 | K11: 4750 | L11: 4650 | M11: =+B11+J11 -> 9400 | N11: 0 | O11: 0 | P11: 0 | Q11: =+R11-P11 -> 9410 | R11: 9410 | S11: =+M11-R11 -> -10 | T11: 0 | U11: 9380 | V11: =IF(T11="-",0,T11-S11) -> 10 | W11: =+U11-R11 -> -30 | X11: =+V11+W11 -> -20 | Y11: 1 | AA11: =W11*100/R11 -> -0.31880978
A12: =+A11+1 -> 6 | B12: =IF(T11="-",S11,T11) -> 0 | H12: 0 | I12: 22390 | J12: =SUM(F12:I12) -> 22390 | K12: 18310 | L12: 4080 | M12: =+B12+J12 -> 22390 | N12: 0 | O12: 0 | P12: 0 | Q12: =+R12-P12 -> 12590 | R12: 12590 | S12: =+M12-R12 -> 9800 | T12: - | U12: 12540 | V12: =IF(T12="-",0,T12-S12) -> 0 | W12: =+U12-R12 -> -50 | X12: =+V12+W12 -> -50 | Y12: 2 | AA12: =W12*100/R12 -> -0.39714059
A13: =+A12+1 -> 7 | B13: =IF(T12="-",S12,T12) -> 9800 | H13: 0 | I13: 25220 | J13: =SUM(F13:I13) -> 25220 | K13: 25220 | L13: 0 | M13: =+B13+J13 -> 35020 | N13: 0 | O13: 0 | P13: 0 | Q13: =+R13-P13 -> 22170 | R13: 22170 | S13: =+M13-R13 -> 12850 | T13: - | U13: 22110 | V13: =IF(T13="-",0,T13-S13) -> 0 | W13: =+U13-R13 -> -60 | X13: =+V13+W13 -> -60 | Y13: 2 | AA13: =W13*100/R13 -> -0.27063599
A14: =+A13+1 -> 8 | B14: =IF(T13="-",S13,T13) -> 12850 | H14: 0 | I14: 31030 | J14: =SUM(F14:I14) -> 31030 | K14: 31030 | L14: 0 | M14: =+B14+J14 -> 43880 | N14: 0 | O14: 0 | P14: 0 | Q14: =+R14-P14 -> 43290 | R14: 43290 | S14: =+M14-R14 -> 590 | T14: 0 | U14: 43190 | V14: =IF(T14="-",0,T14-S14) -> -590 | W14: =+U14-R14 -> -100 | X14: =+V14+W14 -> -690 | Y14: 4 | AA14: =W14*100/R14 -> -0.23100023
A15: =+A14+1 -> 9 | B15: =IF(T14="-",S14,T14) -> 0 | H15: 0 | I15: 33520 | J15: =SUM(F15:I15) -> 33520 | K15: 33520 | L15: 0 | M15: =+B15+J15 -> 33520 | N15: 0 | O15: 0 | P15: 0 | Q15: =+R15-P15 -> 22030 | R15: 22030 | S15: =+M15-R15 -> 11490 | T15: - | U15: 21920 | V15: =IF(T15="-",0,T15-S15) -> 0 | W15: =+U15-R15 -> -110 | X15: =+V15+W15 -> -110 | Y15: 2 | AA15: =W15*100/R15 -> -0.49931911
A16: =+A15+1 -> 10 | B16: =IF(T15="-",S15,T15) -> 11490 | H16: 0 | I16: 30850 | J16: =SUM(F16:I16) -> 30850 | K16: 30850 | L16: 0 | M16: =+B16+J16 -> 42340 | N16: 0 | O16: 0 | P16: 0 | Q16: =+R16-P16 -> 22390 | R16: 22390 | S16: =+M16-R16 -> 19950 | T16: - | U16: 22160 | V16: =IF(T16="-",0,T16-S16) -> 0 | W16: =+U16-R16 -> -230 | X16: =+V16+W16 -> -230 | Y16: 2 | AA16: =W16*100/R16 -> -1.0272443
A17: =+A16+1 -> 11 | B17: =IF(T16="-",S16,T16) -> 19950 | H17: 0 | I17: 47690 | J17: =SUM(F17:I17) -> 47690 | K17: 47690 | L17: 0 | M17: =+B17+J17 -> 67640 | N17: 0 | O17: 0 | P17: 0 | Q17: =+R17-P17 -> 66020 | R17: 66020 | S17: =+M17-R17 -> 1620 | T17: - | U17: 65780 | V17: =IF(T17="-",0,T17-S17) -> 0 | W17: =+U17-R17 -> -240 | X17: =+V17+W17 -> -240 | Y17: 6 | AA17: =W17*100/R17 -> -0.3635262
A18: =+A17+1 -> 12 | B18: =IF(T17="-",S17,T17) -> 1620 | H18: 0 | I18: 58830 | J18: =SUM(F18:I18) -> 58830 | K18: 54620 | L18: 4210 | M18: =+B18+J18 -> 60450 | N18: 0 | O18: 0 | P18: 0 | Q18: =+R18-P18 -> 36360 | R18: 36360 | S18: =+M18-R18 -> 24090 | T18: - | U18: 36150 | V18: =IF(T18="-",0,T18-S18) -> 0 | W18: =+U18-R18 -> -210 | X18: =+V18+W18 -> -210 | Y18: 3 | AA18: =W18*100/R18 -> -0.57755776
A19: =+A18+1 -> 13 | B19: =IF(T18="-",S18,T18) -> 24090 | H19: 0 | I19: 48780 | J19: =SUM(F19:I19) -> 48780 | K19: 41080 | L19: 7700 | M19: =+B19+J19 -> 72870 | N19: 0 | O19: 0 | P19: 0 | Q19: =+R19-P19 -> 57260 | R19: 57260 | S19: =+M19-R19 -> 15610 | T19: - | U19: 57040 | V19: =IF(T19="-",0,T19-S19) -> 0 | W19: =+U19-R19 -> -220 | X19: =+V19+W19 -> -220 | Y19: 5 | AA19: =W19*100/R19 -> -0.38421236
A20: =+A19+1 -> 14 | B20: =IF(T19="-",S19,T19) -> 15610 | H20: 0 | I20: 36930 | J20: =SUM(F20:I20) -> 36930 | K20: 35230 | L20: 1700 | M20: =+B20+J20 -> 52540 | N20: 0 | O20: 0 | P20: 0 | Q20: =+R20-P20 -> 43990 | R20: 43990 | S20: =+M20-R20 -> 8550 | T20: - | U20: 43790 | V20: =IF(T20="-",0,T20-S20) -> 0 | W20: =+U20-R20 -> -200 | X20: =+V20+W20 -> -200 | Y20: 4 | AA20: =W20*100/R20 -> -0.45464878
A21: =+A20+1 -> 15 | B21: =IF(T20="-",S20,T20) -> 8550 | H21: 0 | I21: 16710 | J21: =SUM(F21:I21) -> 16710 | K21: 16710 | L21: 0 | M21: =+B21+J21 -> 25260 | N21: 0 | O21: 0 | P21: 0 | Q21: =+R21-P21 -> 22210 | R21: 22210 | S21: =+M21-R21 -> 3050 | T21: - | U21: 22160 | V21: =IF(T21="-",0,T21-S21) -> 0 | W21: =+U21-R21 -> -50 | X21: =+V21+W21 -> -50 | Y21: 2 | AA21: =W21*100/R21 -> -0.22512382
A22: =+A21+1 -> 16 | B22: =IF(T21="-",S21,T21) -> 3050 | H22: 0 | I22: 10280 | J22: =SUM(F22:I22) -> 10280 | K22: 10280 | L22: 0 | M22: =+B22+J22 -> 13330 | N22: 0 | O22: 0 | P22: 0 | Q22: =+R22-P22 -> 11600 | R22: 11600 | S22: =+M22-R22 -> 1730 | T22: 0 | U22: 11520 | V22: =IF(T22="-",0,T22-S22) -> -1730 | W22: =+U22-R22 -> -80 | X22: =+V22+W22 -> -1810 | Y22: 1 | AA22: =W22*100/R22 -> -0.68965517
A23: =+A22+1 -> 17 | B23: =IF(T22="-",S22,T22) -> 0 | H23: 0 | I23: 7140 | J23: =SUM(F23:I23) -> 7140 | K23: 7140 | L23: 0 | M23: =+B23+J23 -> 7140 | N23: 0 | O23: 0 | P23: 0 | Q23: =+R23-P23 -> 7120 | R23: 7120 | S23: =+M23-R23 -> 20 | T23: 0 | U23: 7120 | V23: =IF(T23="-",0,T23-S23) -> -20 | W23: =+U23-R23 -> 0 | X23: =+V23+W23 -> -20 | Y23: 1 | AA23: =W23*100/R23 -> 0
A24: =+A23+1 -> 18 | B24: =IF(T23="-",S23,T23) -> 0 | H24: 0 | I24: 3150 | J24: =SUM(F24:I24) -> 3150 | K24: 3150 | L24: 0 | M24: =+B24+J24 -> 3150 | N24: 0 | O24: 0 | P24: 0 | Q24: =+R24-P24 -> 0 | R24: 0 | S24: =+M24-R24 -> 3150 | T24: - | U24: 0 | V24: =IF(T24="-",0,T24-S24) -> 0 | W24: =+U24-R24 -> 0 | X24: =+V24+W24 -> 0 | Y24: 0 | AA24: =W24*100/R24 -> #DIV/0!
A25: =+A24+1 -> 19 | B25: =IF(T24="-",S24,T24) -> 3150 | C25: 0 | D25: 0 | E25: 0 | F25: 0 | G25: 0 | H25: 0 | I25: 27020 | J25: =SUM(F25:I25) -> 27020 | K25: 27020 | L25: 0 | M25: =+B25+J25 -> 30170 | N25: 0 | O25: 0 | P25: 0 | Q25: =+R25-P25 -> 22260 | R25: 22260 | S25: =+M25-R25 -> 7910 | T25: - | U25: 22120 | V25: =IF(T25="-",0,T25-S25) -> 0 | W25: =+U25-R25 -> -140 | X25: =+V25+W25 -> -140 | Y25: 2 | AA25: =W25*100/R25 -> -0.62893082
A26: =+A25+1 -> 20 | B26: =IF(T25="-",S25,T25) -> 7910 | H26: 0 | I26: 25140 | J26: =SUM(F26:I26) -> 25140 | K26: 25140 | L26: 0 | M26: =+B26+J26 -> 33050 | N26: 0 | O26: 0 | P26: 0 | Q26: =+R26-P26 -> 21590 | R26: 21590 | S26: =+M26-R26 -> 11460 | T26: - | U26: 21530 | V26: =IF(T26="-",0,T26-S26) -> 0 | W26: =+U26-R26 -> -60 | X26: =+V26+W26 -> -60 | Y26: 2 | AA26: =W26*100/R26 -> -0.27790644
A27: =+A26+1 -> 21 | B27: =IF(T26="-",S26,T26) -> 11460 | H27: 0 | I27: 25670 | J27: =SUM(F27:I27) -> 25670 | K27: 25670 | L27: 0 | M27: =+B27+J27 -> 37130 | N27: 0 | O27: 0 | P27: 0 | Q27: =+R27-P27 -> 21530 | R27: 21530 | S27: =+M27-R27 -> 15600 | T27: - | U27: 21380 | V27: =IF(T27="-",0,T27-S27) -> 0 | W27: =+U27-R27 -> -150 | X27: =+V27+W27 -> -150 | Y27: 2 | AA27: =W27*100/R27 -> -0.69670228
A28: =+A27+1 -> 22 | B28: =IF(T27="-",S27,T27) -> 15600 | H28: 0 | I28: 0 | J28: =SUM(F28:I28) -> 0 | K28: 0 | L28: 0 | M28: =+B28+J28 -> 15600 | N28: 0 | O28: 0 | P28: 0 | Q28: =+R28-P28 -> 14800 | R28: 14800 | S28: =+M28-R28 -> 800 | T28: 0 | U28: 14760 | V28: =IF(T28="-",0,T28-S28) -> -800 | W28: =+U28-R28 -> -40 | X28: =+V28+W28 -> -840 | Y28: 2 | AA28: =W28*100/R28 -> -0.27027027
A29: =+A28+1 -> 23 | B29: =IF(T28="-",S28,T28) -> 0 | H29: 0 | I29: 29350 | J29: =SUM(F29:I29) -> 29350 | K29: 29350 | L29: 0 | M29: =+B29+J29 -> 29350 | N29: 0 | O29: 0 | P29: 0 | Q29: =+R29-P29 -> 24610 | R29: 24610 | S29: =+M29-R29 -> 4740 | T29: - | U29: 24500 | V29: =IF(T29="-",0,T29-S29) -> 0 | W29: =+U29-R29 -> -110 | X29: =+V29+W29 -> -110 | Y29: 2 | AA29: =W29*100/R29 -> -0.44697278
A30: =+A29+1 -> 24 | B30: =IF(T29="-",S29,T29) -> 4740 | H30: 0 | I30: 36750 | J30: =SUM(F30:I30) -> 36750 | K30: 36750 | L30: 0 | M30: =+B30+J30 -> 41490 | N30: 0 | O30: 0 | P30: 0 | Q30: =+R30-P30 -> 36390 | R30: 36390 | S30: =+M30-R30 -> 5100 | T30: - | U30: 36270 | V30: =IF(T30="-",0,T30-S30) -> 0 | W30: =+U30-R30 -> -120 | X30: =+V30+W30 -> -120 | Y30: 3 | AA30: =W30*100/R30 -> -0.32976092
A31: =+A30+1 -> 25 | B31: =IF(T30="-",S30,T30) -> 5100 | H31: 0 | I31: 55260 | J31: =SUM(F31:I31) -> 55260 | K31: 50590 | L31: 4670 | M31: =+B31+J31 -> 60360 | N31: 0 | O31: 0 | P31: 0 | Q31: =+R31-P31 -> 36430 | R31: 36430 | S31: =+M31-R31 -> 23930 | T31: - | U31: 36080 | V31: =IF(T31="-",0,T31-S31) -> 0 | W31: =+U31-R31 -> -350 | X31: =+V31+W31 -> -350 | Y31: 3 | Z31: 180 | AA31: =W31*100/R31 -> -0.96074664 | AB31: คัดกลับพี่กุ้ง1เที่ยว
A32: =+A31+1 -> 26 | B32: =IF(T31="-",S31,T31) -> 23930 | H32: 0 | I32: 41400 | J32: =SUM(F32:I32) -> 41400 | K32: 41400 | L32: 0 | M32: =+B32+J32 -> 65330 | N32: 0 | O32: 0 | P32: 0 | Q32: =+R32-P32 -> 61390 | R32: 61390 | S32: =+M32-R32 -> 3940 | T32: - | U32: 60990 | V32: =IF(T32="-",0,T32-S32) -> 0 | W32: =+U32-R32 -> -400 | X32: =+V32+W32 -> -400 | Y32: 5 | Z32: 170 | AA32: =W32*100/R32 -> -0.65157192 | AB32: คัดกลับพี่กุ้ง1เที่ยว
A33: =+A32+1 -> 27 | B33: =IF(T32="-",S32,T32) -> 3940 | H33: 0 | I33: 19370 | J33: =SUM(F33:I33) -> 19370 | K33: 19370 | L33: 0 | M33: =+B33+J33 -> 23310 | N33: 0 | O33: 0 | P33: 0 | Q33: =+R33-P33 -> 22200 | R33: 22200 | S33: =+M33-R33 -> 1110 | T33: 0 | U33: 22030 | V33: =IF(T33="-",0,T33-S33) -> -1110 | W33: =+U33-R33 -> -170 | X33: =+V33+W33 -> -1280 | Y33: 2 | Z33: 60 | AA33: =W33*100/R33 -> -0.76576577 | AB33: คัดกลับพี่กุ้ง1เที่ยว
A34: =+A33+1 -> 28 | B34: =IF(T33="-",S33,T33) -> 0 | H34: 0 | I34: 0 | J34: =SUM(F34:I34) -> 0 | K34: 0 | L34: 0 | M34: =+B34+J34 -> 0 | N34: 0 | O34: 0 | P34: 0 | Q34: =+R34-P34 -> 0 | R34: 0 | S34: =+M34-R34 -> 0 | T34: 0 | U34: 0 | V34: =IF(T34="-",0,T34-S34) -> 0 | W34: =+U34-R34 -> 0 | X34: =+V34+W34 -> 0 | Y34: 0 | AA34: =W34*100/R34 -> #DIV/0!
A35: =+A34+1 -> 29 | B35: =IF(T34="-",S34,T34) -> 0 | H35: 0 | I35: 0 | J35: =SUM(F35:I35) -> 0 | K35: 0 | L35: 0 | M35: =+B35+J35 -> 0 | N35: 0 | O35: 0 | P35: 0 | Q35: =+R35-P35 -> 0 | R35: 0 | S35: =+M35-R35 -> 0 | T35: 0 | U35: 0 | V35: =IF(T35="-",0,T35-S35) -> 0 | W35: =+U35-R35 -> 0 | X35: =+V35+W35 -> 0 | Y35: 0 | AA35: =W35*100/R35 -> #DIV/0!
A36: =+A35+1 -> 30 | B36: =IF(T35="-",S35,T35) -> 0 | H36: 0 | I36: 0 | J36: =SUM(F36:I36) -> 0 | K36: 0 | L36: 0 | M36: =+B36+J36 -> 0 | N36: 0 | O36: 0 | P36: 0 | Q36: =+R36-P36 -> 0 | R36: 0 | S36: =+M36-R36 -> 0 | T36: 0 | U36: 0 | V36: =IF(T36="-",0,T36-S36) -> 0 | W36: =+U36-R36 -> 0 | X36: =+V36+W36 -> 0 | Y36: 0 | AA36: =W36*100/R36 -> #DIV/0!
A37: =+A36+1 -> 31 | B37: =IF(T36="-",S36,T36) -> 0 | H37: 0 | I37: 0 | J37: =SUM(F37:I37) -> 0 | K37: 0 | L37: 0 | M37: =+B37+J37 -> 0 | P37: 0 | Q37: =+R37-P37 -> 0 | R37: 0 | S37: =+M37-R37 -> 0 | T37: 0 | U37: 0 | V37: =IF(T37="-",0,T37-S37) -> 0 | W37: =+U37-R37 -> 0 | X37: =+V37+W37 -> 0 | Y37: 0 | AA37: =W37*100/R37 -> #DIV/0!
A38: รวม | B38: =+B7 -> 0 | C38: =SUM(C7:C37) -> 0 | D38: =SUM(D7:D37) -> 0 | E38: =SUM(E7:E37) -> 0 | F38: =SUM(F7:F37) -> 0 | H38: =SUM(H7:H37) -> 0 | I38: =SUM(I7:I37) -> 659530 | J38: =SUM(J7:J37) -> 659530 | K38: =SUM(K7:K37) -> 632520 | L38: =SUM(L7:L37) -> 27010 | M38: =+B38+J38 -> 659530 | N38: 0 | O38: 0 | P38: =SUM(P7:P37) -> 0 | Q38: =SUM(Q7:Q37) -> 655230 | R38: =+P38+Q38 -> 655230 | S38: =+M38-R38 -> 4300 | T38: =+T37 -> 0 | U38: =SUM(U7:U37) -> 652060 | V38: =SUM(V7:V37) -> -4300 | W38: =SUM(W7:W37) -> -3170 | X38: =SUM(X7:X37) -> -7470 | Y38: =SUM(Y7:Y37) -> 60 | Z38: =SUM(Z7:Z37) -> 410 | AA38: =Z38*100/U38 -> 0.062877649
A39: เฉลี่ย / วัน | C39: =+C38/$A$36 -> 0 | D39: =+D38/$A$36 -> 0 | E39: =+E38/$A$36 -> 0 | F39: =+F38/$A$36 -> 0 | H39: =+H38/A36 -> 0 | I39: =+I38/A36 -> 21984.333 | J39: =+J38/$A$36 -> 21984.333 | K39: =+K38/$A$36 -> 21084 | L39: =+L38/$A$36 -> 900.33333 | M39: =+M38/$A$36 -> 21984.333 | N39: =+N38/$A$36 -> 0 | O39: =+O38/$A$36 -> 0 | P39: =+P38/$A$36 -> 0 | Q39: =+Q38/$A$36 -> 21841 | ... S39: =+S38/$A$36 -> 143.33333 | T39: 0 | U39: =+U38/$A$36 -> 21735.333 | V39: =+V38*100/M38 -> -0.65197944 | W39: =+W38*100/R38 -> -0.48379958 | X39: =+X38*100/(M38) -> -1.1326247 | Y39: =+Y38/A36 -> 2

Sheet รวม
A1: บริษัท ทักษิณปาล์ม (2521) จำกัด - ฝ่ายสวนปาล์มคีรีรัฐนิคม
A2: รายงานสต๊อคผลปาล์มสด เดือน มีนาคม 2569
A3: เครื่องชั่งแรมป์ปลายราง+เครื่องชั่งแรมป์ตะกุก
A5: วันที่ | B5: น้ำหนัก ยกมา | C5: ปลายราง | F5: น้ำหนักลงแรมป์ | L5: ช่วงเวลา | N5: รวมน้ำหนักทั้งหมด | O5: น้ำหนักส่งออก | T5: น้ำหนักคงเหลือ | U5: เคลียร์แรมป์ | W5: น้ำหนัก โรงงาน | X5: น้ำหนักสูญหาย | AA5: จำนวน เที่ยว | AB5: น้ำหนักคัดคืน | AC5: หมายเหตุ
C6: ลูกค้า | D6: ปาล์มสวนฯ | F6: ลูกค้า | G6: ปลายราง | H6: บางกัน | I6: กะเปา | J6: ตะกุก | K6: รวม | L6: 8.00-16.00 | M6: 16.00-19.00 | O6: ปลายราง | P6: บางกัน | Q6: กะเปา | R6: ตะกุก | S6: รวม | U6: ปลายราง | V6: ตะกุก | X6: แรมป์ | Y6: ขนส่ง | Z6: รวม
A7: 1 | B7: =+แรมป์สวน!B7+ตะกุก!B7 -> 25330 | C7: =+แรมป์สวน!C7+ตะกุก!C7 -> 11640 | D7: =+แรมป์สวน!D7+ตะกุก!D7 -> 0 | E7: =+แรมป์สวน!E7+ตะกุก!E7 -> 6990 | F7: =+แรมป์สวน!G7 -> 11640 | G7: =+แรมป์สวน!H7+ตะกุก!F7 -> 6990 | H7: =+แรมป์สวน!I7+ตะกุก!G7 -> 0 | I7: =+แรมป์สวน!J7+ตะกุก!H7 -> 0 | J7: =+แรมป์สวน!K7+ตะกุก!I7 -> 0 | K7: =SUM(F7:J7) -> 18630 | L7: =+แรมป์สวน!M7+ตะกุก!K7 -> 18630 | M7: =+แรมป์สวน!N7+ตะกุก!L7 -> 0 | N7: =+B7+K7 -> 43960 | O7: =+แรมป์สวน!P7+ตะกุก!N7 -> 44030 | P7: =+แรมป์สวน!Q7+ตะกุก!O7 -> 0 | Q7: =+แรมป์สวน!R7+ตะกุก!P7 -> 0 | R7: =+แรมป์สวน!S7+ตะกุก!Q7 -> 0 | S7: =SUM(O7:R7) -> 44030 | T7: =+N7-S7 -> -70 | U7: =+แรมป์สวน!V7 -> 0 | V7: =+ตะกุก!T7 -> 0 | W7: =+แรมป์สวน!W7+ตะกุก!U7 -> 43970 | X7: =+แรมป์สวน!X7+ตะกุก!V7 -> 70 | Y7: =+W7-S7 -> -60 | Z7: =+X7+Y7 -> 10 | AA7: =+แรมป์สวน!AA7+ตะกุก!Y7 -> 2 | AB7: =+แรมป์สวน!AB7+ตะกุก!Z7 -> 0
A8: =+A7+1 -> 2 | B8: =+แรมป์สวน!B8+ตะกุก!B8 -> 0 | C8: =+แรมป์สวน!C8+ตะกุก!C8 -> 32370 | D8: =+แรมป์สวน!D8+ตะกุก!D8 -> 47070 | E8: =+แรมป์สวน!E8+ตะกุก!E8 -> 14670 | F8: =+แรมป์สวน!G8 -> 32370 | G8: =+แรมป์สวน!H8+ตะกุก!F8 -> 61740 | H8: =+แรมป์สวน!I8+ตะกุก!G8 -> 0 | I8: =+แรมป์สวน!J8+ตะกุก!H8 -> 0 | J8: =+แรมป์สวน!K8+ตะกุก!I8 -> 8790 | K8: =SUM(F8:J8) -> 102900 | L8: =+แรมป์สวน!M8+ตะกุก!K8 -> 101620 | M8: =+แรมป์สวน!N8+ตะกุก!L8 -> 1280 | N8: =+B8+K8 -> 102900 | O8: =+แรมป์สวน!P8+ตะกุก!N8 -> 93660 | P8: =+แรมป์สวน!Q8+ตะกุก!O8 -> 0 | Q8: =+แรมป์สวน!R8+ตะกุก!P8 -> 0 | R8: =+แรมป์สวน!S8+ตะกุก!Q8 -> 8740 | S8: =SUM(O8:R8) -> 102400 | T8: =+N8-S8 -> 500 | U8: =+แรมป์สวน!V8 -> 0 | V8: =+ตะกุก!T8 -> 0 | W8: =+แรมป์สวน!W8+ตะกุก!U8 -> 102040 | X8: =+แรมป์สวน!X8+ตะกุก!V8 -> -500 | Y8: =+W8-S8 -> -360 | Z8: =+X8+Y8 -> -860 | AA8: =+แรมป์สวน!AA8+ตะกุก!Y8 -> 5 | AB8: =+แรมป์สวน!AB8+ตะกุก!Z8 -> 0
A9: =+A8+1 -> 3 | B9: =+แรมป์สวน!B9+ตะกุก!B9 -> 0 | C9: =+แรมป์สวน!C9+ตะกุก!C9 -> 0 | D9: =+แรมป์สวน!D9+ตะกุก!D9 -> 0 | E9: =+แรมป์สวน!E9+ตะกุก!E9 -> 0 | F9: =+แรมป์สวน!G9 -> 0 | G9: =+แรมป์สวน!H9+ตะกุก!F9 -> 0 | H9: =+แรมป์สวน!I9+ตะกุก!G9 -> 0 | I9: =+แรมป์สวน!J9+ตะกุก!H9 -> 0 | J9: =+แรมป์สวน!K9+ตะกุก!I9 -> 0 | K9: =SUM(F9:J9) -> 0 | L9: =+แรมป์สวน!M9+ตะกุก!K9 -> 0 | M9: =+แรมป์สวน!N9+ตะกุก!L9 -> 0 | N9: =+B9+K9 -> 0 | O9: =+แรมป์สวน!P9+ตะกุก!N9 -> 0 | P9: =+แรมป์สวน!Q9+ตะกุก!O9 -> 0 | Q9: =+แรมป์สวน!R9+ตะกุก!P9 -> 0 | R9: =+แรมป์สวน!S9+ตะกุก!Q9 -> 0 | S9: =SUM(O9:R9) -> 0 | T9: =+N9-S9 -> 0 | U9: =+แรมป์สวน!V9 -> 0 | V9: =+ตะกุก!T9 -> 0 | W9: =+แรมป์สวน!W9+ตะกุก!U9 -> 0 | X9: =+แรมป์สวน!X9+ตะกุก!V9 -> 0 | Y9: =+W9-S9 -> 0 | Z9: =+X9+Y9 -> 0 | AA9: =+แรมป์สวน!AA9+ตะกุก!Y9 -> 0 | AB9: =+แรมป์สวน!AB9+ตะกุก!Z9 -> 0
A10: =+A9+1 -> 4 | B10: =+แรมป์สวน!B10+ตะกุก!B10 -> 0 | C10: =+แรมป์สวน!C10+ตะกุก!C10 -> 37830 | D10: =+แรมป์สวน!D10+ตะกุก!D10 -> 56230 | E10: =+แรมป์สวน!E10+ตะกุก!E10 -> 38910 | F10: =+แรมป์สวน!G10 -> 37830 | G10: =+แรมป์สวน!H10+ตะกุก!F10 -> 95140 | H10: =+แรมป์สวน!I10+ตะกุก!G10 -> 0 | I10: =+แรมป์สวน!J10+ตะกุก!H10 -> 0 | J10: =+แรมป์สวน!K10+ตะกุก!I10 -> 8860 | K10: =SUM(F10:J10) -> 141830 | L10: =+แรมป์สวน!M10+ตะกุก!K10 -> 120730 | M10: =+แรมป์สวน!N10+ตะกุก!L10 -> 21100 | N10: =+B10+K10 -> 141830 | O10: =+แรมป์สวน!P10+ตะกุก!N10 -> 112800 | P10: =+แรมป์สวน!Q10+ตะกุก!O10 -> 0 | Q10: =+แรมป์สวน!R10+ตะกุก!P10 -> 0 | R10: =+แรมป์สวน!S10+ตะกุก!Q10 -> 8850 | S10: =SUM(O10:R10) -> 121650 | T10: =+N10-S10 -> 20180 | U10: =+แรมป์สวน!V10 -> 19320 | V10: =+ตะกุก!T10 -> 0 | W10: =+แรมป์สวน!W10+ตะกุก!U10 -> 121260 | X10: =+แรมป์สวน!X10+ตะกุก!V10 -> -860 | Y10: =+W10-S10 -> -390 | Z10: =+X10+Y10 -> -1250 | AA10: =+แรมป์สวน!AA10+ตะกุก!Y10 -> 5 | AB10: =+แรมป์สวน!AB10+ตะกุก!Z10 -> 0
A11: =+A10+1 -> 5 | B11: =+แรมป์สวน!B11+ตะกุก!B11 -> 19320 | C11: =+แรมป์สวน!C11+ตะกุก!C11 -> 29930 | D11: =+แรมป์สวน!D11+ตะกุก!D11 -> 34210 | E11: =+แรมป์สวน!E11+ตะกุก!E11 -> 35090 | F11: =+แรมป์สวน!G11 -> 29930 | G11: =+แรมป์สวน!H11+ตะกุก!F11 -> 69300 | H11: =+แรมป์สวน!I11+ตะกุก!G11 -> 0 | I11: =+แรมป์สวน!J11+ตะกุก!H11 -> 0 | J11: =+แรมป์สวน!K11+ตะกุก!I11 -> 9400 | K11: =SUM(F11:J11) -> 108630 | L11: =+แรมป์สวน!M11+ตะกุก!K11 -> 93350 | M11: =+แรมป์สวน!N11+ตะกุก!L11 -> 15280 | N11: =+B11+K11 -> 127950 | O11: =+แรมป์สวน!P11+ตะกุก!N11 -> 84680 | P11: =+แรมป์สวน!Q11+ตะกุก!O11 -> 0 | Q11: =+แรมป์สวน!R11+ตะกุก!P11 -> 0 | R11: =+แรมป์สวน!S11+ตะกุก!Q11 -> 9410 | S11: =SUM(O11:R11) -> 94090 | T11: =+N11-S11 -> 33860 | U11: =+แรมป์สวน!V11 -> 33020 | V11: =+ตะกุก!T11 -> 0 | W11: =+แรมป์สวน!W11+ตะกุก!U11 -> 93790 | X11: =+แรมป์สวน!X11+ตะกุก!V11 -> -840 | Y11: =+W11-S11 -> -300 | Z11: =+X11+Y11 -> -1140 | AA11: =+แรมป์สวน!AA11+ตะกุก!Y11 -> 4 | AB11: =+แรมป์สวน!AB11+ตะกุก!Z11 -> 0
A12: =+A11+1 -> 6 | B12: =+แรมป์สวน!B12+ตะกุก!B12 -> 33020 | C12: =+แรมป์สวน!C12+ตะกุก!C12 -> 29170 | D12: =+แรมป์สวน!D12+ตะกุก!D12 -> 45580 | E12: =+แรมป์สวน!E12+ตะกุก!E12 -> 22460 | F12: =+แรมป์สวน!G12 -> 29170 | G12: =+แรมป์สวน!H12+ตะกุก!F12 -> 68040 | H12: =+แรมป์สวน!I12+ตะกุก!G12 -> 0 | I12: =+แรมป์สวน!J12+ตะกุก!H12 -> 0 | J12: =+แรมป์สวน!K12+ตะกุก!I12 -> 22390 | K12: =SUM(F12:J12) -> 119600 | L12: =+แรมป์สวน!M12+ตะกุก!K12 -> 105390 | M12: =+แรมป์สวน!N12+ตะกุก!L12 -> 14210 | N12: =+B12+K12 -> 152620 | O12: =+แรมป์สวน!P12+ตะกุก!N12 -> 129910 | P12: =+แรมป์สวน!Q12+ตะกุก!O12 -> 0 | Q12: =+แรมป์สวน!R12+ตะกุก!P12 -> 0 | R12: =+แรมป์สวน!S12+ตะกุก!Q12 -> 12590 | S12: =SUM(O12:R12) -> 142500 | T12: =+N12-S12 -> 10120 | U12: =+แรมป์สวน!V12 -> 0 | V12: =+ตะกุก!T12 -> - | W12: =+แรมป์สวน!W12+ตะกุก!U12 -> 142190 | X12: =+แรมป์สวน!X12+ตะกุก!V12 -> -320 | Y12: =+W12-S12 -> -310 | Z12: =+X12+Y12 -> -630 | AA12: =+แรมป์สวน!AA12+ตะกุก!Y12 -> 7 | AB12: =+แรมป์สวน!AB12+ตะกุก!Z12 -> 0
A13: =+A12+1 -> 7 | B13: =+แรมป์สวน!B13+ตะกุก!B13 -> 9800 | C13: =+แรมป์สวน!C13+ตะกุก!C13 -> 33230 | D13: =+แรมป์สวน!D13+ตะกุก!D13 -> 49060 | E13: =+แรมป์สวน!E13+ตะกุก!E13 -> 16600 | F13: =+แรมป์สวน!G13 -> 33230 | G13: =+แรมป์สวน!H13+ตะกุก!F13 -> 65660 | H13: =+แรมป์สวน!I13+ตะกุก!G13 -> 0 | I13: =+แรมป์สวน!J13+ตะกุก!H13 -> 0 | J13: =+แรมป์สวน!K13+ตะกุก!I13 -> 25220 | K13: =SUM(F13:J13) -> 124110 | L13: =+แรมป์สวน!M13+ตะกุก!K13 -> 116990 | M13: =+แรมป์สวน!N13+ตะกุก!L13 -> 7120 | N13: =+B13+K13 -> 133910 | O13: =+แรมป์สวน!P13+ตะกุก!N13 -> 77250 | P13: =+แรมป์สวน!Q13+ตะกุก!O13 -> 0 | Q13: =+แรมป์สวน!R13+ตะกุก!P13 -> 0 | R13: =+แรมป์สวน!S13+ตะกุก!Q13 -> 22170 | S13: =SUM(O13:R13) -> 99420 | T13: =+N13-S13 -> 34490 | U13: =+แรมป์สวน!V13 -> 21190 | V13: =+ตะกุก!T13 -> - | W13: =+แรมป์สวน!W13+ตะกุก!U13 -> 99190 | X13: =+แรมป์สวน!X13+ตะกุก!V13 -> -450 | Y13: =+W13-S13 -> -230 | Z13: =+X13+Y13 -> -680 | AA13: =+แรมป์สวน!AA13+ตะกุก!Y13 -> 5 | AB13: =+แรมป์สวน!AB13+ตะกุก!Z13 -> 0
A14: =+A13+1 -> 8 | B14: =+แรมป์สวน!B14+ตะกุก!B14 -> 34040 | C14: =+แรมป์สวน!C14+ตะกุก!C14 -> 0 | D14: =+แรมป์สวน!D14+ตะกุก!D14 -> 0 | E14: =+แรมป์สวน!E14+ตะกุก!E14 -> 0 | F14: =+แรมป์สวน!G14 -> 0 | G14: =+แรมป์สวน!H14+ตะกุก!F14 -> 0 | H14: =+แรมป์สวน!I14+ตะกุก!G14 -> 0 | I14: =+แรมป์สวน!J14+ตะกุก!H14 -> 0 | J14: =+แรมป์สวน!K14+ตะกุก!I14 -> 31030 | K14: =SUM(F14:J14) -> 31030 | L14: =+แรมป์สวน!M14+ตะกุก!K14 -> 31030 | M14: =+แรมป์สวน!N14+ตะกุก!L14 -> 0 | N14: =+B14+K14 -> 65070 | O14: =+แรมป์สวน!P14+ตะกุก!N14 -> 21190 | P14: =+แรมป์สวน!Q14+ตะกุก!O14 -> 0 | Q14: =+แรมป์สวน!R14+ตะกุก!P14 -> 0 | R14: =+แรมป์สวน!S14+ตะกุก!Q14 -> 43290 | S14: =SUM(O14:R14) -> 64480 | T14: =+N14-S14 -> 590 | U14: =+แรมป์สวน!V14 -> 0 | V14: =+ตะกุก!T14 -> 0 | W14: =+แรมป์สวน!W14+ตะกุก!U14 -> 64320 | X14: =+แรมป์สวน!X14+ตะกุก!V14 -> -590 | Y14: =+W14-S14 -> -160 | Z14: =+X14+Y14 -> -750 | AA14: =+แรมป์สวน!AA14+ตะกุก!Y14 -> 5 | AB14: =+แรมป์สวน!AB14+ตะกุก!Z14 -> 0
A15: =+A14+1 -> 9 | B15: =+แรมป์สวน!B15+ตะกุก!B15 -> 0 | C15: =+แรมป์สวน!C15+ตะกุก!C15 -> 20710 | D15: =+แรมป์สวน!D15+ตะกุก!D15 -> 48700 | E15: =+แรมป์สวน!E15+ตะกุก!E15 -> 15430 | F15: =+แรมป์สวน!G15 -> 20710 | G15: =+แรมป์สวน!H15+ตะกุก!F15 -> 64130 | H15: =+แรมป์สวน!I15+ตะกุก!G15 -> 0 | I15: =+แรมป์สวน!J15+ตะกุก!H15 -> 0 | J15: =+แรมป์สวน!K15+ตะกุก!I15 -> 33520 | K15: =SUM(F15:J15) -> 118360 | L15: =+แรมป์สวน!M15+ตะกุก!K15 -> 118360 | M15: =+แรมป์สวน!N15+ตะกุก!L15 -> 0 | N15: =+B15+K15 -> 118360 | O15: =+แรมป์สวน!P15+ตะกุก!N15 -> 55060 | P15: =+แรมป์สวน!Q15+ตะกุก!O15 -> 0 | Q15: =+แรมป์สวน!R15+ตะกุก!P15 -> 0 | R15: =+แรมป์สวน!S15+ตะกุก!Q15 -> 22030 | S15: =SUM(O15:R15) -> 77090 | T15: =+N15-S15 -> 41270 | U15: =+แรมป์สวน!V15 -> 28840 | V15: =+ตะกุก!T15 -> - | W15: =+แรมป์สวน!W15+ตะกุก!U15 -> 76830 | X15: =+แรมป์สวน!X15+ตะกุก!V15 -> -940 | Y15: =+W15-S15 -> -260 | Z15: =+X15+Y15 -> -1200 | AA15: =+แรมป์สวน!AA15+ตะกุก!Y15 -> 5 | AB15: =+แรมป์สวน!AB15+ตะกุก!Z15 -> 0
A16: =+A15+1 -> 10 | B16: =+แรมป์สวน!B16+ตะกุก!B16 -> 40330 | C16: =+แรมป์สวน!C16+ตะกุก!C16 -> 27140 | D16: =+แรมป์สวน!D16+ตะกุก!D16 -> 47690 | E16: =+แรมป์สวน!E16+ตะกุก!E16 -> 14250 | F16: =+แรมป์สวน!G16 -> 27140 | G16: =+แรมป์สวน!H16+ตะกุก!F16 -> 61940 | H16: =+แรมป์สวน!I16+ตะกุก!G16 -> 0 | I16: =+แรมป์สวน!J16+ตะกุก!H16 -> 0 | J16: =+แรมป์สวน!K16+ตะกุก!I16 -> 30850 | K16: =SUM(F16:J16) -> 119930 | L16: =+แรมป์สวน!M16+ตะกุก!K16 -> 114660 | M16: =+แรมป์สวน!N16+ตะกุก!L16 -> 5270 | N16: =+B16+K16 -> 160260 | O16: =+แรมป์สวน!P16+ตะกุก!N16 -> 77460 | P16: =+แรมป์สวน!Q16+ตะกุก!O16 -> 0 | Q16: =+แรมป์สวน!R16+ตะกุก!P16 -> 0 | R16: =+แรมป์สวน!S16+ตะกุก!Q16 -> 22390 | S16: =SUM(O16:R16) -> 99850 | T16: =+N16-S16 -> 60410 | U16: =+แรมป์สวน!V16 -> 39970 | V16: =+ตะกุก!T16 -> - | W16: =+แรมป์สวน!W16+ตะกุก!U16 -> 99540 | X16: =+แรมป์สวน!X16+ตะกุก!V16 -> -490 | Y16: =+W16-S16 -> -310 | Z16: =+X16+Y16 -> -800 | AA16: =+แรมป์สวน!AA16+ตะกุก!Y16 -> 5 | AB16: =+แรมป์สวน!AB16+ตะกุก!Z16 -> 0
A17: =+A16+1 -> 11 | B17: =+แรมป์สวน!B17+ตะกุก!B17 -> 59920 | C17: =+แรมป์สวน!C17+ตะกุก!C17 -> 37540 | D17: =+แรมป์สวน!D17+ตะกุก!D17 -> 45590 | E17: =+แรมป์สวน!E17+ตะกุก!E17 -> 17890 | F17: =+แรมป์สวน!G17 -> 37540 | G17: =+แรมป์สวน!H17+ตะกุก!F17 -> 63480 | H17: =+แรมป์สวน!I17+ตะกุก!G17 -> 0 | I17: =+แรมป์สวน!J17+ตะกุก!H17 -> 0 | J17: =+แรมป์สวน!K17+ตะกุก!I17 -> 47690 | K17: =SUM(F17:J17) -> 148710 | L17: =+แรมป์สวน!M17+ตะกุก!K17 -> 140080 | M17: =+แรมป์สวน!N17+ตะกุก!L17 -> 8630 | N17: =+B17+K17 -> 208630 | O17: =+แรมป์สวน!P17+ตะกุก!N17 -> 110600 | P17: =+แรมป์สวน!Q17+ตะกุก!O17 -> 0 | Q17: =+แรมป์สวน!R17+ตะกุก!P17 -> 0 | R17: =+แรมป์สวน!S17+ตะกุก!Q17 -> 66020 | S17: =SUM(O17:R17) -> 176620 | T17: =+N17-S17 -> 32010 | U17: =+แรมป์สวน!V17 -> 29800 | V17: =+ตะกุก!T17 -> - | W17: =+แรมป์สวน!W17+ตะกุก!U17 -> 176160 | X17: =+แรมป์สวน!X17+ตะกุก!V17 -> -590 | Y17: =+W17-S17 -> -460 | Z17: =+X17+Y17 -> -1050 | AA17: =+แรมป์สวน!AA17+ตะกุก!Y17 -> 12 | AB17: =+แรมป์สวน!AB17+ตะกุก!Z17 -> 0
A18: =+A17+1 -> 12 | B18: =+แรมป์สวน!B18+ตะกุก!B18 -> 31420 | C18: =+แรมป์สวน!C18+ตะกุก!C18 -> 32580 | D18: =+แรมป์สวน!D18+ตะกุก!D18 -> 43430 | E18: =+แรมป์สวน!E18+ตะกุก!E18 -> 20620 | F18: =+แรมป์สวน!G18 -> 32580 | G18: =+แรมป์สวน!H18+ตะกุก!F18 -> 64050 | H18: =+แรมป์สวน!I18+ตะกุก!G18 -> 0 | I18: =+แรมป์สวน!J18+ตะกุก!H18 -> 0 | J18: =+แรมป์สวน!K18+ตะกุก!I18 -> 58830 | K18: =SUM(F18:J18) -> 155460 | L18: =+แรมป์สวน!M18+ตะกุก!K18 -> 140030 | M18: =+แรมป์สวน!N18+ตะกุก!L18 -> 15430 | N18: =+B18+K18 -> 186880 | O18: =+แรมป์สวน!P18+ตะกุก!N18 -> 122140 | P18: =+แรมป์สวน!Q18+ตะกุก!O18 -> 0 | Q18: =+แรมป์สวน!R18+ตะกุก!P18 -> 0 | R18: =+แรมป์สวน!S18+ตะกุก!Q18 -> 36360 | S18: =SUM(O18:R18) -> 158500 | T18: =+N18-S18 -> 28380 | U18: =+แรมป์สวน!V18 -> 3750 | V18: =+ตะกุก!T18 -> - | W18: =+แรมป์สวน!W18+ตะกุก!U18 -> 157950 | X18: =+แรมป์สวน!X18+ตะกุก!V18 -> -540 | Y18: =+W18-S18 -> -550 | Z18: =+X18+Y18 -> -1090 | AA18: =+แรมป์สวน!AA18+ตะกุก!Y18 -> 10 | AB18: =+แรมป์สวน!AB18+ตะกุก!Z18 -> 0
A19: =+A18+1 -> 13 | B19: =+แรมป์สวน!B19+ตะกุก!B19 -> 27840 | C19: =+แรมป์สวน!C19+ตะกุก!C19 -> 23530 | D19: =+แรมป์สวน!D19+ตะกุก!D19 -> 56040 | E19: =+แรมป์สวน!E19+ตะกุก!E19 -> 13360 | F19: =+แรมป์สวน!G19 -> 23530 | G19: =+แรมป์สวน!H19+ตะกุก!F19 -> 69400 | H19: =+แรมป์สวน!I19+ตะกุก!G19 -> 0 | I19: =+แรมป์สวน!J19+ตะกุก!H19 -> 0 | J19: =+แรมป์สวน!K19+ตะกุก!I19 -> 48780 | K19: =SUM(F19:J19) -> 141710 | L19: =+แรมป์สวน!M19+ตะกุก!K19 -> 122390 | M19: =+แรมป์สวน!N19+ตะกุก!L19 -> 19320 | N19: =+B19+K19 -> 169550 | O19: =+แรมป์สวน!P19+ตะกุก!N19 -> 83380 | P19: =+แรมป์สวน!Q19+ตะกุก!O19 -> 0 | Q19: =+แรมป์สวน!R19+ตะกุก!P19 -> 0 | R19: =+แรมป์สวน!S19+ตะกุก!Q19 -> 57260 | S19: =SUM(O19:R19) -> 140640 | T19: =+N19-S19 -> 28910 | U19: =+แรมป์สวน!V19 -> 13030 | V19: =+ตะกุก!T19 -> - | W19: =+แรมป์สวน!W19+ตะกุก!U19 -> 140210 | X19: =+แรมป์สวน!X19+ตะกุก!V19 -> -270 | Y19: =+W19-S19 -> -430 | Z19: =+X19+Y19 -> -700 | AA19: =+แรมป์สวน!AA19+ตะกุก!Y19 -> 9 | AB19: =+แรมป์สวน!AB19+ตะกุก!Z19 -> 0
... A30: =+A29+1 -> 24 | B30: =+แรมป์สวน!B30+ตะกุก!B30 -> 16400 | C30: =+แรมป์สวน!C30+ตะกุก!C30 -> 16320 | D30: =+แรมป์สวน!D30+ตะกุก!D30 -> 53050 | E30: =+แรมป์สวน!E30+ตะกุก!E30 -> 16950 | F30: =+แรมป์สวน!G30 -> 16320 | G30: =+แรมป์สวน!H30+ตะกุก!F30 -> 70000 | H30: =+แรมป์สวน!I30+ตะกุก!G30 -> 0 | I30: =+แรมป์สวน!J30+ตะกุก!H30 -> 0 | J30: =+แรมป์สวน!K30+ตะกุก!I30 -> 36750 | K30: =SUM(F30:J30) -> 123070 | L30: =+แรมป์สวน!M30+ตะกุก!K30 -> 108660 | M30: =+แรมป์สวน!N30+ตะกุก!L30 -> 14410 | N30: =+B30+K30 -> 139470 | O30: =+แรมป์สวน!P30+ตะกุก!N30 -> 83360 | P30: =+แรมป์สวน!Q30+ตะกุก!O30 -> 0 | Q30: =+แรมป์สวน!R30+ตะกุก!P30 -> 0 | R30: =+แรมป์สวน!S30+ตะกุก!Q30 -> 36390 | S30: =SUM(O30:R30) -> 119750 | T30: =+N30-S30 -> 19720 | U30: =+แรมป์สวน!V30 -> 14240 | V30: =+ตะกุก!T30 -> - | W30: =+แรมป์สวน!W30+ตะกุก!U30 -> 119340 | X30: =+แรมป์สวน!X30+ตะกุก!V30 -> -380 | Y30: =+W30-S30 -> -410 | Z30: =+X30+Y30 -> -790 | AA30: =+แรมป์สวน!AA30+ตะกุก!Y30 -> 8 | AB30: =+แรมป์สวน!AB30+ตะกุก!Z30 -> 0
A31: =+A30+1 -> 25 | B31: =+แรมป์สวน!B31+ตะกุก!B31 -> 19340 | C31: =+แรมป์สวน!C31+ตะกุก!C31 -> 8490 | D31: =+แรมป์สวน!D31+ตะกุก!D31 -> 42290 | E31: =+แรมป์สวน!E31+ตะกุก!E31 -> 11380 | F31: =+แรมป์สวน!G31 -> 8490 | G31: =+แรมป์สวน!H31+ตะกุก!F31 -> 53670 | H31: =+แรมป์สวน!I31+ตะกุก!G31 -> 0 | I31: =+แรมป์สวน!J31+ตะกุก!H31 -> 0 | J31: =+แรมป์สวน!K31+ตะกุก!I31 -> 55260 | K31: =SUM(F31:J31) -> 117420 | L31: =+แรมป์สวน!M31+ตะกุก!K31 -> 100750 | M31: =+แรมป์สวน!N31+ตะกุก!L31 -> 16670 | N31: =+B31+K31 -> 136760 | O31: =+แรมป์สวน!P31+ตะกุก!N31 -> 55290 | P31: =+แรมป์สวน!Q31+ตะกุก!O31 -> 0 | Q31: =+แรมป์สวน!R31+ตะกุก!P31 -> 0 | R31: =+แรมป์สวน!S31+ตะกุก!Q31 -> 36430 | S31: =SUM(O31:R31) -> 91720 | T31: =+N31-S31 -> 45040 | U31: =+แรมป์สวน!V31 -> 20690 | V31: =+ตะกุก!T31 -> - | W31: =+แรมป์สวน!W31+ตะกุก!U31 -> 90970 | X31: =+แรมป์สวน!X31+ตะกุก!V31 -> -420 | Y31: =+W31-S31 -> -750 | Z31: =+X31+Y31 -> -1170 | AA31: =+แรมป์สวน!AA31+ตะกุก!Y31 -> 6 | AB31: 0
A32: =+A31+1 -> 26 | B32: =+แรมป์สวน!B32+ตะกุก!B32 -> 44620 | C32: =+แรมป์สวน!C32+ตะกุก!C32 -> 34770 | D32: =+แรมป์สวน!D32+ตะกุก!D32 -> 54990 | E32: =+แรมป์สวน!E32+ตะกุก!E32 -> 13730 | F32: =+แรมป์สวน!G32 -> 34770 | G32: =+แรมป์สวน!H32+ตะกุก!F32 -> 68720 | H32: =+แรมป์สวน!I32+ตะกุก!G32 -> 0 | I32: =+แรมป์สวน!J32+ตะกุก!H32 -> 0 | J32: =+แรมป์สวน!K32+ตะกุก!I32 -> 41400 | K32: =SUM(F32:J32) -> 144890 | L32: =+แรมป์สวน!M32+ตะกุก!K32 -> 128900 | M32: =+แรมป์สวน!N33+ตะกุก!L32 -> 3710 | N32: =+B32+K32 -> 189510 | O32: =+แรมป์สวน!P32+ตะกุก!N32 -> 111470 | P32: =+แรมป์สวน!Q32+ตะกุก!O32 -> 0 | Q32: =+แรมป์สวน!R32+ตะกุก!P32 -> 0 | R32: =+แรมป์สวน!S32+ตะกุก!Q32 -> 61390 | S32: =SUM(O32:R32) -> 172860 | T32: =+N32-S32 -> 16650 | U32: =+แรมป์สวน!V32 -> 12300 | V32: =+ตะกุก!T32 -> - | W32: =+แรมป์สวน!W32+ตะกุก!U32 -> 172060 | X32: =+แรมป์สวน!X32+ตะกุก!V32 -> -410 | Y32: =+W32-S32 -> -800 | Z32: =+X32+Y32 -> -1210 | AA32: =+แรมป์สวน!AA32+ตะกุก!Y32 -> 11 | AB32: =+แรมป์สวน!AB32+ตะกุก!Z32 -> 170
A33: =+A32+1 -> 27 | B33: =+แรมป์สวน!B33+ตะกุก!B33 -> 16240 | C33: =+แรมป์สวน!C33+ตะกุก!C33 -> 23870 | D33: =+แรมป์สวน!D33+ตะกุก!D33 -> 41700 | E33: =+แรมป์สวน!E33+ตะกุก!E33 -> 16570 | F33: =+แรมป์สวน!G33 -> 23870 | G33: =+แรมป์สวน!H33+ตะกุก!F33 -> 59820 | H33: =+แรมป์สวน!I33+ตะกุก!G33 -> 0 | I33: =+แรมป์สวน!J33+ตะกุก!H33 -> 0 | J33: =+แรมป์สวน!K33+ตะกุก!I33 -> 19370 | K33: =SUM(F33:J33) -> 103060 | L33: =+แรมป์สวน!M33+ตะกุก!K33 -> 99350 | M33: =+แรมป์สวน!N34+ตะกุก!L33 -> 7770 | N33: =+B33+K33 -> 119300 | O33: =+แรมป์สวน!P33+ตะกุก!N33 -> 69410 | P33: =+แรมป์สวน!Q33+ตะกุก!O33 -> 0 | Q33: =+แรมป์สวน!R33+ตะกุก!P33 -> 0 | R33: =+แรมป์สวน!S33+ตะกุก!Q33 -> 22200 | S33: =SUM(O33:R33) -> 91610 | T33: =+N33-S33 -> 27690 | U33: =+แรมป์สวน!V33 -> 26010 | V33: =+ตะกุก!T33 -> 0 | W33: =+แรมป์สวน!W33+ตะกุก!U33 -> 91150 | X33: =+แรมป์สวน!X33+ตะกุก!V33 -> -1680 | Y33: =+W33-S33 -> -460 | Z33: =+X33+Y33 -> -2140 | AA33: =+แรมป์สวน!AA33+ตะกุก!Y33 -> 6 | AB33: =+แรมป์สวน!AB33+ตะกุก!Z33 -> 60
A34: =+A33+1 -> 28 | B34: =+แรมป์สวน!B34+ตะกุก!B34 -> 26010 | C34: =+แรมป์สวน!C34+ตะกุก!C34 -> 36940 | D34: =+แรมป์สวน!D34+ตะกุก!D34 -> 58390 | E34: =+แรมป์สวน!E34+ตะกุก!E34 -> 12580 | F34: =+แรมป์สวน!G34 -> 36940 | G34: =+แรมป์สวน!H34+ตะกุก!F34 -> 70970 | H34: =+แรมป์สวน!I34+ตะกุก!G34 -> 0 | I34: =+แรมป์สวน!J34+ตะกุก!H34 -> 0 | J34: =+แรมป์สวน!K34+ตะกุก!I34 -> 0 | K34: =SUM(F34:J34) -> 107910 | L34: =+แรมป์สวน!M34+ตะกุก!K34 -> 100140 | M34: =+แรมป์สวน!N34+ตะกุก!L34 -> 7770 | N34: =+B34+K34 -> 133920 | O34: =+แรมป์สวน!P34+ตะกุก!N34 -> 122640 | P34: =+แรมป์สวน!Q34+ตะกุก!O34 -> 0 | Q34: =+แรมป์สวน!R34+ตะกุก!P34 -> 0 | R34: =+แรมป์สวน!S34+ตะกุก!Q34 -> 0 | S34: =SUM(O34:R34) -> 122640 | T34: =+N34-S34 -> 11280 | U34: =+แรมป์สวน!V34 -> - | V34: =+ตะกุก!T34 -> 0 | W34: =+แรมป์สวน!W34+ตะกุก!U34 -> 122260 | X34: =+แรมป์สวน!X34+ตะกุก!V34 -> 0 | Y34: =+W34-S34 -> -380 | Z34: =+X34+Y34 -> -380 | AA34: =+แรมป์สวน!AA34+ตะกุก!Y34 -> 7 | AB34: =+แรมป์สวน!AB34+ตะกุก!Z34 -> 0
A35: =+A34+1 -> 29 | B35: =+แรมป์สวน!B35+ตะกุก!B35 -> 11280 | C35: =+แรมป์สวน!C35+ตะกุก!C35 -> 17790 | D35: =+แรมป์สวน!D35+ตะกุก!D35 -> 18160 | E35: =+แรมป์สวน!E35+ตะกุก!E35 -> 0 | F35: =+แรมป์สวน!G35 -> 17790 | G35: =+แรมป์สวน!H35+ตะกุก!F35 -> 18160 | H35: =+แรมป์สวน!I35+ตะกุก!G35 -> 0 | I35: =+แรมป์สวน!J35+ตะกุก!H35 -> 0 | J35: =+แรมป์สวน!K35+ตะกุก!I35 -> 0 | K35: =SUM(F35:J35) -> 35950 | L35: =+แรมป์สวน!M35+ตะกุก!K35 -> 35950 | M35: =+แรมป์สวน!N35+ตะกุก!L35 -> 0 | N35: =+B35+K35 -> 47230 | O35: =+แรมป์สวน!P35+ตะกุก!N35 -> 42190 | P35: =+แรมป์สวน!Q35+ตะกุก!O35 -> 0 | Q35: =+แรมป์สวน!R35+ตะกุก!P35 -> 0 | R35: =+แรมป์สวน!S35+ตะกุก!Q35 -> 0 | S35: =SUM(O35:R35) -> 42190 | T35: =+N35-S35 -> 5040 | U35: =+แรมป์สวน!V35 -> 4770 | V35: =+ตะกุก!T35 -> 0 | W35: =+แรมป์สวน!W35+ตะกุก!U35 -> 42010 | X35: =+แรมป์สวน!X35+ตะกุก!V35 -> -270 | Y35: =+W35-S35 -> -180 | Z35: =+X35+Y35 -> -450 | AA35: =+แรมป์สวน!AA35+ตะกุก!Y35 -> 3 | AB35: =+แรมป์สวน!AB35+ตะกุก!Z35 -> 0
A36: =+A35+1 -> 30 | B36: =+แรมป์สวน!B36+ตะกุก!B36 -> 4770 | C36: =+แรมป์สวน!C36+ตะกุก!C36 -> 46450 | D36: =+แรมป์สวน!D36+ตะกุก!D36 -> 39870 | E36: =+แรมป์สวน!E36+ตะกุก!E36 -> 5800 | F36: =+แรมป์สวน!G36 -> 46450 | G36: =+แรมป์สวน!H36+ตะกุก!F36 -> 45670 | H36: =+แรมป์สวน!I36+ตะกุก!G36 -> 0 | I36: =+แรมป์สวน!J36+ตะกุก!H36 -> 0 | J36: =+แรมป์สวน!K36+ตะกุก!I36 -> 0 | K36: =SUM(F36:J36) -> 92120 | L36: =+แรมป์สวน!M36+ตะกุก!K36 -> 77890 | M36: =+แรมป์สวน!N36+ตะกุก!L36 -> 14230 | N36: =+B36+K36 -> 96890 | O36: =+แรมป์สวน!P36+ตะกุก!N36 -> 80720 | P36: =+แรมป์สวน!Q36+ตะกุก!O36 -> 0 | Q36: =+แรมป์สวน!R36+ตะกุก!P36 -> 0 | R36: =+แรมป์สวน!S36+ตะกุก!Q36 -> 0 | S36: =SUM(O36:R36) -> 80720 | T36: =+N36-S36 -> 16170 | U36: =+แรมป์สวน!V36 -> 16540 | V36: =+ตะกุก!T36 -> 0 | W36: =+แรมป์สวน!W36+ตะกุก!U36 -> 80460 | X36: =+แรมป์สวน!X36+ตะกุก!V36 -> 370 | Y36: =+W36-S36 -> -260 | Z36: =+X36+Y36 -> 110 | AA36: =+แรมป์สวน!AA36+ตะกุก!Y36 -> 5 | AB36: =+แรมป์สวน!AB36+ตะกุก!Z36 -> 0
A37: 31 | B37: =+แรมป์สวน!B37+ตะกุก!B37 -> 16540 | C37: =+แรมป์สวน!C37+ตะกุก!C37 -> 25150 | D37: =+แรมป์สวน!D37+ตะกุก!D37 -> 35020 | E37: =+แรมป์สวน!E37+ตะกุก!E37 -> 8300 | F37: =+แรมป์สวน!G37 -> 25150 | G37: =+แรมป์สวน!H37+ตะกุก!F37 -> 43320 | H37: =+แรมป์สวน!I37+ตะกุก!G37 -> 0 | I37: =+แรมป์สวน!J37+ตะกุก!H37 -> 0 | J37: =+แรมป์สวน!K37+ตะกุก!I37 -> 0 | K37: =SUM(F37:J37) -> 68470 | L37: =+แรมป์สวน!M37+ตะกุก!K37 -> 64670 | M37: =+แรมป์สวน!N37+ตะกุก!L37 -> 3800 | N37: =+B37+K37 -> 85010 | O37: =+แรมป์สวน!P37+ตะกุก!N37 -> 80930 | P37: =+แรมป์สวน!Q37+ตะกุก!O37 -> 0 | Q37: =+แรมป์สวน!R37+ตะกุก!P37 -> 0 | R37: =+แรมป์สวน!S37+ตะกุก!Q37 -> 0 | S37: =SUM(O37:R37) -> 80930 | T37: =+N37-S37 -> 4080 | U37: =+แรมป์สวน!V37 -> 4220 | V37: =+ตะกุก!T37 -> 0 | W37: =+แรมป์สวน!W37+ตะกุก!U37 -> 80590 | X37: =+แรมป์สวน!X37+ตะกุก!V37 -> 140 | Y37: =+W37-S37 -> -340 | Z37: =+X37+Y37 -> -200 | AA37: =+แรมป์สวน!AA37+ตะกุก!Y37 -> 6 | AB37: =+แรมป์สวน!AB37+ตะกุก!Z37 -> 30
A38: รวม | B38: =B7 -> 25330 | C38: =SUM(C7:C37) -> 720000 | D38: =SUM(D7:D37) -> 1242030 | E38: =SUM(E7:E37) -> 489750 | F38: =SUM(F7:F37) -> 720000 | G38: =SUM(G7:G37) -> 1733330 | H38: =SUM(H7:H37) -> 0 | I38: =SUM(I7:I37) -> 0 | J38: =SUM(J7:J37) -> 659530 | ... M38: =SUM(M7:M37) -> 239720 | N38: =+B38+K38 -> 3138190 | O38: =SUM(O7:O37) -> 2464400 | P38: =SUM(P7:P37) -> 0 | Q38: =SUM(Q7:Q37) -> 0 | R38: =SUM(R7:R37) -> 655230 | S38: =SUM(S7:S37) -> 3119630 | T38: =+N38-S38 -> 18560 | U38: =+U37 -> 4220 | V38: =+V36 -> 0 | W38: =SUM(W7:W37) -> 3108560 | X38: =+แรมป์สวน!X38+ตะกุก!V38 -> -14340 | Y38: =SUM(Y7:Y37) -> -11070 | Z38: =SUM(Z7:Z37) -> -25410 | AA38: =SUM(AA7:AA37) -> 194 | AB38: =SUM(AB7:AB37) -> 380
A39: เฉลี่ย / วัน | C39: =+C38/$A$37 -> 23225.806 | D39: =+D38/$A$37 -> 40065.484 | E39: =+E38/$A$37 -> 15798.387 | F39: =+F38/$A$37 -> 23225.806 | G39: =+G38/$A$37 -> 55913.871 | H39: =+H38/$A$37 -> 0 | I39: =+I38/$A$37 -> 0 | J39: =+J38/$A$37 -> 21275.161 | K39: =+K38/$A$37 -> 100414.84 | L39: =+L38/$A$36 -> 95497.333 | M39: =+M38/$A$36 -> 7990.6667 | N39: =+N38/$A$37 -> 101231.94 | O39: =+O38/$A$37 -> 79496.774 | P39: =+P38/$A$37 -> 0 | Q39: =+Q38/$A$37 -> 0 | R39: =+R38/$A$37 -> 21136.452 | S39: =+S38/$A$37 -> 100633.23 | T39: =SUM(T7:T37)/A37 -> 19895.806 | U39: 0 | V39: 0 | W39: =+W38/$A$37 -> 100276.13 | X39: =+X38*100/N38 -> -0.4569513 | Y39: =+Y38*100/S38 -> -0.35484977 | Z39: =X39+Y39 -> -0.81180107 | AA39: =+AA38/A36 -> 6.4666667 | AB39: =+AB38/A36 -> 12.666667
H40: =+G38+H38 -> 1733330 | K40: =+K38-F38 -> 2392860

Sheet Sheet1
E1: ธกส.-สวน | G1: ธกส.-สวน
A2: 1 | B2: 0 | D2: 45141 | E2: 200 | F2: 45143 | G2: 375
A3: 2 | B3: 0 | D3: 45143 | E3: 1795 | F3: 45143 | G3: 555
A4: 3 | B4: 200 | C4: =+E2 -> 200 | D4: 45145 | E4: 2560 | F4: 45143 | G4: 435
A5: 4 | B5: 0 | D5: 45145 | E5: 3160 | F5: 45143 | G5: 587 | I5: ขาด
A6: 5 | B6: 4650 | C6: =+E3+G3+G4+G5+G2 -> 3747 | D6: 45145 | E6: 2045 | F6: 45146 | G6: 1123 | I6: =+B6-C6 -> 903
A7: 6 | B7: 0 | D7: 45145 | E7: 790 | F7: 45146 | G7: 2297
A8: 7 | B8: 8555 | C8: =+E4+E5+E6+E7 -> 8555 | D8: 45146 | E8: 1785 | F8: 45146 | G8: 350
A9: 8 | B9: 12995 | C9: =+E8+E9+E10+E11+G6+G7+G8+G9 -> 12995 | D9: 45146 | E9: 2220 | F9: 45146 | G9: 2015
A10: 9 | B10: 26290 | C10: =+E12+E13+E14+E15+G10+G11 -> 26290 | D10: 45146 | E10: 1050 | F10: 45147 | G10: 3203
A11: 10 | B11: 14475 | C11: =+E16+E17+E18+E19+E20 -> 14475 | D11: 45146 | E11: 2155 | F11: 45147 | G11: 3632
A12: 11 | B12: 28535 | C12: =+E21+E22+E23+E24+E25+E26+G12+G13 -> 28535 | D12: 45147 | E12: 7225 | F12: 45149 | G12: 1050
A13: 12 | B13: 0 | D13: 45147 | E13: 2990 | F13: 45149 | G13: 4460
A14: 13 | B14: 0 | D14: 45147 | E14: 2090 | F14: 45159 | G14: 162
A15: 14 | B15: 26675 | C15: =+E27+E28+E29+E30+E31+E32+E33 -> 26675 | D15: 45147 | E15: 7150 | F15: 45159 | G15: 352
A16: 15 | B16: 15890 | C16: =+E34+E35+E36+E37+E38+E39 -> 15890 | D16: 45148 | E16: 2425 | F16: 45159 | G16: 596
A17: 16 | B17: 2075 | C17: =+E40 -> 2075 | D17: 45148 | E17: 3405 | F17: 45159 | G17: 149
A18: 17 | B18: 0 | D18: 45148 | E18: 3120 | F18: 45159 | G18: 180
A19: 18 | B19: 0 | D19: 45148 | E19: 2425 | F19: 45159 | G19: 806
A20: 19 | B20: 0 | D20: 45148 | E20: 3100 | F20: 45161 | G20: 1827
A21: 20 | B21: 0 | D21: 45149 | E21: 2710 | F21: 45161 | G21: 533
A22: 21 | B22: 9045 | C22: =+E41+E42+E43+G14+G15+G16+G17+G18+G19 -> 9045 | D22: 45149 | E22: 7050 | F22: 45161 | G22: 1911 | I22: =+B22-C22 -> 0
A23: 22 | B23: 7730 | C23: =+E44+E45+E46 -> 7730 | D23: 45149 | E23: 3380 | F23: 45161 | G23: 1174
A24: 23 | B24: 16910 | C24: =+E47+E48+E49+E50+E51+G20+G21+G22+G23 -> 16910 | D24: 45149 | E24: 1655 | F24: 45162 | G24: 1288
A25: 24 | B25: 10705 | C25: =+E52+E53+G24+G25+G26+G27 -> 10705 | D25: 45149 | E25: 5435 | F25: 45162 | G25: 1287
A26: 25 | B26: 11220 | C26: =+E54+E55+E56+E57 -> 11220 | D26: 45149 | E26: 2795 | F26: 45162 | G26: 1192
A27: 26 | B27: 11250 | C27: =+E58+E59+E60+G28+G29 -> 11250 | D27: 45152 | E27: 5775 | F27: 45162 | G27: 1528
A28: 27 | B28: 0 | D28: 45152 | E28: 2575 | F28: 45164 | G28: 1410
A29: 28 | B29: 36685 | C29: =+E61+E62+E63+E64+E65+E66+G30+G31 -> 36685 | D29: 45152 | E29: 3470 | F29: 45164 | G29: 970
A30: 29 | B30: 28170 | C30: =+E67+E68+E69+E70+E71+E72 -> 28170 | D30: 45152 | E30: 5055 | F30: 45166 | G30: 6473
A31: 30 | B31: 19005 | C31: =+E73+E74+E75+G32+G33 -> 19005 | D31: 45152 | E31: 2675 | F31: 45166 | G31: 812
A32: 31 | B32: 5020 | C32: =+E76 -> 5020 | D32: 45152 | E32: 3805 | F32: 45168 | G32: 682
B33: =SUM(B2:B32) -> 296080 | D33: 45152 | E33: 3320 | F33: 45168 | G33: 3738
D34: 45153 | E34: 2805
D35: 45153 | E35: 2600
D36: 45153 | E36: 1875
D37: 45153 | E37: 2795
D38: 45153 | E38: 2640
D39: 45153 | E39: 3175
D40: 45154 | E40: 2075
...
